2025-06-06 10:18:04.608 | ERROR | src.middleware:dispatch:21
from_bx
2025-06-06 10:23:22.145 | ERROR | src.middleware:dispatch:20
from_bx
2025-06-06 10:24:41.094 | ERROR | src.middleware:dispatch:20
from_bx
2025-06-06 10:38:46.410 | ERROR | src.middleware:dispatch:20
from_bx
2025-06-06 10:39:11.294 | ERROR | src.middleware:dispatch:20
from_bx
2025-06-06 10:42:33.433 | ERROR | src.middleware:dispatch:20
from_bx
2025-06-06 10:44:13.172 | ERROR | src.middleware:dispatch:20
from_bx
2025-06-06 11:16:00.945 | CRITICAL | src.middleware:_coro:18
from_bx
2025-06-06 11:18:20.138 | CRITICAL | src.middleware:_coro:18
from_bx
2025-06-06 11:22:46.422 | CRITICAL | src.middleware:_coro:18
from_bx
NoneType: None
2025-06-06 11:23:05.365 | CRITICAL | src.middleware:_coro:18
from_bx
NoneType: None
2025-06-06 12:05:01.089 | CRITICAL | /usr/lib/python3.13/asyncio/events.py:89 (_run)
Error: AttributeError: from_bx
Traceback:
NoneType: None

2025-06-06 12:05:48.809 | CRITICAL | /usr/lib/python3.13/asyncio/events.py:89 (_run)
Error: AttributeError: from_bx
Traceback:
NoneType: None

2025-06-06 12:06:52.303 | CRITICAL | /home/dfx_17/Projects/Slovo/schedule/backend/.venv/lib/python3.13/site-packages/starlette/applications.py:112 (__call__)
Error: AttributeError: from_bx
Traceback:
NoneType: None

2025-06-06 12:07:46.166 | CRITICAL | /home/dfx_17/Projects/Slovo/schedule/backend/.venv/lib/python3.13/site-packages/starlette/applications.py:112 (__call__)
Error: AttributeError: from_bx
Traceback:
NoneType: None

2025-06-06 12:10:45.353 | CRITICAL | /home/dfx_17/Projects/Slovo/schedule/backend/.venv/lib/python3.13/site-packages/starlette/applications.py:112 (__call__)
Error: AttributeError: from_bx
Traceback:
Traceback (most recent call last):
  File "/home/dfx_17/Projects/Slovo/schedule/backend/.venv/lib/python3.13/site-packages/starlette/middleware/base.py", line 148, in call_next
    message = await recv_stream.receive()
              ^^^^^^^^^^^^^^^^^^^^^^^^^^^
  File "/home/dfx_17/Projects/Slovo/schedule/backend/.venv/lib/python3.13/site-packages/anyio/streams/memory.py", line 126, in receive
    raise EndOfStream from None
anyio.EndOfStream

During handling of the above exception, another exception occurred:

Traceback (most recent call last):
  File "/home/dfx_17/Projects/Slovo/schedule/backend/src/middleware.py", line 48, in dispatch
    return await call_next(request)
           ^^^^^^^^^^^^^^^^^^^^^^^^
  File "/home/dfx_17/Projects/Slovo/schedule/backend/.venv/lib/python3.13/site-packages/starlette/middleware/base.py", line 156, in call_next
    raise app_exc
  File "/home/dfx_17/Projects/Slovo/schedule/backend/.venv/lib/python3.13/site-packages/starlette/middleware/base.py", line 141, in coro
    await self.app(scope, receive_or_disconnect, send_no_error)
  File "/home/dfx_17/Projects/Slovo/schedule/backend/.venv/lib/python3.13/site-packages/starlette/middleware/cors.py", line 85, in __call__
    await self.app(scope, receive, send)
  File "/home/dfx_17/Projects/Slovo/schedule/backend/.venv/lib/python3.13/site-packages/starlette/middleware/exceptions.py", line 62, in __call__
    await wrap_app_handling_exceptions(self.app, conn)(scope, receive, send)
  File "/home/dfx_17/Projects/Slovo/schedule/backend/.venv/lib/python3.13/site-packages/starlette/_exception_handler.py", line 53, in wrapped_app
    raise exc
  File "/home/dfx_17/Projects/Slovo/schedule/backend/.venv/lib/python3.13/site-packages/starlette/_exception_handler.py", line 42, in wrapped_app
    await app(scope, receive, sender)
  File "/home/dfx_17/Projects/Slovo/schedule/backend/.venv/lib/python3.13/site-packages/starlette/routing.py", line 714, in __call__
    await self.middleware_stack(scope, receive, send)
  File "/home/dfx_17/Projects/Slovo/schedule/backend/.venv/lib/python3.13/site-packages/starlette/routing.py", line 734, in app
    await route.handle(scope, receive, send)
  File "/home/dfx_17/Projects/Slovo/schedule/backend/.venv/lib/python3.13/site-packages/starlette/routing.py", line 288, in handle
    await self.app(scope, receive, send)
  File "/home/dfx_17/Projects/Slovo/schedule/backend/.venv/lib/python3.13/site-packages/starlette/routing.py", line 76, in app
    await wrap_app_handling_exceptions(app, request)(scope, receive, send)
  File "/home/dfx_17/Projects/Slovo/schedule/backend/.venv/lib/python3.13/site-packages/starlette/_exception_handler.py", line 53, in wrapped_app
    raise exc
  File "/home/dfx_17/Projects/Slovo/schedule/backend/.venv/lib/python3.13/site-packages/starlette/_exception_handler.py", line 42, in wrapped_app
    await app(scope, receive, sender)
  File "/home/dfx_17/Projects/Slovo/schedule/backend/.venv/lib/python3.13/site-packages/starlette/routing.py", line 73, in app
    response = await f(request)
               ^^^^^^^^^^^^^^^^
  File "/home/dfx_17/Projects/Slovo/schedule/backend/.venv/lib/python3.13/site-packages/fastapi/routing.py", line 301, in app
    raw_response = await run_endpoint_function(
                   ^^^^^^^^^^^^^^^^^^^^^^^^^^^^
    ...<3 lines>...
    )
    ^
  File "/home/dfx_17/Projects/Slovo/schedule/backend/.venv/lib/python3.13/site-packages/fastapi/routing.py", line 212, in run_endpoint_function
    return await dependant.call(**values)
           ^^^^^^^^^^^^^^^^^^^^^^^^^^^^^^
  File "/home/dfx_17/Projects/Slovo/schedule/backend/src/api/appointment.py", line 50, in get_appointment
    return Appointment.from_bx(data)
           ^^^^^^^^^^^^^^^^^^^
  File "/home/dfx_17/Projects/Slovo/schedule/backend/.venv/lib/python3.13/site-packages/pydantic/_internal/_model_construction.py", line 271, in __getattr__
    raise AttributeError(item)
AttributeError: from_bx. Did you mean: 'from_orm'?

2025-06-06 12:11:19.885 | CRITICAL | /home/dfx_17/Projects/Slovo/schedule/backend/.venv/lib/python3.13/site-packages/starlette/applications.py:112 (__call__)
Error: AttributeError: from_bx
Traceback:
Traceback (most recent call last):
  File "/home/dfx_17/Projects/Slovo/schedule/backend/.venv/lib/python3.13/site-packages/starlette/middleware/base.py", line 148, in call_next
    message = await recv_stream.receive()
              ^^^^^^^^^^^^^^^^^^^^^^^^^^^
  File "/home/dfx_17/Projects/Slovo/schedule/backend/.venv/lib/python3.13/site-packages/anyio/streams/memory.py", line 126, in receive
    raise EndOfStream from None
anyio.EndOfStream

During handling of the above exception, another exception occurred:

Traceback (most recent call last):
  File "/home/dfx_17/Projects/Slovo/schedule/backend/src/middleware.py", line 48, in dispatch
    return await call_next(request)
           ^^^^^^^^^^^^^^^^^^^^^^^^
  File "/home/dfx_17/Projects/Slovo/schedule/backend/.venv/lib/python3.13/site-packages/starlette/middleware/base.py", line 156, in call_next
    raise app_exc
  File "/home/dfx_17/Projects/Slovo/schedule/backend/.venv/lib/python3.13/site-packages/starlette/middleware/base.py", line 141, in coro
    await self.app(scope, receive_or_disconnect, send_no_error)
  File "/home/dfx_17/Projects/Slovo/schedule/backend/.venv/lib/python3.13/site-packages/starlette/middleware/cors.py", line 85, in __call__
    await self.app(scope, receive, send)
  File "/home/dfx_17/Projects/Slovo/schedule/backend/.venv/lib/python3.13/site-packages/starlette/middleware/exceptions.py", line 62, in __call__
    await wrap_app_handling_exceptions(self.app, conn)(scope, receive, send)
  File "/home/dfx_17/Projects/Slovo/schedule/backend/.venv/lib/python3.13/site-packages/starlette/_exception_handler.py", line 53, in wrapped_app
    raise exc
  File "/home/dfx_17/Projects/Slovo/schedule/backend/.venv/lib/python3.13/site-packages/starlette/_exception_handler.py", line 42, in wrapped_app
    await app(scope, receive, sender)
  File "/home/dfx_17/Projects/Slovo/schedule/backend/.venv/lib/python3.13/site-packages/starlette/routing.py", line 714, in __call__
    await self.middleware_stack(scope, receive, send)
  File "/home/dfx_17/Projects/Slovo/schedule/backend/.venv/lib/python3.13/site-packages/starlette/routing.py", line 734, in app
    await route.handle(scope, receive, send)
  File "/home/dfx_17/Projects/Slovo/schedule/backend/.venv/lib/python3.13/site-packages/starlette/routing.py", line 288, in handle
    await self.app(scope, receive, send)
  File "/home/dfx_17/Projects/Slovo/schedule/backend/.venv/lib/python3.13/site-packages/starlette/routing.py", line 76, in app
    await wrap_app_handling_exceptions(app, request)(scope, receive, send)
  File "/home/dfx_17/Projects/Slovo/schedule/backend/.venv/lib/python3.13/site-packages/starlette/_exception_handler.py", line 53, in wrapped_app
    raise exc
  File "/home/dfx_17/Projects/Slovo/schedule/backend/.venv/lib/python3.13/site-packages/starlette/_exception_handler.py", line 42, in wrapped_app
    await app(scope, receive, sender)
  File "/home/dfx_17/Projects/Slovo/schedule/backend/.venv/lib/python3.13/site-packages/starlette/routing.py", line 73, in app
    response = await f(request)
               ^^^^^^^^^^^^^^^^
  File "/home/dfx_17/Projects/Slovo/schedule/backend/.venv/lib/python3.13/site-packages/fastapi/routing.py", line 301, in app
    raw_response = await run_endpoint_function(
                   ^^^^^^^^^^^^^^^^^^^^^^^^^^^^
    ...<3 lines>...
    )
    ^
  File "/home/dfx_17/Projects/Slovo/schedule/backend/.venv/lib/python3.13/site-packages/fastapi/routing.py", line 212, in run_endpoint_function
    return await dependant.call(**values)
           ^^^^^^^^^^^^^^^^^^^^^^^^^^^^^^
  File "/home/dfx_17/Projects/Slovo/schedule/backend/src/api/appointment.py", line 50, in get_appointment
    return Appointment.from_bx(data)
           ^^^^^^^^^^^^^^^^^^^
  File "/home/dfx_17/Projects/Slovo/schedule/backend/.venv/lib/python3.13/site-packages/pydantic/_internal/_model_construction.py", line 271, in __getattr__
    raise AttributeError(item)
AttributeError: from_bx. Did you mean: 'from_orm'?

2025-06-06 12:11:36.063 | CRITICAL | /home/dfx_17/Projects/Slovo/schedule/backend/.venv/lib/python3.13/site-packages/starlette/applications.py:112 (__call__)
Error: AttributeError: from_bx
Traceback:
Traceback (most recent call last):
  File "/home/dfx_17/Projects/Slovo/schedule/backend/.venv/lib/python3.13/site-packages/starlette/middleware/base.py", line 148, in call_next
    message = await recv_stream.receive()
              ^^^^^^^^^^^^^^^^^^^^^^^^^^^
  File "/home/dfx_17/Projects/Slovo/schedule/backend/.venv/lib/python3.13/site-packages/anyio/streams/memory.py", line 126, in receive
    raise EndOfStream from None
anyio.EndOfStream

During handling of the above exception, another exception occurred:

Traceback (most recent call last):
  File "/home/dfx_17/Projects/Slovo/schedule/backend/src/middleware.py", line 48, in dispatch
    return await call_next(request)
           ^^^^^^^^^^^^^^^^^^^^^^^^
  File "/home/dfx_17/Projects/Slovo/schedule/backend/.venv/lib/python3.13/site-packages/starlette/middleware/base.py", line 156, in call_next
    raise app_exc
  File "/home/dfx_17/Projects/Slovo/schedule/backend/.venv/lib/python3.13/site-packages/starlette/middleware/base.py", line 141, in coro
    await self.app(scope, receive_or_disconnect, send_no_error)
  File "/home/dfx_17/Projects/Slovo/schedule/backend/.venv/lib/python3.13/site-packages/starlette/middleware/cors.py", line 85, in __call__
    await self.app(scope, receive, send)
  File "/home/dfx_17/Projects/Slovo/schedule/backend/.venv/lib/python3.13/site-packages/starlette/middleware/exceptions.py", line 62, in __call__
    await wrap_app_handling_exceptions(self.app, conn)(scope, receive, send)
  File "/home/dfx_17/Projects/Slovo/schedule/backend/.venv/lib/python3.13/site-packages/starlette/_exception_handler.py", line 53, in wrapped_app
    raise exc
  File "/home/dfx_17/Projects/Slovo/schedule/backend/.venv/lib/python3.13/site-packages/starlette/_exception_handler.py", line 42, in wrapped_app
    await app(scope, receive, sender)
  File "/home/dfx_17/Projects/Slovo/schedule/backend/.venv/lib/python3.13/site-packages/starlette/routing.py", line 714, in __call__
    await self.middleware_stack(scope, receive, send)
  File "/home/dfx_17/Projects/Slovo/schedule/backend/.venv/lib/python3.13/site-packages/starlette/routing.py", line 734, in app
    await route.handle(scope, receive, send)
  File "/home/dfx_17/Projects/Slovo/schedule/backend/.venv/lib/python3.13/site-packages/starlette/routing.py", line 288, in handle
    await self.app(scope, receive, send)
  File "/home/dfx_17/Projects/Slovo/schedule/backend/.venv/lib/python3.13/site-packages/starlette/routing.py", line 76, in app
    await wrap_app_handling_exceptions(app, request)(scope, receive, send)
  File "/home/dfx_17/Projects/Slovo/schedule/backend/.venv/lib/python3.13/site-packages/starlette/_exception_handler.py", line 53, in wrapped_app
    raise exc
  File "/home/dfx_17/Projects/Slovo/schedule/backend/.venv/lib/python3.13/site-packages/starlette/_exception_handler.py", line 42, in wrapped_app
    await app(scope, receive, sender)
  File "/home/dfx_17/Projects/Slovo/schedule/backend/.venv/lib/python3.13/site-packages/starlette/routing.py", line 73, in app
    response = await f(request)
               ^^^^^^^^^^^^^^^^
  File "/home/dfx_17/Projects/Slovo/schedule/backend/.venv/lib/python3.13/site-packages/fastapi/routing.py", line 301, in app
    raw_response = await run_endpoint_function(
                   ^^^^^^^^^^^^^^^^^^^^^^^^^^^^
    ...<3 lines>...
    )
    ^
  File "/home/dfx_17/Projects/Slovo/schedule/backend/.venv/lib/python3.13/site-packages/fastapi/routing.py", line 212, in run_endpoint_function
    return await dependant.call(**values)
           ^^^^^^^^^^^^^^^^^^^^^^^^^^^^^^
  File "/home/dfx_17/Projects/Slovo/schedule/backend/src/api/appointment.py", line 50, in get_appointment
    return Appointment.from_bx(data)
           ^^^^^^^^^^^^^^^^^^^
  File "/home/dfx_17/Projects/Slovo/schedule/backend/.venv/lib/python3.13/site-packages/pydantic/_internal/_model_construction.py", line 271, in __getattr__
    raise AttributeError(item)
AttributeError: from_bx. Did you mean: 'from_orm'?

2025-06-06 12:16:58.325 | CRITICAL | /home/dfx_17/Projects/Slovo/schedule/backend/.venv/lib/python3.13/site-packages/starlette/applications.py:112 (__call__)
Error: AttributeError: from_bx
Traceback:
Traceback (most recent call last):
  File "/home/dfx_17/Projects/Slovo/schedule/backend/.venv/lib/python3.13/site-packages/starlette/middleware/base.py", line 148, in call_next
    message = await recv_stream.receive()
              ^^^^^^^^^^^^^^^^^^^^^^^^^^^
  File "/home/dfx_17/Projects/Slovo/schedule/backend/.venv/lib/python3.13/site-packages/anyio/streams/memory.py", line 126, in receive
    raise EndOfStream from None
anyio.EndOfStream

During handling of the above exception, another exception occurred:

Traceback (most recent call last):
  File "/home/dfx_17/Projects/Slovo/schedule/backend/src/middleware.py", line 48, in dispatch
    return await call_next(request)
           ^^^^^^^^^^^^^^^^^^^^^^^^
  File "/home/dfx_17/Projects/Slovo/schedule/backend/.venv/lib/python3.13/site-packages/starlette/middleware/base.py", line 156, in call_next
    raise app_exc
  File "/home/dfx_17/Projects/Slovo/schedule/backend/.venv/lib/python3.13/site-packages/starlette/middleware/base.py", line 141, in coro
    await self.app(scope, receive_or_disconnect, send_no_error)
  File "/home/dfx_17/Projects/Slovo/schedule/backend/.venv/lib/python3.13/site-packages/starlette/middleware/cors.py", line 85, in __call__
    await self.app(scope, receive, send)
  File "/home/dfx_17/Projects/Slovo/schedule/backend/.venv/lib/python3.13/site-packages/starlette/middleware/exceptions.py", line 62, in __call__
    await wrap_app_handling_exceptions(self.app, conn)(scope, receive, send)
  File "/home/dfx_17/Projects/Slovo/schedule/backend/.venv/lib/python3.13/site-packages/starlette/_exception_handler.py", line 53, in wrapped_app
    raise exc
  File "/home/dfx_17/Projects/Slovo/schedule/backend/.venv/lib/python3.13/site-packages/starlette/_exception_handler.py", line 42, in wrapped_app
    await app(scope, receive, sender)
  File "/home/dfx_17/Projects/Slovo/schedule/backend/.venv/lib/python3.13/site-packages/starlette/routing.py", line 714, in __call__
    await self.middleware_stack(scope, receive, send)
  File "/home/dfx_17/Projects/Slovo/schedule/backend/.venv/lib/python3.13/site-packages/starlette/routing.py", line 734, in app
    await route.handle(scope, receive, send)
  File "/home/dfx_17/Projects/Slovo/schedule/backend/.venv/lib/python3.13/site-packages/starlette/routing.py", line 288, in handle
    await self.app(scope, receive, send)
  File "/home/dfx_17/Projects/Slovo/schedule/backend/.venv/lib/python3.13/site-packages/starlette/routing.py", line 76, in app
    await wrap_app_handling_exceptions(app, request)(scope, receive, send)
  File "/home/dfx_17/Projects/Slovo/schedule/backend/.venv/lib/python3.13/site-packages/starlette/_exception_handler.py", line 53, in wrapped_app
    raise exc
  File "/home/dfx_17/Projects/Slovo/schedule/backend/.venv/lib/python3.13/site-packages/starlette/_exception_handler.py", line 42, in wrapped_app
    await app(scope, receive, sender)
  File "/home/dfx_17/Projects/Slovo/schedule/backend/.venv/lib/python3.13/site-packages/starlette/routing.py", line 73, in app
    response = await f(request)
               ^^^^^^^^^^^^^^^^
  File "/home/dfx_17/Projects/Slovo/schedule/backend/.venv/lib/python3.13/site-packages/fastapi/routing.py", line 301, in app
    raw_response = await run_endpoint_function(
                   ^^^^^^^^^^^^^^^^^^^^^^^^^^^^
    ...<3 lines>...
    )
    ^
  File "/home/dfx_17/Projects/Slovo/schedule/backend/.venv/lib/python3.13/site-packages/fastapi/routing.py", line 212, in run_endpoint_function
    return await dependant.call(**values)
           ^^^^^^^^^^^^^^^^^^^^^^^^^^^^^^
  File "/home/dfx_17/Projects/Slovo/schedule/backend/src/api/appointment.py", line 50, in get_appointment
    return Appointment.from_bx(data)
           ^^^^^^^^^^^^^^^^^^^
  File "/home/dfx_17/Projects/Slovo/schedule/backend/.venv/lib/python3.13/site-packages/pydantic/_internal/_model_construction.py", line 271, in __getattr__
    raise AttributeError(item)
AttributeError: from_bx. Did you mean: 'from_orm'?

2025-06-06 12:21:42.492 | CRITICAL | /home/dfx_17/Projects/Slovo/schedule/backend/.venv/lib/python3.13/site-packages/starlette/applications.py:112 (__call__)
Error: AttributeError: from_bx
Traceback:
Traceback (most recent call last):
  File "/home/dfx_17/Projects/Slovo/schedule/backend/.venv/lib/python3.13/site-packages/starlette/middleware/base.py", line 148, in call_next
    message = await recv_stream.receive()
              ^^^^^^^^^^^^^^^^^^^^^^^^^^^
  File "/home/dfx_17/Projects/Slovo/schedule/backend/.venv/lib/python3.13/site-packages/anyio/streams/memory.py", line 126, in receive
    raise EndOfStream from None
anyio.EndOfStream

During handling of the above exception, another exception occurred:

Traceback (most recent call last):
  File "/home/dfx_17/Projects/Slovo/schedule/backend/src/middleware.py", line 48, in dispatch
    return await call_next(request)
           ^^^^^^^^^^^^^^^^^^^^^^^^
  File "/home/dfx_17/Projects/Slovo/schedule/backend/.venv/lib/python3.13/site-packages/starlette/middleware/base.py", line 156, in call_next
    raise app_exc
  File "/home/dfx_17/Projects/Slovo/schedule/backend/.venv/lib/python3.13/site-packages/starlette/middleware/base.py", line 141, in coro
    await self.app(scope, receive_or_disconnect, send_no_error)
  File "/home/dfx_17/Projects/Slovo/schedule/backend/.venv/lib/python3.13/site-packages/starlette/middleware/cors.py", line 85, in __call__
    await self.app(scope, receive, send)
  File "/home/dfx_17/Projects/Slovo/schedule/backend/.venv/lib/python3.13/site-packages/starlette/middleware/exceptions.py", line 62, in __call__
    await wrap_app_handling_exceptions(self.app, conn)(scope, receive, send)
  File "/home/dfx_17/Projects/Slovo/schedule/backend/.venv/lib/python3.13/site-packages/starlette/_exception_handler.py", line 53, in wrapped_app
    raise exc
  File "/home/dfx_17/Projects/Slovo/schedule/backend/.venv/lib/python3.13/site-packages/starlette/_exception_handler.py", line 42, in wrapped_app
    await app(scope, receive, sender)
  File "/home/dfx_17/Projects/Slovo/schedule/backend/.venv/lib/python3.13/site-packages/starlette/routing.py", line 714, in __call__
    await self.middleware_stack(scope, receive, send)
  File "/home/dfx_17/Projects/Slovo/schedule/backend/.venv/lib/python3.13/site-packages/starlette/routing.py", line 734, in app
    await route.handle(scope, receive, send)
  File "/home/dfx_17/Projects/Slovo/schedule/backend/.venv/lib/python3.13/site-packages/starlette/routing.py", line 288, in handle
    await self.app(scope, receive, send)
  File "/home/dfx_17/Projects/Slovo/schedule/backend/.venv/lib/python3.13/site-packages/starlette/routing.py", line 76, in app
    await wrap_app_handling_exceptions(app, request)(scope, receive, send)
  File "/home/dfx_17/Projects/Slovo/schedule/backend/.venv/lib/python3.13/site-packages/starlette/_exception_handler.py", line 53, in wrapped_app
    raise exc
  File "/home/dfx_17/Projects/Slovo/schedule/backend/.venv/lib/python3.13/site-packages/starlette/_exception_handler.py", line 42, in wrapped_app
    await app(scope, receive, sender)
  File "/home/dfx_17/Projects/Slovo/schedule/backend/.venv/lib/python3.13/site-packages/starlette/routing.py", line 73, in app
    response = await f(request)
               ^^^^^^^^^^^^^^^^
  File "/home/dfx_17/Projects/Slovo/schedule/backend/.venv/lib/python3.13/site-packages/fastapi/routing.py", line 301, in app
    raw_response = await run_endpoint_function(
                   ^^^^^^^^^^^^^^^^^^^^^^^^^^^^
    ...<3 lines>...
    )
    ^
  File "/home/dfx_17/Projects/Slovo/schedule/backend/.venv/lib/python3.13/site-packages/fastapi/routing.py", line 212, in run_endpoint_function
    return await dependant.call(**values)
           ^^^^^^^^^^^^^^^^^^^^^^^^^^^^^^
  File "/home/dfx_17/Projects/Slovo/schedule/backend/src/api/appointment.py", line 50, in get_appointment
    return Appointment.from_bx(data)
           ^^^^^^^^^^^^^^^^^^^
  File "/home/dfx_17/Projects/Slovo/schedule/backend/.venv/lib/python3.13/site-packages/pydantic/_internal/_model_construction.py", line 271, in __getattr__
    raise AttributeError(item)
AttributeError: from_bx. Did you mean: 'from_orm'?

2025-06-06 12:24:07.699 | CRITICAL | /home/dfx_17/Projects/Slovo/schedule/backend/.venv/lib/python3.13/site-packages/starlette/applications.py:112 (__call__)
Traceback (most recent call last):
  File "/home/dfx_17/Projects/Slovo/schedule/backend/.venv/lib/python3.13/site-packages/starlette/middleware/base.py", line 148, in call_next
    message = await recv_stream.receive()
              ^^^^^^^^^^^^^^^^^^^^^^^^^^^
  File "/home/dfx_17/Projects/Slovo/schedule/backend/.venv/lib/python3.13/site-packages/anyio/streams/memory.py", line 126, in receive
    raise EndOfStream from None
anyio.EndOfStream

During handling of the above exception, another exception occurred:

Traceback (most recent call last):
  File "/home/dfx_17/Projects/Slovo/schedule/backend/src/middleware.py", line 39, in dispatch
    return await call_next(request)
           ^^^^^^^^^^^^^^^^^^^^^^^^
  File "/home/dfx_17/Projects/Slovo/schedule/backend/.venv/lib/python3.13/site-packages/starlette/middleware/base.py", line 156, in call_next
    raise app_exc
  File "/home/dfx_17/Projects/Slovo/schedule/backend/.venv/lib/python3.13/site-packages/starlette/middleware/base.py", line 141, in coro
    await self.app(scope, receive_or_disconnect, send_no_error)
  File "/home/dfx_17/Projects/Slovo/schedule/backend/.venv/lib/python3.13/site-packages/starlette/middleware/cors.py", line 85, in __call__
    await self.app(scope, receive, send)
  File "/home/dfx_17/Projects/Slovo/schedule/backend/.venv/lib/python3.13/site-packages/starlette/middleware/exceptions.py", line 62, in __call__
    await wrap_app_handling_exceptions(self.app, conn)(scope, receive, send)
  File "/home/dfx_17/Projects/Slovo/schedule/backend/.venv/lib/python3.13/site-packages/starlette/_exception_handler.py", line 53, in wrapped_app
    raise exc
  File "/home/dfx_17/Projects/Slovo/schedule/backend/.venv/lib/python3.13/site-packages/starlette/_exception_handler.py", line 42, in wrapped_app
    await app(scope, receive, sender)
  File "/home/dfx_17/Projects/Slovo/schedule/backend/.venv/lib/python3.13/site-packages/starlette/routing.py", line 714, in __call__
    await self.middleware_stack(scope, receive, send)
  File "/home/dfx_17/Projects/Slovo/schedule/backend/.venv/lib/python3.13/site-packages/starlette/routing.py", line 734, in app
    await route.handle(scope, receive, send)
  File "/home/dfx_17/Projects/Slovo/schedule/backend/.venv/lib/python3.13/site-packages/starlette/routing.py", line 288, in handle
    await self.app(scope, receive, send)
  File "/home/dfx_17/Projects/Slovo/schedule/backend/.venv/lib/python3.13/site-packages/starlette/routing.py", line 76, in app
    await wrap_app_handling_exceptions(app, request)(scope, receive, send)
  File "/home/dfx_17/Projects/Slovo/schedule/backend/.venv/lib/python3.13/site-packages/starlette/_exception_handler.py", line 53, in wrapped_app
    raise exc
  File "/home/dfx_17/Projects/Slovo/schedule/backend/.venv/lib/python3.13/site-packages/starlette/_exception_handler.py", line 42, in wrapped_app
    await app(scope, receive, sender)
  File "/home/dfx_17/Projects/Slovo/schedule/backend/.venv/lib/python3.13/site-packages/starlette/routing.py", line 73, in app
    response = await f(request)
               ^^^^^^^^^^^^^^^^
  File "/home/dfx_17/Projects/Slovo/schedule/backend/.venv/lib/python3.13/site-packages/fastapi/routing.py", line 301, in app
    raw_response = await run_endpoint_function(
                   ^^^^^^^^^^^^^^^^^^^^^^^^^^^^
    ...<3 lines>...
    )
    ^
  File "/home/dfx_17/Projects/Slovo/schedule/backend/.venv/lib/python3.13/site-packages/fastapi/routing.py", line 212, in run_endpoint_function
    return await dependant.call(**values)
           ^^^^^^^^^^^^^^^^^^^^^^^^^^^^^^
  File "/home/dfx_17/Projects/Slovo/schedule/backend/src/api/appointment.py", line 50, in get_appointment
    return Appointment.from_bx(data)
           ^^^^^^^^^^^^^^^^^^^
  File "/home/dfx_17/Projects/Slovo/schedule/backend/.venv/lib/python3.13/site-packages/pydantic/_internal/_model_construction.py", line 271, in __getattr__
    raise AttributeError(item)
AttributeError: from_bx. Did you mean: 'from_orm'?

2025-06-06 12:30:57.610 | CRITICAL | /home/dfx_17/Projects/Slovo/schedule/backend/.venv/lib/python3.13/site-packages/starlette/applications.py:112 (__call__)
Traceback (most recent call last):
  File "/home/dfx_17/Projects/Slovo/schedule/backend/src/middleware.py", line 40, in dispatch
    print(result.render())
          ~~~~~~~~~~~~~^^
TypeError: Response.render() missing 1 required positional argument: 'content'

2025-06-06 12:32:24.084 | CRITICAL | /home/dfx_17/Projects/Slovo/schedule/backend/.venv/lib/python3.13/site-packages/starlette/applications.py:112 (__call__)
Traceback (most recent call last):
  File "/home/dfx_17/Projects/Slovo/schedule/backend/src/middleware.py", line 40, in dispatch
    async for t in result.body_iterator():
                   ~~~~~~~~~~~~~~~~~~~~^^
TypeError: 'async_generator' object is not callable

2025-06-06 12:53:34.643 | CRITICAL | /home/dfx_17/Projects/Slovo/schedule/backend/.venv/lib/python3.13/site-packages/starlette/applications.py:112 (__call__)
Traceback (most recent call last):
  File "/home/dfx_17/Projects/Slovo/schedule/backend/.venv/lib/python3.13/site-packages/starlette/middleware/base.py", line 148, in call_next
    message = await recv_stream.receive()
              ^^^^^^^^^^^^^^^^^^^^^^^^^^^
  File "/home/dfx_17/Projects/Slovo/schedule/backend/.venv/lib/python3.13/site-packages/anyio/streams/memory.py", line 111, in receive
    return self.receive_nowait()
           ~~~~~~~~~~~~~~~~~~~^^
  File "/home/dfx_17/Projects/Slovo/schedule/backend/.venv/lib/python3.13/site-packages/anyio/streams/memory.py", line 104, in receive_nowait
    raise EndOfStream
anyio.EndOfStream

During handling of the above exception, another exception occurred:

Traceback (most recent call last):
  File "/home/dfx_17/Projects/Slovo/schedule/backend/src/middleware.py", line 39, in dispatch
    result = await call_next(request)
             ^^^^^^^^^^^^^^^^^^^^^^^^
  File "/home/dfx_17/Projects/Slovo/schedule/backend/.venv/lib/python3.13/site-packages/starlette/middleware/base.py", line 156, in call_next
    raise app_exc
  File "/home/dfx_17/Projects/Slovo/schedule/backend/.venv/lib/python3.13/site-packages/starlette/middleware/base.py", line 141, in coro
    await self.app(scope, receive_or_disconnect, send_no_error)
  File "/home/dfx_17/Projects/Slovo/schedule/backend/.venv/lib/python3.13/site-packages/starlette/middleware/cors.py", line 85, in __call__
    await self.app(scope, receive, send)
  File "/home/dfx_17/Projects/Slovo/schedule/backend/.venv/lib/python3.13/site-packages/starlette/middleware/exceptions.py", line 62, in __call__
    await wrap_app_handling_exceptions(self.app, conn)(scope, receive, send)
  File "/home/dfx_17/Projects/Slovo/schedule/backend/.venv/lib/python3.13/site-packages/starlette/_exception_handler.py", line 53, in wrapped_app
    raise exc
  File "/home/dfx_17/Projects/Slovo/schedule/backend/.venv/lib/python3.13/site-packages/starlette/_exception_handler.py", line 42, in wrapped_app
    await app(scope, receive, sender)
  File "/home/dfx_17/Projects/Slovo/schedule/backend/.venv/lib/python3.13/site-packages/starlette/routing.py", line 714, in __call__
    await self.middleware_stack(scope, receive, send)
  File "/home/dfx_17/Projects/Slovo/schedule/backend/.venv/lib/python3.13/site-packages/starlette/routing.py", line 734, in app
    await route.handle(scope, receive, send)
  File "/home/dfx_17/Projects/Slovo/schedule/backend/.venv/lib/python3.13/site-packages/starlette/routing.py", line 288, in handle
    await self.app(scope, receive, send)
  File "/home/dfx_17/Projects/Slovo/schedule/backend/.venv/lib/python3.13/site-packages/starlette/routing.py", line 76, in app
    await wrap_app_handling_exceptions(app, request)(scope, receive, send)
  File "/home/dfx_17/Projects/Slovo/schedule/backend/.venv/lib/python3.13/site-packages/starlette/_exception_handler.py", line 53, in wrapped_app
    raise exc
  File "/home/dfx_17/Projects/Slovo/schedule/backend/.venv/lib/python3.13/site-packages/starlette/_exception_handler.py", line 42, in wrapped_app
    await app(scope, receive, sender)
  File "/home/dfx_17/Projects/Slovo/schedule/backend/.venv/lib/python3.13/site-packages/starlette/routing.py", line 73, in app
    response = await f(request)
               ^^^^^^^^^^^^^^^^
  File "/home/dfx_17/Projects/Slovo/schedule/backend/.venv/lib/python3.13/site-packages/fastapi/routing.py", line 301, in app
    raw_response = await run_endpoint_function(
                   ^^^^^^^^^^^^^^^^^^^^^^^^^^^^
    ...<3 lines>...
    )
    ^
  File "/home/dfx_17/Projects/Slovo/schedule/backend/.venv/lib/python3.13/site-packages/fastapi/routing.py", line 212, in run_endpoint_function
    return await dependant.call(**values)
           ^^^^^^^^^^^^^^^^^^^^^^^^^^^^^^
  File "/home/dfx_17/Projects/Slovo/schedule/backend/src/api/appointment.py", line 46, in get_appointment
    1 / 0
    ~~^~~
ZeroDivisionError: division by zero

2025-06-06 12:57:09.725 | CRITICAL | /home/dfx_17/Projects/Slovo/schedule/backend/.venv/lib/python3.13/site-packages/starlette/applications.py:112 (__call__)
Traceback (most recent call last):
  File "/home/dfx_17/Projects/Slovo/schedule/backend/.venv/lib/python3.13/site-packages/starlette/middleware/base.py", line 148, in call_next
    message = await recv_stream.receive()
              ^^^^^^^^^^^^^^^^^^^^^^^^^^^
  File "/home/dfx_17/Projects/Slovo/schedule/backend/.venv/lib/python3.13/site-packages/anyio/streams/memory.py", line 111, in receive
    return self.receive_nowait()
           ~~~~~~~~~~~~~~~~~~~^^
  File "/home/dfx_17/Projects/Slovo/schedule/backend/.venv/lib/python3.13/site-packages/anyio/streams/memory.py", line 104, in receive_nowait
    raise EndOfStream
anyio.EndOfStream

During handling of the above exception, another exception occurred:

Traceback (most recent call last):
  File "/home/dfx_17/Projects/Slovo/schedule/backend/src/middleware.py", line 32, in dispatch
    return await call_next(request)
           ^^^^^^^^^^^^^^^^^^^^^^^^
  File "/home/dfx_17/Projects/Slovo/schedule/backend/.venv/lib/python3.13/site-packages/starlette/middleware/base.py", line 156, in call_next
    raise app_exc
  File "/home/dfx_17/Projects/Slovo/schedule/backend/.venv/lib/python3.13/site-packages/starlette/middleware/base.py", line 141, in coro
    await self.app(scope, receive_or_disconnect, send_no_error)
  File "/home/dfx_17/Projects/Slovo/schedule/backend/.venv/lib/python3.13/site-packages/starlette/middleware/cors.py", line 85, in __call__
    await self.app(scope, receive, send)
  File "/home/dfx_17/Projects/Slovo/schedule/backend/.venv/lib/python3.13/site-packages/starlette/middleware/exceptions.py", line 62, in __call__
    await wrap_app_handling_exceptions(self.app, conn)(scope, receive, send)
  File "/home/dfx_17/Projects/Slovo/schedule/backend/.venv/lib/python3.13/site-packages/starlette/_exception_handler.py", line 53, in wrapped_app
    raise exc
  File "/home/dfx_17/Projects/Slovo/schedule/backend/.venv/lib/python3.13/site-packages/starlette/_exception_handler.py", line 42, in wrapped_app
    await app(scope, receive, sender)
  File "/home/dfx_17/Projects/Slovo/schedule/backend/.venv/lib/python3.13/site-packages/starlette/routing.py", line 714, in __call__
    await self.middleware_stack(scope, receive, send)
  File "/home/dfx_17/Projects/Slovo/schedule/backend/.venv/lib/python3.13/site-packages/starlette/routing.py", line 734, in app
    await route.handle(scope, receive, send)
  File "/home/dfx_17/Projects/Slovo/schedule/backend/.venv/lib/python3.13/site-packages/starlette/routing.py", line 288, in handle
    await self.app(scope, receive, send)
  File "/home/dfx_17/Projects/Slovo/schedule/backend/.venv/lib/python3.13/site-packages/starlette/routing.py", line 76, in app
    await wrap_app_handling_exceptions(app, request)(scope, receive, send)
  File "/home/dfx_17/Projects/Slovo/schedule/backend/.venv/lib/python3.13/site-packages/starlette/_exception_handler.py", line 53, in wrapped_app
    raise exc
  File "/home/dfx_17/Projects/Slovo/schedule/backend/.venv/lib/python3.13/site-packages/starlette/_exception_handler.py", line 42, in wrapped_app
    await app(scope, receive, sender)
  File "/home/dfx_17/Projects/Slovo/schedule/backend/.venv/lib/python3.13/site-packages/starlette/routing.py", line 73, in app
    response = await f(request)
               ^^^^^^^^^^^^^^^^
  File "/home/dfx_17/Projects/Slovo/schedule/backend/.venv/lib/python3.13/site-packages/fastapi/routing.py", line 301, in app
    raw_response = await run_endpoint_function(
                   ^^^^^^^^^^^^^^^^^^^^^^^^^^^^
    ...<3 lines>...
    )
    ^
  File "/home/dfx_17/Projects/Slovo/schedule/backend/.venv/lib/python3.13/site-packages/fastapi/routing.py", line 212, in run_endpoint_function
    return await dependant.call(**values)
           ^^^^^^^^^^^^^^^^^^^^^^^^^^^^^^
  File "/home/dfx_17/Projects/Slovo/schedule/backend/src/api/appointment.py", line 46, in get_appointment
    1 / 0
    ~~^~~
ZeroDivisionError: division by zero

2025-06-06 12:58:28.767 | CRITICAL | /home/dfx_17/Projects/Slovo/schedule/backend/.venv/lib/python3.13/site-packages/starlette/applications.py:112 (__call__)
Traceback (most recent call last):
  File "/home/dfx_17/Projects/Slovo/schedule/backend/.venv/lib/python3.13/site-packages/starlette/middleware/base.py", line 148, in call_next
    message = await recv_stream.receive()
              ^^^^^^^^^^^^^^^^^^^^^^^^^^^
  File "/home/dfx_17/Projects/Slovo/schedule/backend/.venv/lib/python3.13/site-packages/anyio/streams/memory.py", line 126, in receive
    raise EndOfStream from None
anyio.EndOfStream

During handling of the above exception, another exception occurred:

Traceback (most recent call last):
  File "/home/dfx_17/Projects/Slovo/schedule/backend/src/middleware.py", line 32, in dispatch
    return await call_next(request)
           ^^^^^^^^^^^^^^^^^^^^^^^^
  File "/home/dfx_17/Projects/Slovo/schedule/backend/.venv/lib/python3.13/site-packages/starlette/middleware/base.py", line 156, in call_next
    raise app_exc
  File "/home/dfx_17/Projects/Slovo/schedule/backend/.venv/lib/python3.13/site-packages/starlette/middleware/base.py", line 141, in coro
    await self.app(scope, receive_or_disconnect, send_no_error)
  File "/home/dfx_17/Projects/Slovo/schedule/backend/.venv/lib/python3.13/site-packages/starlette/middleware/cors.py", line 85, in __call__
    await self.app(scope, receive, send)
  File "/home/dfx_17/Projects/Slovo/schedule/backend/.venv/lib/python3.13/site-packages/starlette/middleware/exceptions.py", line 62, in __call__
    await wrap_app_handling_exceptions(self.app, conn)(scope, receive, send)
  File "/home/dfx_17/Projects/Slovo/schedule/backend/.venv/lib/python3.13/site-packages/starlette/_exception_handler.py", line 53, in wrapped_app
    raise exc
  File "/home/dfx_17/Projects/Slovo/schedule/backend/.venv/lib/python3.13/site-packages/starlette/_exception_handler.py", line 42, in wrapped_app
    await app(scope, receive, sender)
  File "/home/dfx_17/Projects/Slovo/schedule/backend/.venv/lib/python3.13/site-packages/starlette/routing.py", line 714, in __call__
    await self.middleware_stack(scope, receive, send)
  File "/home/dfx_17/Projects/Slovo/schedule/backend/.venv/lib/python3.13/site-packages/starlette/routing.py", line 734, in app
    await route.handle(scope, receive, send)
  File "/home/dfx_17/Projects/Slovo/schedule/backend/.venv/lib/python3.13/site-packages/starlette/routing.py", line 288, in handle
    await self.app(scope, receive, send)
  File "/home/dfx_17/Projects/Slovo/schedule/backend/.venv/lib/python3.13/site-packages/starlette/routing.py", line 76, in app
    await wrap_app_handling_exceptions(app, request)(scope, receive, send)
  File "/home/dfx_17/Projects/Slovo/schedule/backend/.venv/lib/python3.13/site-packages/starlette/_exception_handler.py", line 63, in wrapped_app
    await response(scope, receive, sender)
          ~~~~~~~~^^^^^^^^^^^^^^^^^^^^^^^^
TypeError: 'HTTPException' object is not callable

2025-06-06 12:59:16.924 | CRITICAL | /home/dfx_17/Projects/Slovo/schedule/backend/.venv/lib/python3.13/site-packages/starlette/applications.py:112 (__call__)
Traceback (most recent call last):
  File "/home/dfx_17/Projects/Slovo/schedule/backend/.venv/lib/python3.13/site-packages/starlette/middleware/base.py", line 148, in call_next
    message = await recv_stream.receive()
              ^^^^^^^^^^^^^^^^^^^^^^^^^^^
  File "/home/dfx_17/Projects/Slovo/schedule/backend/.venv/lib/python3.13/site-packages/anyio/streams/memory.py", line 126, in receive
    raise EndOfStream from None
anyio.EndOfStream

During handling of the above exception, another exception occurred:

Traceback (most recent call last):
  File "/home/dfx_17/Projects/Slovo/schedule/backend/src/middleware.py", line 32, in dispatch
    return await call_next(request)
           ^^^^^^^^^^^^^^^^^^^^^^^^
  File "/home/dfx_17/Projects/Slovo/schedule/backend/.venv/lib/python3.13/site-packages/starlette/middleware/base.py", line 156, in call_next
    raise app_exc
  File "/home/dfx_17/Projects/Slovo/schedule/backend/.venv/lib/python3.13/site-packages/starlette/middleware/base.py", line 141, in coro
    await self.app(scope, receive_or_disconnect, send_no_error)
  File "/home/dfx_17/Projects/Slovo/schedule/backend/.venv/lib/python3.13/site-packages/starlette/middleware/cors.py", line 85, in __call__
    await self.app(scope, receive, send)
  File "/home/dfx_17/Projects/Slovo/schedule/backend/.venv/lib/python3.13/site-packages/starlette/middleware/exceptions.py", line 62, in __call__
    await wrap_app_handling_exceptions(self.app, conn)(scope, receive, send)
  File "/home/dfx_17/Projects/Slovo/schedule/backend/.venv/lib/python3.13/site-packages/starlette/_exception_handler.py", line 59, in wrapped_app
    response = await handler(conn, exc)
               ^^^^^^^^^^^^^^^^^^^^^^^^
  File "/home/dfx_17/Projects/Slovo/schedule/backend/main.py", line 29, in handle_exception
    raise exc
  File "/home/dfx_17/Projects/Slovo/schedule/backend/.venv/lib/python3.13/site-packages/starlette/_exception_handler.py", line 42, in wrapped_app
    await app(scope, receive, sender)
  File "/home/dfx_17/Projects/Slovo/schedule/backend/.venv/lib/python3.13/site-packages/starlette/routing.py", line 714, in __call__
    await self.middleware_stack(scope, receive, send)
  File "/home/dfx_17/Projects/Slovo/schedule/backend/.venv/lib/python3.13/site-packages/starlette/routing.py", line 734, in app
    await route.handle(scope, receive, send)
  File "/home/dfx_17/Projects/Slovo/schedule/backend/.venv/lib/python3.13/site-packages/starlette/routing.py", line 288, in handle
    await self.app(scope, receive, send)
  File "/home/dfx_17/Projects/Slovo/schedule/backend/.venv/lib/python3.13/site-packages/starlette/routing.py", line 76, in app
    await wrap_app_handling_exceptions(app, request)(scope, receive, send)
  File "/home/dfx_17/Projects/Slovo/schedule/backend/.venv/lib/python3.13/site-packages/starlette/_exception_handler.py", line 59, in wrapped_app
    response = await handler(conn, exc)
               ^^^^^^^^^^^^^^^^^^^^^^^^
  File "/home/dfx_17/Projects/Slovo/schedule/backend/main.py", line 29, in handle_exception
    raise exc
  File "/home/dfx_17/Projects/Slovo/schedule/backend/.venv/lib/python3.13/site-packages/starlette/_exception_handler.py", line 42, in wrapped_app
    await app(scope, receive, sender)
  File "/home/dfx_17/Projects/Slovo/schedule/backend/.venv/lib/python3.13/site-packages/starlette/routing.py", line 73, in app
    response = await f(request)
               ^^^^^^^^^^^^^^^^
  File "/home/dfx_17/Projects/Slovo/schedule/backend/.venv/lib/python3.13/site-packages/fastapi/routing.py", line 301, in app
    raw_response = await run_endpoint_function(
                   ^^^^^^^^^^^^^^^^^^^^^^^^^^^^
    ...<3 lines>...
    )
    ^
  File "/home/dfx_17/Projects/Slovo/schedule/backend/.venv/lib/python3.13/site-packages/fastapi/routing.py", line 212, in run_endpoint_function
    return await dependant.call(**values)
           ^^^^^^^^^^^^^^^^^^^^^^^^^^^^^^
  File "/home/dfx_17/Projects/Slovo/schedule/backend/src/api/appointment.py", line 48, in get_appointment
    raise HTTPException(status_code=404, detail="Appointment not found")
fastapi.exceptions.HTTPException: 404: Appointment not found

2025-06-06 12:59:45.184 | CRITICAL | /home/dfx_17/Projects/Slovo/schedule/backend/.venv/lib/python3.13/site-packages/starlette/applications.py:112 (__call__)
Traceback (most recent call last):
  File "/home/dfx_17/Projects/Slovo/schedule/backend/.venv/lib/python3.13/site-packages/starlette/middleware/base.py", line 148, in call_next
    message = await recv_stream.receive()
              ^^^^^^^^^^^^^^^^^^^^^^^^^^^
  File "/home/dfx_17/Projects/Slovo/schedule/backend/.venv/lib/python3.13/site-packages/anyio/streams/memory.py", line 126, in receive
    raise EndOfStream from None
anyio.EndOfStream

During handling of the above exception, another exception occurred:

Traceback (most recent call last):
  File "/home/dfx_17/Projects/Slovo/schedule/backend/src/middleware.py", line 32, in dispatch
    return await call_next(request)
           ^^^^^^^^^^^^^^^^^^^^^^^^
  File "/home/dfx_17/Projects/Slovo/schedule/backend/.venv/lib/python3.13/site-packages/starlette/middleware/base.py", line 157, in call_next
    raise RuntimeError("No response returned.")
RuntimeError: No response returned.

2025-06-06 13:08:53.687 | CRITICAL | /home/dfx_17/Projects/Slovo/schedule/backend/.venv/lib/python3.13/site-packages/starlette/applications.py:112 (__call__)
Traceback (most recent call last):
  File "/home/dfx_17/Projects/Slovo/schedule/backend/.venv/lib/python3.13/site-packages/starlette/middleware/base.py", line 148, in call_next
    message = await recv_stream.receive()
              ^^^^^^^^^^^^^^^^^^^^^^^^^^^
  File "/home/dfx_17/Projects/Slovo/schedule/backend/.venv/lib/python3.13/site-packages/anyio/streams/memory.py", line 126, in receive
    raise EndOfStream from None
anyio.EndOfStream

During handling of the above exception, another exception occurred:

Traceback (most recent call last):
  File "/home/dfx_17/Projects/Slovo/schedule/backend/src/middleware.py", line 32, in dispatch
    return await call_next(request)
           ^^^^^^^^^^^^^^^^^^^^^^^^
  File "/home/dfx_17/Projects/Slovo/schedule/backend/.venv/lib/python3.13/site-packages/starlette/middleware/base.py", line 156, in call_next
    raise app_exc
  File "/home/dfx_17/Projects/Slovo/schedule/backend/.venv/lib/python3.13/site-packages/starlette/middleware/base.py", line 141, in coro
    await self.app(scope, receive_or_disconnect, send_no_error)
  File "/home/dfx_17/Projects/Slovo/schedule/backend/.venv/lib/python3.13/site-packages/starlette/middleware/cors.py", line 85, in __call__
    await self.app(scope, receive, send)
  File "/home/dfx_17/Projects/Slovo/schedule/backend/.venv/lib/python3.13/site-packages/starlette/middleware/exceptions.py", line 62, in __call__
    await wrap_app_handling_exceptions(self.app, conn)(scope, receive, send)
  File "/home/dfx_17/Projects/Slovo/schedule/backend/.venv/lib/python3.13/site-packages/starlette/_exception_handler.py", line 53, in wrapped_app
    raise exc
  File "/home/dfx_17/Projects/Slovo/schedule/backend/.venv/lib/python3.13/site-packages/starlette/_exception_handler.py", line 42, in wrapped_app
    await app(scope, receive, sender)
  File "/home/dfx_17/Projects/Slovo/schedule/backend/.venv/lib/python3.13/site-packages/starlette/routing.py", line 714, in __call__
    await self.middleware_stack(scope, receive, send)
  File "/home/dfx_17/Projects/Slovo/schedule/backend/.venv/lib/python3.13/site-packages/starlette/routing.py", line 734, in app
    await route.handle(scope, receive, send)
  File "/home/dfx_17/Projects/Slovo/schedule/backend/.venv/lib/python3.13/site-packages/starlette/routing.py", line 288, in handle
    await self.app(scope, receive, send)
  File "/home/dfx_17/Projects/Slovo/schedule/backend/.venv/lib/python3.13/site-packages/starlette/routing.py", line 76, in app
    await wrap_app_handling_exceptions(app, request)(scope, receive, send)
  File "/home/dfx_17/Projects/Slovo/schedule/backend/.venv/lib/python3.13/site-packages/starlette/_exception_handler.py", line 61, in wrapped_app
    response = await run_in_threadpool(handler, conn, exc)  # type: ignore
               ^^^^^^^^^^^^^^^^^^^^^^^^^^^^^^^^^^^^^^^^^^^
  File "/home/dfx_17/Projects/Slovo/schedule/backend/.venv/lib/python3.13/site-packages/starlette/concurrency.py", line 37, in run_in_threadpool
    return await anyio.to_thread.run_sync(func)
           ^^^^^^^^^^^^^^^^^^^^^^^^^^^^^^^^^^^^
  File "/home/dfx_17/Projects/Slovo/schedule/backend/.venv/lib/python3.13/site-packages/anyio/to_thread.py", line 56, in run_sync
    return await get_async_backend().run_sync_in_worker_thread(
           ^^^^^^^^^^^^^^^^^^^^^^^^^^^^^^^^^^^^^^^^^^^^^^^^^^^^
        func, args, abandon_on_cancel=abandon_on_cancel, limiter=limiter
        ^^^^^^^^^^^^^^^^^^^^^^^^^^^^^^^^^^^^^^^^^^^^^^^^^^^^^^^^^^^^^^^^
    )
    ^
  File "/home/dfx_17/Projects/Slovo/schedule/backend/.venv/lib/python3.13/site-packages/anyio/_backends/_asyncio.py", line 2470, in run_sync_in_worker_thread
    return await future
           ^^^^^^^^^^^^
  File "/home/dfx_17/Projects/Slovo/schedule/backend/.venv/lib/python3.13/site-packages/anyio/_backends/_asyncio.py", line 967, in run
    result = context.run(func, *args)
  File "/home/dfx_17/Projects/Slovo/schedule/backend/src/utils/funcs.py", line 12, in handle_http_exception
    asyncio.create_task(coro())
    ~~~~~~~~~~~~~~~~~~~^^^^^^^^
  File "/usr/lib/python3.13/asyncio/tasks.py", line 407, in create_task
    loop = events.get_running_loop()
RuntimeError: no running event loop

