2025-06-06 20:03:41.660 | CRITICAL | /home/dfx_17/Projects/Slovo/schedule/backend/.venv/lib/python3.13/site-packages/starlette/applications.py:112 (__call__)
Traceback (most recent call last):
  File "/home/dfx_17/Projects/Slovo/schedule/backend/.venv/lib/python3.13/site-packages/starlette/middleware/base.py", line 148, in call_next
    message = await recv_stream.receive()
              ^^^^^^^^^^^^^^^^^^^^^^^^^^^
  File "/home/dfx_17/Projects/Slovo/schedule/backend/.venv/lib/python3.13/site-packages/anyio/streams/memory.py", line 111, in receive
    return self.receive_nowait()
           ~~~~~~~~~~~~~~~~~~~^^
  File "/home/dfx_17/Projects/Slovo/schedule/backend/.venv/lib/python3.13/site-packages/anyio/streams/memory.py", line 104, in receive_nowait
    raise EndOfStream
anyio.EndOfStream

During handling of the above exception, another exception occurred:

Traceback (most recent call last):
  File "/home/dfx_17/Projects/Slovo/schedule/backend/src/middleware.py", line 32, in dispatch
    return await call_next(request)
           ^^^^^^^^^^^^^^^^^^^^^^^^
  File "/home/dfx_17/Projects/Slovo/schedule/backend/.venv/lib/python3.13/site-packages/starlette/middleware/base.py", line 156, in call_next
    raise app_exc
  File "/home/dfx_17/Projects/Slovo/schedule/backend/.venv/lib/python3.13/site-packages/starlette/middleware/base.py", line 141, in coro
    await self.app(scope, receive_or_disconnect, send_no_error)
  File "/home/dfx_17/Projects/Slovo/schedule/backend/.venv/lib/python3.13/site-packages/starlette/middleware/cors.py", line 85, in __call__
    await self.app(scope, receive, send)
  File "/home/dfx_17/Projects/Slovo/schedule/backend/.venv/lib/python3.13/site-packages/starlette/middleware/exceptions.py", line 62, in __call__
    await wrap_app_handling_exceptions(self.app, conn)(scope, receive, send)
  File "/home/dfx_17/Projects/Slovo/schedule/backend/.venv/lib/python3.13/site-packages/starlette/_exception_handler.py", line 53, in wrapped_app
    raise exc
  File "/home/dfx_17/Projects/Slovo/schedule/backend/.venv/lib/python3.13/site-packages/starlette/_exception_handler.py", line 42, in wrapped_app
    await app(scope, receive, sender)
  File "/home/dfx_17/Projects/Slovo/schedule/backend/.venv/lib/python3.13/site-packages/starlette/routing.py", line 714, in __call__
    await self.middleware_stack(scope, receive, send)
  File "/home/dfx_17/Projects/Slovo/schedule/backend/.venv/lib/python3.13/site-packages/starlette/routing.py", line 734, in app
    await route.handle(scope, receive, send)
  File "/home/dfx_17/Projects/Slovo/schedule/backend/.venv/lib/python3.13/site-packages/starlette/routing.py", line 288, in handle
    await self.app(scope, receive, send)
  File "/home/dfx_17/Projects/Slovo/schedule/backend/.venv/lib/python3.13/site-packages/starlette/routing.py", line 76, in app
    await wrap_app_handling_exceptions(app, request)(scope, receive, send)
  File "/home/dfx_17/Projects/Slovo/schedule/backend/.venv/lib/python3.13/site-packages/starlette/_exception_handler.py", line 53, in wrapped_app
    raise exc
  File "/home/dfx_17/Projects/Slovo/schedule/backend/.venv/lib/python3.13/site-packages/starlette/_exception_handler.py", line 42, in wrapped_app
    await app(scope, receive, sender)
  File "/home/dfx_17/Projects/Slovo/schedule/backend/.venv/lib/python3.13/site-packages/starlette/routing.py", line 73, in app
    response = await f(request)
               ^^^^^^^^^^^^^^^^
  File "/home/dfx_17/Projects/Slovo/schedule/backend/.venv/lib/python3.13/site-packages/fastapi/routing.py", line 301, in app
    raw_response = await run_endpoint_function(
                   ^^^^^^^^^^^^^^^^^^^^^^^^^^^^
    ...<3 lines>...
    )
    ^
  File "/home/dfx_17/Projects/Slovo/schedule/backend/.venv/lib/python3.13/site-packages/fastapi/routing.py", line 212, in run_endpoint_function
    return await dependant.call(**values)
           ^^^^^^^^^^^^^^^^^^^^^^^^^^^^^^
  File "/home/dfx_17/Projects/Slovo/schedule/backend/src/api/appointment.py", line 26, in get_appointment
    1 /0
    ~~^~
ZeroDivisionError: division by zero

2025-06-06 20:18:47.256 | CRITICAL | /home/dfx_17/Projects/Slovo/schedule/backend/.venv/lib/python3.13/site-packages/starlette/applications.py:112 (__call__)
Traceback (most recent call last):
  File "/home/dfx_17/Projects/Slovo/schedule/backend/.venv/lib/python3.13/site-packages/starlette/middleware/base.py", line 148, in call_next
    message = await recv_stream.receive()
              ^^^^^^^^^^^^^^^^^^^^^^^^^^^
  File "/home/dfx_17/Projects/Slovo/schedule/backend/.venv/lib/python3.13/site-packages/anyio/streams/memory.py", line 111, in receive
    return self.receive_nowait()
           ~~~~~~~~~~~~~~~~~~~^^
  File "/home/dfx_17/Projects/Slovo/schedule/backend/.venv/lib/python3.13/site-packages/anyio/streams/memory.py", line 104, in receive_nowait
    raise EndOfStream
anyio.EndOfStream

During handling of the above exception, another exception occurred:

Traceback (most recent call last):
  File "/home/dfx_17/Projects/Slovo/schedule/backend/src/middleware.py", line 32, in dispatch
    return await call_next(request)
           ^^^^^^^^^^^^^^^^^^^^^^^^
  File "/home/dfx_17/Projects/Slovo/schedule/backend/.venv/lib/python3.13/site-packages/starlette/middleware/base.py", line 156, in call_next
    raise app_exc
  File "/home/dfx_17/Projects/Slovo/schedule/backend/.venv/lib/python3.13/site-packages/starlette/middleware/base.py", line 141, in coro
    await self.app(scope, receive_or_disconnect, send_no_error)
  File "/home/dfx_17/Projects/Slovo/schedule/backend/.venv/lib/python3.13/site-packages/starlette/middleware/cors.py", line 85, in __call__
    await self.app(scope, receive, send)
  File "/home/dfx_17/Projects/Slovo/schedule/backend/.venv/lib/python3.13/site-packages/starlette/middleware/exceptions.py", line 62, in __call__
    await wrap_app_handling_exceptions(self.app, conn)(scope, receive, send)
  File "/home/dfx_17/Projects/Slovo/schedule/backend/.venv/lib/python3.13/site-packages/starlette/_exception_handler.py", line 53, in wrapped_app
    raise exc
  File "/home/dfx_17/Projects/Slovo/schedule/backend/.venv/lib/python3.13/site-packages/starlette/_exception_handler.py", line 42, in wrapped_app
    await app(scope, receive, sender)
  File "/home/dfx_17/Projects/Slovo/schedule/backend/.venv/lib/python3.13/site-packages/starlette/routing.py", line 714, in __call__
    await self.middleware_stack(scope, receive, send)
  File "/home/dfx_17/Projects/Slovo/schedule/backend/.venv/lib/python3.13/site-packages/starlette/routing.py", line 734, in app
    await route.handle(scope, receive, send)
  File "/home/dfx_17/Projects/Slovo/schedule/backend/.venv/lib/python3.13/site-packages/starlette/routing.py", line 288, in handle
    await self.app(scope, receive, send)
  File "/home/dfx_17/Projects/Slovo/schedule/backend/.venv/lib/python3.13/site-packages/starlette/routing.py", line 76, in app
    await wrap_app_handling_exceptions(app, request)(scope, receive, send)
  File "/home/dfx_17/Projects/Slovo/schedule/backend/.venv/lib/python3.13/site-packages/starlette/_exception_handler.py", line 53, in wrapped_app
    raise exc
  File "/home/dfx_17/Projects/Slovo/schedule/backend/.venv/lib/python3.13/site-packages/starlette/_exception_handler.py", line 42, in wrapped_app
    await app(scope, receive, sender)
  File "/home/dfx_17/Projects/Slovo/schedule/backend/.venv/lib/python3.13/site-packages/starlette/routing.py", line 73, in app
    response = await f(request)
               ^^^^^^^^^^^^^^^^
  File "/home/dfx_17/Projects/Slovo/schedule/backend/.venv/lib/python3.13/site-packages/fastapi/routing.py", line 301, in app
    raw_response = await run_endpoint_function(
                   ^^^^^^^^^^^^^^^^^^^^^^^^^^^^
    ...<3 lines>...
    )
    ^
  File "/home/dfx_17/Projects/Slovo/schedule/backend/.venv/lib/python3.13/site-packages/fastapi/routing.py", line 212, in run_endpoint_function
    return await dependant.call(**values)
           ^^^^^^^^^^^^^^^^^^^^^^^^^^^^^^
  File "/home/dfx_17/Projects/Slovo/schedule/backend/src/api/appointment.py", line 26, in get_appointment
    1 / 0
    ~~^~~
ZeroDivisionError: division by zero

2025-06-06 20:19:52.150 | CRITICAL | /home/dfx_17/Projects/Slovo/schedule/backend/.venv/lib/python3.13/site-packages/starlette/applications.py:112 (__call__)
Traceback (most recent call last):
  File "/home/dfx_17/Projects/Slovo/schedule/backend/.venv/lib/python3.13/site-packages/starlette/middleware/base.py", line 148, in call_next
    message = await recv_stream.receive()
              ^^^^^^^^^^^^^^^^^^^^^^^^^^^
  File "/home/dfx_17/Projects/Slovo/schedule/backend/.venv/lib/python3.13/site-packages/anyio/streams/memory.py", line 111, in receive
    return self.receive_nowait()
           ~~~~~~~~~~~~~~~~~~~^^
  File "/home/dfx_17/Projects/Slovo/schedule/backend/.venv/lib/python3.13/site-packages/anyio/streams/memory.py", line 104, in receive_nowait
    raise EndOfStream
anyio.EndOfStream

During handling of the above exception, another exception occurred:

Traceback (most recent call last):
  File "/home/dfx_17/Projects/Slovo/schedule/backend/src/middleware.py", line 32, in dispatch
    return await call_next(request)
           ^^^^^^^^^^^^^^^^^^^^^^^^
  File "/home/dfx_17/Projects/Slovo/schedule/backend/.venv/lib/python3.13/site-packages/starlette/middleware/base.py", line 156, in call_next
    raise app_exc
  File "/home/dfx_17/Projects/Slovo/schedule/backend/.venv/lib/python3.13/site-packages/starlette/middleware/base.py", line 141, in coro
    await self.app(scope, receive_or_disconnect, send_no_error)
  File "/home/dfx_17/Projects/Slovo/schedule/backend/.venv/lib/python3.13/site-packages/starlette/middleware/cors.py", line 85, in __call__
    await self.app(scope, receive, send)
  File "/home/dfx_17/Projects/Slovo/schedule/backend/.venv/lib/python3.13/site-packages/starlette/middleware/exceptions.py", line 62, in __call__
    await wrap_app_handling_exceptions(self.app, conn)(scope, receive, send)
  File "/home/dfx_17/Projects/Slovo/schedule/backend/.venv/lib/python3.13/site-packages/starlette/_exception_handler.py", line 53, in wrapped_app
    raise exc
  File "/home/dfx_17/Projects/Slovo/schedule/backend/.venv/lib/python3.13/site-packages/starlette/_exception_handler.py", line 42, in wrapped_app
    await app(scope, receive, sender)
  File "/home/dfx_17/Projects/Slovo/schedule/backend/.venv/lib/python3.13/site-packages/starlette/routing.py", line 714, in __call__
    await self.middleware_stack(scope, receive, send)
  File "/home/dfx_17/Projects/Slovo/schedule/backend/.venv/lib/python3.13/site-packages/starlette/routing.py", line 734, in app
    await route.handle(scope, receive, send)
  File "/home/dfx_17/Projects/Slovo/schedule/backend/.venv/lib/python3.13/site-packages/starlette/routing.py", line 288, in handle
    await self.app(scope, receive, send)
  File "/home/dfx_17/Projects/Slovo/schedule/backend/.venv/lib/python3.13/site-packages/starlette/routing.py", line 76, in app
    await wrap_app_handling_exceptions(app, request)(scope, receive, send)
  File "/home/dfx_17/Projects/Slovo/schedule/backend/.venv/lib/python3.13/site-packages/starlette/_exception_handler.py", line 53, in wrapped_app
    raise exc
  File "/home/dfx_17/Projects/Slovo/schedule/backend/.venv/lib/python3.13/site-packages/starlette/_exception_handler.py", line 42, in wrapped_app
    await app(scope, receive, sender)
  File "/home/dfx_17/Projects/Slovo/schedule/backend/.venv/lib/python3.13/site-packages/starlette/routing.py", line 73, in app
    response = await f(request)
               ^^^^^^^^^^^^^^^^
  File "/home/dfx_17/Projects/Slovo/schedule/backend/.venv/lib/python3.13/site-packages/fastapi/routing.py", line 301, in app
    raw_response = await run_endpoint_function(
                   ^^^^^^^^^^^^^^^^^^^^^^^^^^^^
    ...<3 lines>...
    )
    ^
  File "/home/dfx_17/Projects/Slovo/schedule/backend/.venv/lib/python3.13/site-packages/fastapi/routing.py", line 212, in run_endpoint_function
    return await dependant.call(**values)
           ^^^^^^^^^^^^^^^^^^^^^^^^^^^^^^
  File "/home/dfx_17/Projects/Slovo/schedule/backend/src/api/appointment.py", line 26, in get_appointment
    1 / 0
    ~~^~~
ZeroDivisionError: division by zero

2025-06-06 20:27:29.511 | CRITICAL | /home/dfx_17/Projects/Slovo/schedule/backend/.venv/lib/python3.13/site-packages/starlette/applications.py:112 (__call__)
Traceback (most recent call last):
  File "/home/dfx_17/Projects/Slovo/schedule/backend/.venv/lib/python3.13/site-packages/starlette/middleware/base.py", line 148, in call_next
    message = await recv_stream.receive()
              ^^^^^^^^^^^^^^^^^^^^^^^^^^^
  File "/home/dfx_17/Projects/Slovo/schedule/backend/.venv/lib/python3.13/site-packages/anyio/streams/memory.py", line 111, in receive
    return self.receive_nowait()
           ~~~~~~~~~~~~~~~~~~~^^
  File "/home/dfx_17/Projects/Slovo/schedule/backend/.venv/lib/python3.13/site-packages/anyio/streams/memory.py", line 104, in receive_nowait
    raise EndOfStream
anyio.EndOfStream

During handling of the above exception, another exception occurred:

Traceback (most recent call last):
  File "/home/dfx_17/Projects/Slovo/schedule/backend/src/middleware.py", line 32, in dispatch
    return await call_next(request)
           ^^^^^^^^^^^^^^^^^^^^^^^^
  File "/home/dfx_17/Projects/Slovo/schedule/backend/.venv/lib/python3.13/site-packages/starlette/middleware/base.py", line 156, in call_next
    raise app_exc
  File "/home/dfx_17/Projects/Slovo/schedule/backend/.venv/lib/python3.13/site-packages/starlette/middleware/base.py", line 141, in coro
    await self.app(scope, receive_or_disconnect, send_no_error)
  File "/home/dfx_17/Projects/Slovo/schedule/backend/.venv/lib/python3.13/site-packages/starlette/middleware/cors.py", line 85, in __call__
    await self.app(scope, receive, send)
  File "/home/dfx_17/Projects/Slovo/schedule/backend/.venv/lib/python3.13/site-packages/starlette/middleware/exceptions.py", line 62, in __call__
    await wrap_app_handling_exceptions(self.app, conn)(scope, receive, send)
  File "/home/dfx_17/Projects/Slovo/schedule/backend/.venv/lib/python3.13/site-packages/starlette/_exception_handler.py", line 53, in wrapped_app
    raise exc
  File "/home/dfx_17/Projects/Slovo/schedule/backend/.venv/lib/python3.13/site-packages/starlette/_exception_handler.py", line 42, in wrapped_app
    await app(scope, receive, sender)
  File "/home/dfx_17/Projects/Slovo/schedule/backend/.venv/lib/python3.13/site-packages/starlette/routing.py", line 714, in __call__
    await self.middleware_stack(scope, receive, send)
  File "/home/dfx_17/Projects/Slovo/schedule/backend/.venv/lib/python3.13/site-packages/starlette/routing.py", line 734, in app
    await route.handle(scope, receive, send)
  File "/home/dfx_17/Projects/Slovo/schedule/backend/.venv/lib/python3.13/site-packages/starlette/routing.py", line 288, in handle
    await self.app(scope, receive, send)
  File "/home/dfx_17/Projects/Slovo/schedule/backend/.venv/lib/python3.13/site-packages/starlette/routing.py", line 76, in app
    await wrap_app_handling_exceptions(app, request)(scope, receive, send)
  File "/home/dfx_17/Projects/Slovo/schedule/backend/.venv/lib/python3.13/site-packages/starlette/_exception_handler.py", line 53, in wrapped_app
    raise exc
  File "/home/dfx_17/Projects/Slovo/schedule/backend/.venv/lib/python3.13/site-packages/starlette/_exception_handler.py", line 42, in wrapped_app
    await app(scope, receive, sender)
  File "/home/dfx_17/Projects/Slovo/schedule/backend/.venv/lib/python3.13/site-packages/starlette/routing.py", line 73, in app
    response = await f(request)
               ^^^^^^^^^^^^^^^^
  File "/home/dfx_17/Projects/Slovo/schedule/backend/.venv/lib/python3.13/site-packages/fastapi/routing.py", line 301, in app
    raw_response = await run_endpoint_function(
                   ^^^^^^^^^^^^^^^^^^^^^^^^^^^^
    ...<3 lines>...
    )
    ^
  File "/home/dfx_17/Projects/Slovo/schedule/backend/.venv/lib/python3.13/site-packages/fastapi/routing.py", line 212, in run_endpoint_function
    return await dependant.call(**values)
           ^^^^^^^^^^^^^^^^^^^^^^^^^^^^^^
  File "/home/dfx_17/Projects/Slovo/schedule/backend/src/api/appointment.py", line 26, in get_appointment
    1 / 0
    ~~^~~
ZeroDivisionError: division by zero

2025-06-06 20:47:57.795 | CRITICAL | /home/dfx_17/Projects/Slovo/schedule/backend/.venv/lib/python3.13/site-packages/starlette/applications.py:112 (__call__)
Traceback (most recent call last):
  File "/home/dfx_17/Projects/Slovo/schedule/backend/.venv/lib/python3.13/site-packages/starlette/middleware/base.py", line 148, in call_next
    message = await recv_stream.receive()
              ^^^^^^^^^^^^^^^^^^^^^^^^^^^
  File "/home/dfx_17/Projects/Slovo/schedule/backend/.venv/lib/python3.13/site-packages/anyio/streams/memory.py", line 126, in receive
    raise EndOfStream from None
anyio.EndOfStream

During handling of the above exception, another exception occurred:

Traceback (most recent call last):
  File "/home/dfx_17/Projects/Slovo/schedule/backend/src/middleware.py", line 32, in dispatch
    return await call_next(request)
           ^^^^^^^^^^^^^^^^^^^^^^^^
  File "/home/dfx_17/Projects/Slovo/schedule/backend/.venv/lib/python3.13/site-packages/starlette/middleware/base.py", line 156, in call_next
    raise app_exc
  File "/home/dfx_17/Projects/Slovo/schedule/backend/.venv/lib/python3.13/site-packages/starlette/middleware/base.py", line 141, in coro
    await self.app(scope, receive_or_disconnect, send_no_error)
  File "/home/dfx_17/Projects/Slovo/schedule/backend/.venv/lib/python3.13/site-packages/starlette/middleware/cors.py", line 85, in __call__
    await self.app(scope, receive, send)
  File "/home/dfx_17/Projects/Slovo/schedule/backend/.venv/lib/python3.13/site-packages/starlette/middleware/exceptions.py", line 62, in __call__
    await wrap_app_handling_exceptions(self.app, conn)(scope, receive, send)
  File "/home/dfx_17/Projects/Slovo/schedule/backend/.venv/lib/python3.13/site-packages/starlette/_exception_handler.py", line 53, in wrapped_app
    raise exc
  File "/home/dfx_17/Projects/Slovo/schedule/backend/.venv/lib/python3.13/site-packages/starlette/_exception_handler.py", line 42, in wrapped_app
    await app(scope, receive, sender)
  File "/home/dfx_17/Projects/Slovo/schedule/backend/.venv/lib/python3.13/site-packages/starlette/routing.py", line 714, in __call__
    await self.middleware_stack(scope, receive, send)
  File "/home/dfx_17/Projects/Slovo/schedule/backend/.venv/lib/python3.13/site-packages/starlette/routing.py", line 734, in app
    await route.handle(scope, receive, send)
  File "/home/dfx_17/Projects/Slovo/schedule/backend/.venv/lib/python3.13/site-packages/starlette/routing.py", line 288, in handle
    await self.app(scope, receive, send)
  File "/home/dfx_17/Projects/Slovo/schedule/backend/.venv/lib/python3.13/site-packages/starlette/routing.py", line 76, in app
    await wrap_app_handling_exceptions(app, request)(scope, receive, send)
  File "/home/dfx_17/Projects/Slovo/schedule/backend/.venv/lib/python3.13/site-packages/starlette/_exception_handler.py", line 53, in wrapped_app
    raise exc
  File "/home/dfx_17/Projects/Slovo/schedule/backend/.venv/lib/python3.13/site-packages/starlette/_exception_handler.py", line 42, in wrapped_app
    await app(scope, receive, sender)
  File "/home/dfx_17/Projects/Slovo/schedule/backend/.venv/lib/python3.13/site-packages/starlette/routing.py", line 73, in app
    response = await f(request)
               ^^^^^^^^^^^^^^^^
  File "/home/dfx_17/Projects/Slovo/schedule/backend/.venv/lib/python3.13/site-packages/fastapi/routing.py", line 301, in app
    raw_response = await run_endpoint_function(
                   ^^^^^^^^^^^^^^^^^^^^^^^^^^^^
    ...<3 lines>...
    )
    ^
  File "/home/dfx_17/Projects/Slovo/schedule/backend/.venv/lib/python3.13/site-packages/fastapi/routing.py", line 212, in run_endpoint_function
    return await dependant.call(**values)
           ^^^^^^^^^^^^^^^^^^^^^^^^^^^^^^
  File "/home/dfx_17/Projects/Slovo/schedule/backend/src/api/appointment.py", line 27, in get_appointment
    data = await BitrixClient.get_crm_item(aety, id)
           ^^^^^^^^^^^^^^^^^^^^^^^^^^^^^^^^^^^^^^^^^
  File "/home/dfx_17/Projects/Slovo/schedule/backend/src/core/bitrix.py", line 32, in get_crm_item
    return await BITRIX.call("crm.item.get", items)
           ^^^^^^^^^^^^^^^^^^^^^^^^^^^^^^^^^^^^^^^^
  File "/home/dfx_17/Projects/Slovo/schedule/backend/.venv/lib/python3.13/site-packages/fast_bitrix24/logger.py", line 19, in wrapper
    return await func(*args, **kwargs)
           ^^^^^^^^^^^^^^^^^^^^^^^^^^^
  File "/home/dfx_17/Projects/Slovo/schedule/backend/.venv/lib/python3.13/site-packages/fast_bitrix24/bitrix.py", line 201, in call
    return await self.srh.run_async(request_cls(self, method, items).run())
           ^^^^^^^^^^^^^^^^^^^^^^^^^^^^^^^^^^^^^^^^^^^^^^^^^^^^^^^^^^^^^^^^
  File "/home/dfx_17/Projects/Slovo/schedule/backend/.venv/lib/python3.13/site-packages/fast_bitrix24/srh.py", line 129, in run_async
    return await coroutine
           ^^^^^^^^^^^^^^^
  File "/home/dfx_17/Projects/Slovo/schedule/backend/.venv/lib/python3.13/site-packages/fast_bitrix24/user_request.py", line 330, in run
    raw_results = await MultipleServerRequestHandlerPreserveIDs(
                  ^^^^^^^^^^^^^^^^^^^^^^^^^^^^^^^^^^^^^^^^^^^^^^
    ...<5 lines>...
    ).run()
    ^^^^^^^
  File "/home/dfx_17/Projects/Slovo/schedule/backend/.venv/lib/python3.13/site-packages/fast_bitrix24/mult_request.py", line 67, in run
    extracted_len = self.process_done_tasks(done)
  File "/home/dfx_17/Projects/Slovo/schedule/backend/.venv/lib/python3.13/site-packages/fast_bitrix24/mult_request.py", line 97, in process_done_tasks
    ).extract_results()
      ~~~~~~~~~~~~~~~^^
  File "/home/dfx_17/Projects/Slovo/schedule/backend/.venv/lib/python3.13/site-packages/fast_bitrix24/server_response.py", line 45, in extract_results
    self.raise_for_errors()
    ~~~~~~~~~~~~~~~~~~~~~^^
  File "/home/dfx_17/Projects/Slovo/schedule/backend/.venv/lib/python3.13/site-packages/fast_bitrix24/server_response.py", line 64, in raise_for_errors
    raise ErrorInServerResponseException(errors)
fast_bitrix24.server_response.ErrorInServerResponseException: {'order0000000000': {'error': 'NOT_FOUND', 'error_description': 'Элемент не найден'}}

2025-06-06 20:48:05.781 | CRITICAL | /home/dfx_17/Projects/Slovo/schedule/backend/.venv/lib/python3.13/site-packages/starlette/applications.py:112 (__call__)
Traceback (most recent call last):
  File "/home/dfx_17/Projects/Slovo/schedule/backend/.venv/lib/python3.13/site-packages/starlette/middleware/base.py", line 148, in call_next
    message = await recv_stream.receive()
              ^^^^^^^^^^^^^^^^^^^^^^^^^^^
  File "/home/dfx_17/Projects/Slovo/schedule/backend/.venv/lib/python3.13/site-packages/anyio/streams/memory.py", line 126, in receive
    raise EndOfStream from None
anyio.EndOfStream

During handling of the above exception, another exception occurred:

Traceback (most recent call last):
  File "/home/dfx_17/Projects/Slovo/schedule/backend/src/middleware.py", line 32, in dispatch
    return await call_next(request)
           ^^^^^^^^^^^^^^^^^^^^^^^^
  File "/home/dfx_17/Projects/Slovo/schedule/backend/.venv/lib/python3.13/site-packages/starlette/middleware/base.py", line 156, in call_next
    raise app_exc
  File "/home/dfx_17/Projects/Slovo/schedule/backend/.venv/lib/python3.13/site-packages/starlette/middleware/base.py", line 141, in coro
    await self.app(scope, receive_or_disconnect, send_no_error)
  File "/home/dfx_17/Projects/Slovo/schedule/backend/.venv/lib/python3.13/site-packages/starlette/middleware/cors.py", line 85, in __call__
    await self.app(scope, receive, send)
  File "/home/dfx_17/Projects/Slovo/schedule/backend/.venv/lib/python3.13/site-packages/starlette/middleware/exceptions.py", line 62, in __call__
    await wrap_app_handling_exceptions(self.app, conn)(scope, receive, send)
  File "/home/dfx_17/Projects/Slovo/schedule/backend/.venv/lib/python3.13/site-packages/starlette/_exception_handler.py", line 53, in wrapped_app
    raise exc
  File "/home/dfx_17/Projects/Slovo/schedule/backend/.venv/lib/python3.13/site-packages/starlette/_exception_handler.py", line 42, in wrapped_app
    await app(scope, receive, sender)
  File "/home/dfx_17/Projects/Slovo/schedule/backend/.venv/lib/python3.13/site-packages/starlette/routing.py", line 714, in __call__
    await self.middleware_stack(scope, receive, send)
  File "/home/dfx_17/Projects/Slovo/schedule/backend/.venv/lib/python3.13/site-packages/starlette/routing.py", line 734, in app
    await route.handle(scope, receive, send)
  File "/home/dfx_17/Projects/Slovo/schedule/backend/.venv/lib/python3.13/site-packages/starlette/routing.py", line 288, in handle
    await self.app(scope, receive, send)
  File "/home/dfx_17/Projects/Slovo/schedule/backend/.venv/lib/python3.13/site-packages/starlette/routing.py", line 76, in app
    await wrap_app_handling_exceptions(app, request)(scope, receive, send)
  File "/home/dfx_17/Projects/Slovo/schedule/backend/.venv/lib/python3.13/site-packages/starlette/_exception_handler.py", line 53, in wrapped_app
    raise exc
  File "/home/dfx_17/Projects/Slovo/schedule/backend/.venv/lib/python3.13/site-packages/starlette/_exception_handler.py", line 42, in wrapped_app
    await app(scope, receive, sender)
  File "/home/dfx_17/Projects/Slovo/schedule/backend/.venv/lib/python3.13/site-packages/starlette/routing.py", line 73, in app
    response = await f(request)
               ^^^^^^^^^^^^^^^^
  File "/home/dfx_17/Projects/Slovo/schedule/backend/.venv/lib/python3.13/site-packages/fastapi/routing.py", line 301, in app
    raw_response = await run_endpoint_function(
                   ^^^^^^^^^^^^^^^^^^^^^^^^^^^^
    ...<3 lines>...
    )
    ^
  File "/home/dfx_17/Projects/Slovo/schedule/backend/.venv/lib/python3.13/site-packages/fastapi/routing.py", line 212, in run_endpoint_function
    return await dependant.call(**values)
           ^^^^^^^^^^^^^^^^^^^^^^^^^^^^^^
  File "/home/dfx_17/Projects/Slovo/schedule/backend/src/api/appointment.py", line 31, in get_appointment
    appointment = Appointment.from_bitrix(data)
                  ^^^^^^^^^^^^^^^^^^^^^^^
  File "/home/dfx_17/Projects/Slovo/schedule/backend/.venv/lib/python3.13/site-packages/pydantic/_internal/_model_construction.py", line 271, in __getattr__
    raise AttributeError(item)
AttributeError: from_bitrix

2025-06-06 20:54:19.146 | CRITICAL | /home/dfx_17/Projects/Slovo/schedule/backend/.venv/lib/python3.13/site-packages/starlette/applications.py:112 (__call__)
Traceback (most recent call last):
  File "/home/dfx_17/Projects/Slovo/schedule/backend/.venv/lib/python3.13/site-packages/starlette/middleware/base.py", line 148, in call_next
    message = await recv_stream.receive()
              ^^^^^^^^^^^^^^^^^^^^^^^^^^^
  File "/home/dfx_17/Projects/Slovo/schedule/backend/.venv/lib/python3.13/site-packages/anyio/streams/memory.py", line 126, in receive
    raise EndOfStream from None
anyio.EndOfStream

During handling of the above exception, another exception occurred:

Traceback (most recent call last):
  File "/home/dfx_17/Projects/Slovo/schedule/backend/src/middleware.py", line 32, in dispatch
    return await call_next(request)
           ^^^^^^^^^^^^^^^^^^^^^^^^
  File "/home/dfx_17/Projects/Slovo/schedule/backend/.venv/lib/python3.13/site-packages/starlette/middleware/base.py", line 156, in call_next
    raise app_exc
  File "/home/dfx_17/Projects/Slovo/schedule/backend/.venv/lib/python3.13/site-packages/starlette/middleware/base.py", line 141, in coro
    await self.app(scope, receive_or_disconnect, send_no_error)
  File "/home/dfx_17/Projects/Slovo/schedule/backend/.venv/lib/python3.13/site-packages/starlette/middleware/cors.py", line 85, in __call__
    await self.app(scope, receive, send)
  File "/home/dfx_17/Projects/Slovo/schedule/backend/.venv/lib/python3.13/site-packages/starlette/middleware/exceptions.py", line 62, in __call__
    await wrap_app_handling_exceptions(self.app, conn)(scope, receive, send)
  File "/home/dfx_17/Projects/Slovo/schedule/backend/.venv/lib/python3.13/site-packages/starlette/_exception_handler.py", line 53, in wrapped_app
    raise exc
  File "/home/dfx_17/Projects/Slovo/schedule/backend/.venv/lib/python3.13/site-packages/starlette/_exception_handler.py", line 42, in wrapped_app
    await app(scope, receive, sender)
  File "/home/dfx_17/Projects/Slovo/schedule/backend/.venv/lib/python3.13/site-packages/starlette/routing.py", line 714, in __call__
    await self.middleware_stack(scope, receive, send)
  File "/home/dfx_17/Projects/Slovo/schedule/backend/.venv/lib/python3.13/site-packages/starlette/routing.py", line 734, in app
    await route.handle(scope, receive, send)
  File "/home/dfx_17/Projects/Slovo/schedule/backend/.venv/lib/python3.13/site-packages/starlette/routing.py", line 288, in handle
    await self.app(scope, receive, send)
  File "/home/dfx_17/Projects/Slovo/schedule/backend/.venv/lib/python3.13/site-packages/starlette/routing.py", line 76, in app
    await wrap_app_handling_exceptions(app, request)(scope, receive, send)
  File "/home/dfx_17/Projects/Slovo/schedule/backend/.venv/lib/python3.13/site-packages/starlette/_exception_handler.py", line 53, in wrapped_app
    raise exc
  File "/home/dfx_17/Projects/Slovo/schedule/backend/.venv/lib/python3.13/site-packages/starlette/_exception_handler.py", line 42, in wrapped_app
    await app(scope, receive, sender)
  File "/home/dfx_17/Projects/Slovo/schedule/backend/.venv/lib/python3.13/site-packages/starlette/routing.py", line 73, in app
    response = await f(request)
               ^^^^^^^^^^^^^^^^
  File "/home/dfx_17/Projects/Slovo/schedule/backend/.venv/lib/python3.13/site-packages/fastapi/routing.py", line 301, in app
    raw_response = await run_endpoint_function(
                   ^^^^^^^^^^^^^^^^^^^^^^^^^^^^
    ...<3 lines>...
    )
    ^
  File "/home/dfx_17/Projects/Slovo/schedule/backend/.venv/lib/python3.13/site-packages/fastapi/routing.py", line 212, in run_endpoint_function
    return await dependant.call(**values)
           ^^^^^^^^^^^^^^^^^^^^^^^^^^^^^^
  File "/home/dfx_17/Projects/Slovo/schedule/backend/src/api/appointment.py", line 31, in get_appointment
    appointment = Appointment.from_bitrix(data)
                  ^^^^^^^^^^^^^^^^^^^^^^^
  File "/home/dfx_17/Projects/Slovo/schedule/backend/.venv/lib/python3.13/site-packages/pydantic/_internal/_model_construction.py", line 271, in __getattr__
    raise AttributeError(item)
AttributeError: from_bitrix

2025-06-06 20:59:52.271 | CRITICAL | /home/dfx_17/Projects/Slovo/schedule/backend/.venv/lib/python3.13/site-packages/starlette/applications.py:112 (__call__)
Traceback (most recent call last):
  File "/home/dfx_17/Projects/Slovo/schedule/backend/.venv/lib/python3.13/site-packages/starlette/middleware/base.py", line 148, in call_next
    message = await recv_stream.receive()
              ^^^^^^^^^^^^^^^^^^^^^^^^^^^
  File "/home/dfx_17/Projects/Slovo/schedule/backend/.venv/lib/python3.13/site-packages/anyio/streams/memory.py", line 126, in receive
    raise EndOfStream from None
anyio.EndOfStream

During handling of the above exception, another exception occurred:

Traceback (most recent call last):
  File "/home/dfx_17/Projects/Slovo/schedule/backend/src/middleware.py", line 32, in dispatch
    return await call_next(request)
           ^^^^^^^^^^^^^^^^^^^^^^^^
  File "/home/dfx_17/Projects/Slovo/schedule/backend/.venv/lib/python3.13/site-packages/starlette/middleware/base.py", line 156, in call_next
    raise app_exc
  File "/home/dfx_17/Projects/Slovo/schedule/backend/.venv/lib/python3.13/site-packages/starlette/middleware/base.py", line 141, in coro
    await self.app(scope, receive_or_disconnect, send_no_error)
  File "/home/dfx_17/Projects/Slovo/schedule/backend/.venv/lib/python3.13/site-packages/starlette/middleware/cors.py", line 85, in __call__
    await self.app(scope, receive, send)
  File "/home/dfx_17/Projects/Slovo/schedule/backend/.venv/lib/python3.13/site-packages/starlette/middleware/exceptions.py", line 62, in __call__
    await wrap_app_handling_exceptions(self.app, conn)(scope, receive, send)
  File "/home/dfx_17/Projects/Slovo/schedule/backend/.venv/lib/python3.13/site-packages/starlette/_exception_handler.py", line 53, in wrapped_app
    raise exc
  File "/home/dfx_17/Projects/Slovo/schedule/backend/.venv/lib/python3.13/site-packages/starlette/_exception_handler.py", line 42, in wrapped_app
    await app(scope, receive, sender)
  File "/home/dfx_17/Projects/Slovo/schedule/backend/.venv/lib/python3.13/site-packages/starlette/routing.py", line 714, in __call__
    await self.middleware_stack(scope, receive, send)
  File "/home/dfx_17/Projects/Slovo/schedule/backend/.venv/lib/python3.13/site-packages/starlette/routing.py", line 734, in app
    await route.handle(scope, receive, send)
  File "/home/dfx_17/Projects/Slovo/schedule/backend/.venv/lib/python3.13/site-packages/starlette/routing.py", line 288, in handle
    await self.app(scope, receive, send)
  File "/home/dfx_17/Projects/Slovo/schedule/backend/.venv/lib/python3.13/site-packages/starlette/routing.py", line 76, in app
    await wrap_app_handling_exceptions(app, request)(scope, receive, send)
  File "/home/dfx_17/Projects/Slovo/schedule/backend/.venv/lib/python3.13/site-packages/starlette/_exception_handler.py", line 53, in wrapped_app
    raise exc
  File "/home/dfx_17/Projects/Slovo/schedule/backend/.venv/lib/python3.13/site-packages/starlette/_exception_handler.py", line 42, in wrapped_app
    await app(scope, receive, sender)
  File "/home/dfx_17/Projects/Slovo/schedule/backend/.venv/lib/python3.13/site-packages/starlette/routing.py", line 73, in app
    response = await f(request)
               ^^^^^^^^^^^^^^^^
  File "/home/dfx_17/Projects/Slovo/schedule/backend/.venv/lib/python3.13/site-packages/fastapi/routing.py", line 301, in app
    raw_response = await run_endpoint_function(
                   ^^^^^^^^^^^^^^^^^^^^^^^^^^^^
    ...<3 lines>...
    )
    ^
  File "/home/dfx_17/Projects/Slovo/schedule/backend/.venv/lib/python3.13/site-packages/fastapi/routing.py", line 212, in run_endpoint_function
    return await dependant.call(**values)
           ^^^^^^^^^^^^^^^^^^^^^^^^^^^^^^
  File "/home/dfx_17/Projects/Slovo/schedule/backend/src/api/appointment.py", line 28, in get_appointment
    print(BXAppointment(**data))
          ~~~~~~~~~~~~~^^^^^^^^
  File "/home/dfx_17/Projects/Slovo/schedule/backend/.venv/lib/python3.13/site-packages/pydantic/main.py", line 253, in __init__
    validated_self = self.__pydantic_validator__.validate_python(data, self_instance=self)
pydantic_core._pydantic_core.ValidationError: 1 validation error for BXAppointment
ufCrm3Code
  Input should be a valid string [type=string_type, input_value=['65'], input_type=list]
    For further information visit https://errors.pydantic.dev/2.11/v/string_type

2025-06-06 21:04:50.044 | CRITICAL | /home/dfx_17/Projects/Slovo/schedule/backend/.venv/lib/python3.13/site-packages/starlette/applications.py:112 (__call__)
Traceback (most recent call last):
  File "/home/dfx_17/Projects/Slovo/schedule/backend/.venv/lib/python3.13/site-packages/starlette/middleware/base.py", line 148, in call_next
    message = await recv_stream.receive()
              ^^^^^^^^^^^^^^^^^^^^^^^^^^^
  File "/home/dfx_17/Projects/Slovo/schedule/backend/.venv/lib/python3.13/site-packages/anyio/streams/memory.py", line 126, in receive
    raise EndOfStream from None
anyio.EndOfStream

During handling of the above exception, another exception occurred:

Traceback (most recent call last):
  File "/home/dfx_17/Projects/Slovo/schedule/backend/src/middleware.py", line 32, in dispatch
    return await call_next(request)
           ^^^^^^^^^^^^^^^^^^^^^^^^
  File "/home/dfx_17/Projects/Slovo/schedule/backend/.venv/lib/python3.13/site-packages/starlette/middleware/base.py", line 156, in call_next
    raise app_exc
  File "/home/dfx_17/Projects/Slovo/schedule/backend/.venv/lib/python3.13/site-packages/starlette/middleware/base.py", line 141, in coro
    await self.app(scope, receive_or_disconnect, send_no_error)
  File "/home/dfx_17/Projects/Slovo/schedule/backend/.venv/lib/python3.13/site-packages/starlette/middleware/cors.py", line 85, in __call__
    await self.app(scope, receive, send)
  File "/home/dfx_17/Projects/Slovo/schedule/backend/.venv/lib/python3.13/site-packages/starlette/middleware/exceptions.py", line 62, in __call__
    await wrap_app_handling_exceptions(self.app, conn)(scope, receive, send)
  File "/home/dfx_17/Projects/Slovo/schedule/backend/.venv/lib/python3.13/site-packages/starlette/_exception_handler.py", line 53, in wrapped_app
    raise exc
  File "/home/dfx_17/Projects/Slovo/schedule/backend/.venv/lib/python3.13/site-packages/starlette/_exception_handler.py", line 42, in wrapped_app
    await app(scope, receive, sender)
  File "/home/dfx_17/Projects/Slovo/schedule/backend/.venv/lib/python3.13/site-packages/starlette/routing.py", line 714, in __call__
    await self.middleware_stack(scope, receive, send)
  File "/home/dfx_17/Projects/Slovo/schedule/backend/.venv/lib/python3.13/site-packages/starlette/routing.py", line 734, in app
    await route.handle(scope, receive, send)
  File "/home/dfx_17/Projects/Slovo/schedule/backend/.venv/lib/python3.13/site-packages/starlette/routing.py", line 288, in handle
    await self.app(scope, receive, send)
  File "/home/dfx_17/Projects/Slovo/schedule/backend/.venv/lib/python3.13/site-packages/starlette/routing.py", line 76, in app
    await wrap_app_handling_exceptions(app, request)(scope, receive, send)
  File "/home/dfx_17/Projects/Slovo/schedule/backend/.venv/lib/python3.13/site-packages/starlette/_exception_handler.py", line 53, in wrapped_app
    raise exc
  File "/home/dfx_17/Projects/Slovo/schedule/backend/.venv/lib/python3.13/site-packages/starlette/_exception_handler.py", line 42, in wrapped_app
    await app(scope, receive, sender)
  File "/home/dfx_17/Projects/Slovo/schedule/backend/.venv/lib/python3.13/site-packages/starlette/routing.py", line 73, in app
    response = await f(request)
               ^^^^^^^^^^^^^^^^
  File "/home/dfx_17/Projects/Slovo/schedule/backend/.venv/lib/python3.13/site-packages/fastapi/routing.py", line 301, in app
    raw_response = await run_endpoint_function(
                   ^^^^^^^^^^^^^^^^^^^^^^^^^^^^
    ...<3 lines>...
    )
    ^
  File "/home/dfx_17/Projects/Slovo/schedule/backend/.venv/lib/python3.13/site-packages/fastapi/routing.py", line 212, in run_endpoint_function
    return await dependant.call(**values)
           ^^^^^^^^^^^^^^^^^^^^^^^^^^^^^^
  File "/home/dfx_17/Projects/Slovo/schedule/backend/src/api/appointment.py", line 31, in get_appointment
    appointment = Appointment.from_bitrix(data)
                  ^^^^^^^^^^^^^^^^^^^^^^^
  File "/home/dfx_17/Projects/Slovo/schedule/backend/.venv/lib/python3.13/site-packages/pydantic/_internal/_model_construction.py", line 271, in __getattr__
    raise AttributeError(item)
AttributeError: from_bitrix

2025-06-06 21:06:07.053 | CRITICAL | /home/dfx_17/Projects/Slovo/schedule/backend/.venv/lib/python3.13/site-packages/starlette/applications.py:112 (__call__)
Traceback (most recent call last):
  File "/home/dfx_17/Projects/Slovo/schedule/backend/.venv/lib/python3.13/site-packages/starlette/middleware/base.py", line 148, in call_next
    message = await recv_stream.receive()
              ^^^^^^^^^^^^^^^^^^^^^^^^^^^
  File "/home/dfx_17/Projects/Slovo/schedule/backend/.venv/lib/python3.13/site-packages/anyio/streams/memory.py", line 126, in receive
    raise EndOfStream from None
anyio.EndOfStream

During handling of the above exception, another exception occurred:

Traceback (most recent call last):
  File "/home/dfx_17/Projects/Slovo/schedule/backend/src/middleware.py", line 32, in dispatch
    return await call_next(request)
           ^^^^^^^^^^^^^^^^^^^^^^^^
  File "/home/dfx_17/Projects/Slovo/schedule/backend/.venv/lib/python3.13/site-packages/starlette/middleware/base.py", line 156, in call_next
    raise app_exc
  File "/home/dfx_17/Projects/Slovo/schedule/backend/.venv/lib/python3.13/site-packages/starlette/middleware/base.py", line 141, in coro
    await self.app(scope, receive_or_disconnect, send_no_error)
  File "/home/dfx_17/Projects/Slovo/schedule/backend/.venv/lib/python3.13/site-packages/starlette/middleware/cors.py", line 85, in __call__
    await self.app(scope, receive, send)
  File "/home/dfx_17/Projects/Slovo/schedule/backend/.venv/lib/python3.13/site-packages/starlette/middleware/exceptions.py", line 62, in __call__
    await wrap_app_handling_exceptions(self.app, conn)(scope, receive, send)
  File "/home/dfx_17/Projects/Slovo/schedule/backend/.venv/lib/python3.13/site-packages/starlette/_exception_handler.py", line 53, in wrapped_app
    raise exc
  File "/home/dfx_17/Projects/Slovo/schedule/backend/.venv/lib/python3.13/site-packages/starlette/_exception_handler.py", line 42, in wrapped_app
    await app(scope, receive, sender)
  File "/home/dfx_17/Projects/Slovo/schedule/backend/.venv/lib/python3.13/site-packages/starlette/routing.py", line 714, in __call__
    await self.middleware_stack(scope, receive, send)
  File "/home/dfx_17/Projects/Slovo/schedule/backend/.venv/lib/python3.13/site-packages/starlette/routing.py", line 734, in app
    await route.handle(scope, receive, send)
  File "/home/dfx_17/Projects/Slovo/schedule/backend/.venv/lib/python3.13/site-packages/starlette/routing.py", line 288, in handle
    await self.app(scope, receive, send)
  File "/home/dfx_17/Projects/Slovo/schedule/backend/.venv/lib/python3.13/site-packages/starlette/routing.py", line 76, in app
    await wrap_app_handling_exceptions(app, request)(scope, receive, send)
  File "/home/dfx_17/Projects/Slovo/schedule/backend/.venv/lib/python3.13/site-packages/starlette/_exception_handler.py", line 53, in wrapped_app
    raise exc
  File "/home/dfx_17/Projects/Slovo/schedule/backend/.venv/lib/python3.13/site-packages/starlette/_exception_handler.py", line 42, in wrapped_app
    await app(scope, receive, sender)
  File "/home/dfx_17/Projects/Slovo/schedule/backend/.venv/lib/python3.13/site-packages/starlette/routing.py", line 73, in app
    response = await f(request)
               ^^^^^^^^^^^^^^^^
  File "/home/dfx_17/Projects/Slovo/schedule/backend/.venv/lib/python3.13/site-packages/fastapi/routing.py", line 301, in app
    raw_response = await run_endpoint_function(
                   ^^^^^^^^^^^^^^^^^^^^^^^^^^^^
    ...<3 lines>...
    )
    ^
  File "/home/dfx_17/Projects/Slovo/schedule/backend/.venv/lib/python3.13/site-packages/fastapi/routing.py", line 212, in run_endpoint_function
    return await dependant.call(**values)
           ^^^^^^^^^^^^^^^^^^^^^^^^^^^^^^
  File "/home/dfx_17/Projects/Slovo/schedule/backend/src/api/appointment.py", line 31, in get_appointment
    appointment = Appointment.from_bitrix(data)
                  ^^^^^^^^^^^^^^^^^^^^^^^
  File "/home/dfx_17/Projects/Slovo/schedule/backend/.venv/lib/python3.13/site-packages/pydantic/_internal/_model_construction.py", line 271, in __getattr__
    raise AttributeError(item)
AttributeError: from_bitrix

2025-06-06 21:08:03.891 | CRITICAL | /home/dfx_17/Projects/Slovo/schedule/backend/.venv/lib/python3.13/site-packages/starlette/applications.py:112 (__call__)
Traceback (most recent call last):
  File "/home/dfx_17/Projects/Slovo/schedule/backend/.venv/lib/python3.13/site-packages/starlette/middleware/base.py", line 148, in call_next
    message = await recv_stream.receive()
              ^^^^^^^^^^^^^^^^^^^^^^^^^^^
  File "/home/dfx_17/Projects/Slovo/schedule/backend/.venv/lib/python3.13/site-packages/anyio/streams/memory.py", line 126, in receive
    raise EndOfStream from None
anyio.EndOfStream

During handling of the above exception, another exception occurred:

Traceback (most recent call last):
  File "/home/dfx_17/Projects/Slovo/schedule/backend/src/middleware.py", line 32, in dispatch
    return await call_next(request)
           ^^^^^^^^^^^^^^^^^^^^^^^^
  File "/home/dfx_17/Projects/Slovo/schedule/backend/.venv/lib/python3.13/site-packages/starlette/middleware/base.py", line 156, in call_next
    raise app_exc
  File "/home/dfx_17/Projects/Slovo/schedule/backend/.venv/lib/python3.13/site-packages/starlette/middleware/base.py", line 141, in coro
    await self.app(scope, receive_or_disconnect, send_no_error)
  File "/home/dfx_17/Projects/Slovo/schedule/backend/.venv/lib/python3.13/site-packages/starlette/middleware/cors.py", line 85, in __call__
    await self.app(scope, receive, send)
  File "/home/dfx_17/Projects/Slovo/schedule/backend/.venv/lib/python3.13/site-packages/starlette/middleware/exceptions.py", line 62, in __call__
    await wrap_app_handling_exceptions(self.app, conn)(scope, receive, send)
  File "/home/dfx_17/Projects/Slovo/schedule/backend/.venv/lib/python3.13/site-packages/starlette/_exception_handler.py", line 53, in wrapped_app
    raise exc
  File "/home/dfx_17/Projects/Slovo/schedule/backend/.venv/lib/python3.13/site-packages/starlette/_exception_handler.py", line 42, in wrapped_app
    await app(scope, receive, sender)
  File "/home/dfx_17/Projects/Slovo/schedule/backend/.venv/lib/python3.13/site-packages/starlette/routing.py", line 714, in __call__
    await self.middleware_stack(scope, receive, send)
  File "/home/dfx_17/Projects/Slovo/schedule/backend/.venv/lib/python3.13/site-packages/starlette/routing.py", line 734, in app
    await route.handle(scope, receive, send)
  File "/home/dfx_17/Projects/Slovo/schedule/backend/.venv/lib/python3.13/site-packages/starlette/routing.py", line 288, in handle
    await self.app(scope, receive, send)
  File "/home/dfx_17/Projects/Slovo/schedule/backend/.venv/lib/python3.13/site-packages/starlette/routing.py", line 76, in app
    await wrap_app_handling_exceptions(app, request)(scope, receive, send)
  File "/home/dfx_17/Projects/Slovo/schedule/backend/.venv/lib/python3.13/site-packages/starlette/_exception_handler.py", line 53, in wrapped_app
    raise exc
  File "/home/dfx_17/Projects/Slovo/schedule/backend/.venv/lib/python3.13/site-packages/starlette/_exception_handler.py", line 42, in wrapped_app
    await app(scope, receive, sender)
  File "/home/dfx_17/Projects/Slovo/schedule/backend/.venv/lib/python3.13/site-packages/starlette/routing.py", line 73, in app
    response = await f(request)
               ^^^^^^^^^^^^^^^^
  File "/home/dfx_17/Projects/Slovo/schedule/backend/.venv/lib/python3.13/site-packages/fastapi/routing.py", line 301, in app
    raw_response = await run_endpoint_function(
                   ^^^^^^^^^^^^^^^^^^^^^^^^^^^^
    ...<3 lines>...
    )
    ^
  File "/home/dfx_17/Projects/Slovo/schedule/backend/.venv/lib/python3.13/site-packages/fastapi/routing.py", line 212, in run_endpoint_function
    return await dependant.call(**values)
           ^^^^^^^^^^^^^^^^^^^^^^^^^^^^^^
  File "/home/dfx_17/Projects/Slovo/schedule/backend/src/api/appointment.py", line 31, in get_appointment
    appointment = Appointment.from_bitrix(data)
                  ^^^^^^^^^^^^^^^^^^^^^^^
  File "/home/dfx_17/Projects/Slovo/schedule/backend/.venv/lib/python3.13/site-packages/pydantic/_internal/_model_construction.py", line 271, in __getattr__
    raise AttributeError(item)
AttributeError: from_bitrix

2025-06-06 21:11:17.225 | CRITICAL | /home/dfx_17/Projects/Slovo/schedule/backend/.venv/lib/python3.13/site-packages/starlette/applications.py:112 (__call__)
Traceback (most recent call last):
  File "/home/dfx_17/Projects/Slovo/schedule/backend/.venv/lib/python3.13/site-packages/starlette/middleware/base.py", line 148, in call_next
    message = await recv_stream.receive()
              ^^^^^^^^^^^^^^^^^^^^^^^^^^^
  File "/home/dfx_17/Projects/Slovo/schedule/backend/.venv/lib/python3.13/site-packages/anyio/streams/memory.py", line 126, in receive
    raise EndOfStream from None
anyio.EndOfStream

During handling of the above exception, another exception occurred:

Traceback (most recent call last):
  File "/home/dfx_17/Projects/Slovo/schedule/backend/src/middleware.py", line 32, in dispatch
    return await call_next(request)
           ^^^^^^^^^^^^^^^^^^^^^^^^
  File "/home/dfx_17/Projects/Slovo/schedule/backend/.venv/lib/python3.13/site-packages/starlette/middleware/base.py", line 156, in call_next
    raise app_exc
  File "/home/dfx_17/Projects/Slovo/schedule/backend/.venv/lib/python3.13/site-packages/starlette/middleware/base.py", line 141, in coro
    await self.app(scope, receive_or_disconnect, send_no_error)
  File "/home/dfx_17/Projects/Slovo/schedule/backend/.venv/lib/python3.13/site-packages/starlette/middleware/cors.py", line 85, in __call__
    await self.app(scope, receive, send)
  File "/home/dfx_17/Projects/Slovo/schedule/backend/.venv/lib/python3.13/site-packages/starlette/middleware/exceptions.py", line 62, in __call__
    await wrap_app_handling_exceptions(self.app, conn)(scope, receive, send)
  File "/home/dfx_17/Projects/Slovo/schedule/backend/.venv/lib/python3.13/site-packages/starlette/_exception_handler.py", line 53, in wrapped_app
    raise exc
  File "/home/dfx_17/Projects/Slovo/schedule/backend/.venv/lib/python3.13/site-packages/starlette/_exception_handler.py", line 42, in wrapped_app
    await app(scope, receive, sender)
  File "/home/dfx_17/Projects/Slovo/schedule/backend/.venv/lib/python3.13/site-packages/starlette/routing.py", line 714, in __call__
    await self.middleware_stack(scope, receive, send)
  File "/home/dfx_17/Projects/Slovo/schedule/backend/.venv/lib/python3.13/site-packages/starlette/routing.py", line 734, in app
    await route.handle(scope, receive, send)
  File "/home/dfx_17/Projects/Slovo/schedule/backend/.venv/lib/python3.13/site-packages/starlette/routing.py", line 288, in handle
    await self.app(scope, receive, send)
  File "/home/dfx_17/Projects/Slovo/schedule/backend/.venv/lib/python3.13/site-packages/starlette/routing.py", line 76, in app
    await wrap_app_handling_exceptions(app, request)(scope, receive, send)
  File "/home/dfx_17/Projects/Slovo/schedule/backend/.venv/lib/python3.13/site-packages/starlette/_exception_handler.py", line 53, in wrapped_app
    raise exc
  File "/home/dfx_17/Projects/Slovo/schedule/backend/.venv/lib/python3.13/site-packages/starlette/_exception_handler.py", line 42, in wrapped_app
    await app(scope, receive, sender)
  File "/home/dfx_17/Projects/Slovo/schedule/backend/.venv/lib/python3.13/site-packages/starlette/routing.py", line 73, in app
    response = await f(request)
               ^^^^^^^^^^^^^^^^
  File "/home/dfx_17/Projects/Slovo/schedule/backend/.venv/lib/python3.13/site-packages/fastapi/routing.py", line 301, in app
    raw_response = await run_endpoint_function(
                   ^^^^^^^^^^^^^^^^^^^^^^^^^^^^
    ...<3 lines>...
    )
    ^
  File "/home/dfx_17/Projects/Slovo/schedule/backend/.venv/lib/python3.13/site-packages/fastapi/routing.py", line 212, in run_endpoint_function
    return await dependant.call(**values)
           ^^^^^^^^^^^^^^^^^^^^^^^^^^^^^^
  File "/home/dfx_17/Projects/Slovo/schedule/backend/src/api/appointment.py", line 31, in get_appointment
    appointment = Appointment.from_bitrix(data)
                  ^^^^^^^^^^^^^^^^^^^^^^^
  File "/home/dfx_17/Projects/Slovo/schedule/backend/.venv/lib/python3.13/site-packages/pydantic/_internal/_model_construction.py", line 271, in __getattr__
    raise AttributeError(item)
AttributeError: from_bitrix

2025-06-06 21:21:31.078 | CRITICAL | /home/dfx_17/Projects/Slovo/schedule/backend/.venv/lib/python3.13/site-packages/starlette/applications.py:112 (__call__)
Traceback (most recent call last):
  File "/home/dfx_17/Projects/Slovo/schedule/backend/.venv/lib/python3.13/site-packages/starlette/middleware/base.py", line 148, in call_next
    message = await recv_stream.receive()
              ^^^^^^^^^^^^^^^^^^^^^^^^^^^
  File "/home/dfx_17/Projects/Slovo/schedule/backend/.venv/lib/python3.13/site-packages/anyio/streams/memory.py", line 126, in receive
    raise EndOfStream from None
anyio.EndOfStream

During handling of the above exception, another exception occurred:

Traceback (most recent call last):
  File "/home/dfx_17/Projects/Slovo/schedule/backend/src/middleware.py", line 32, in dispatch
    return await call_next(request)
           ^^^^^^^^^^^^^^^^^^^^^^^^
  File "/home/dfx_17/Projects/Slovo/schedule/backend/.venv/lib/python3.13/site-packages/starlette/middleware/base.py", line 156, in call_next
    raise app_exc
  File "/home/dfx_17/Projects/Slovo/schedule/backend/.venv/lib/python3.13/site-packages/starlette/middleware/base.py", line 141, in coro
    await self.app(scope, receive_or_disconnect, send_no_error)
  File "/home/dfx_17/Projects/Slovo/schedule/backend/.venv/lib/python3.13/site-packages/starlette/middleware/cors.py", line 93, in __call__
    await self.simple_response(scope, receive, send, request_headers=headers)
  File "/home/dfx_17/Projects/Slovo/schedule/backend/.venv/lib/python3.13/site-packages/starlette/middleware/cors.py", line 144, in simple_response
    await self.app(scope, receive, send)
  File "/home/dfx_17/Projects/Slovo/schedule/backend/.venv/lib/python3.13/site-packages/starlette/middleware/exceptions.py", line 62, in __call__
    await wrap_app_handling_exceptions(self.app, conn)(scope, receive, send)
  File "/home/dfx_17/Projects/Slovo/schedule/backend/.venv/lib/python3.13/site-packages/starlette/_exception_handler.py", line 53, in wrapped_app
    raise exc
  File "/home/dfx_17/Projects/Slovo/schedule/backend/.venv/lib/python3.13/site-packages/starlette/_exception_handler.py", line 42, in wrapped_app
    await app(scope, receive, sender)
  File "/home/dfx_17/Projects/Slovo/schedule/backend/.venv/lib/python3.13/site-packages/starlette/routing.py", line 714, in __call__
    await self.middleware_stack(scope, receive, send)
  File "/home/dfx_17/Projects/Slovo/schedule/backend/.venv/lib/python3.13/site-packages/starlette/routing.py", line 734, in app
    await route.handle(scope, receive, send)
  File "/home/dfx_17/Projects/Slovo/schedule/backend/.venv/lib/python3.13/site-packages/starlette/routing.py", line 288, in handle
    await self.app(scope, receive, send)
  File "/home/dfx_17/Projects/Slovo/schedule/backend/.venv/lib/python3.13/site-packages/starlette/routing.py", line 76, in app
    await wrap_app_handling_exceptions(app, request)(scope, receive, send)
  File "/home/dfx_17/Projects/Slovo/schedule/backend/.venv/lib/python3.13/site-packages/starlette/_exception_handler.py", line 53, in wrapped_app
    raise exc
  File "/home/dfx_17/Projects/Slovo/schedule/backend/.venv/lib/python3.13/site-packages/starlette/_exception_handler.py", line 42, in wrapped_app
    await app(scope, receive, sender)
  File "/home/dfx_17/Projects/Slovo/schedule/backend/.venv/lib/python3.13/site-packages/starlette/routing.py", line 73, in app
    response = await f(request)
               ^^^^^^^^^^^^^^^^
  File "/home/dfx_17/Projects/Slovo/schedule/backend/.venv/lib/python3.13/site-packages/fastapi/routing.py", line 301, in app
    raw_response = await run_endpoint_function(
                   ^^^^^^^^^^^^^^^^^^^^^^^^^^^^
    ...<3 lines>...
    )
    ^
  File "/home/dfx_17/Projects/Slovo/schedule/backend/.venv/lib/python3.13/site-packages/fastapi/routing.py", line 212, in run_endpoint_function
    return await dependant.call(**values)
           ^^^^^^^^^^^^^^^^^^^^^^^^^^^^^^
  File "/home/dfx_17/Projects/Slovo/schedule/backend/src/api/appointment.py", line 16, in create_appointment
    fields = appointment.to_bx()
  File "/home/dfx_17/Projects/Slovo/schedule/backend/src/schemas/api/appointment.py", line 26, in to_bx
    auf.patient: self.patient,
                 ^^^^^^^^^^^^
  File "/home/dfx_17/Projects/Slovo/schedule/backend/.venv/lib/python3.13/site-packages/pydantic/main.py", line 989, in __getattr__
    raise AttributeError(f'{type(self).__name__!r} object has no attribute {item!r}')
AttributeError: 'Appointment' object has no attribute 'patient'

2025-06-06 23:35:42.778 | CRITICAL | /home/dfx_17/Projects/Slovo/schedule/backend/.venv/lib/python3.13/site-packages/starlette/applications.py:112 (__call__)
Traceback (most recent call last):
  File "/home/dfx_17/Projects/Slovo/schedule/backend/.venv/lib/python3.13/site-packages/starlette/middleware/base.py", line 148, in call_next
    message = await recv_stream.receive()
              ^^^^^^^^^^^^^^^^^^^^^^^^^^^
  File "/home/dfx_17/Projects/Slovo/schedule/backend/.venv/lib/python3.13/site-packages/anyio/streams/memory.py", line 126, in receive
    raise EndOfStream from None
anyio.EndOfStream

During handling of the above exception, another exception occurred:

Traceback (most recent call last):
  File "/home/dfx_17/Projects/Slovo/schedule/backend/src/middleware.py", line 32, in dispatch
    return await call_next(request)
           ^^^^^^^^^^^^^^^^^^^^^^^^
  File "/home/dfx_17/Projects/Slovo/schedule/backend/.venv/lib/python3.13/site-packages/starlette/middleware/base.py", line 156, in call_next
    raise app_exc
  File "/home/dfx_17/Projects/Slovo/schedule/backend/.venv/lib/python3.13/site-packages/starlette/middleware/base.py", line 141, in coro
    await self.app(scope, receive_or_disconnect, send_no_error)
  File "/home/dfx_17/Projects/Slovo/schedule/backend/.venv/lib/python3.13/site-packages/starlette/middleware/cors.py", line 85, in __call__
    await self.app(scope, receive, send)
  File "/home/dfx_17/Projects/Slovo/schedule/backend/.venv/lib/python3.13/site-packages/starlette/middleware/exceptions.py", line 62, in __call__
    await wrap_app_handling_exceptions(self.app, conn)(scope, receive, send)
  File "/home/dfx_17/Projects/Slovo/schedule/backend/.venv/lib/python3.13/site-packages/starlette/_exception_handler.py", line 53, in wrapped_app
    raise exc
  File "/home/dfx_17/Projects/Slovo/schedule/backend/.venv/lib/python3.13/site-packages/starlette/_exception_handler.py", line 42, in wrapped_app
    await app(scope, receive, sender)
  File "/home/dfx_17/Projects/Slovo/schedule/backend/.venv/lib/python3.13/site-packages/starlette/routing.py", line 714, in __call__
    await self.middleware_stack(scope, receive, send)
  File "/home/dfx_17/Projects/Slovo/schedule/backend/.venv/lib/python3.13/site-packages/starlette/routing.py", line 734, in app
    await route.handle(scope, receive, send)
  File "/home/dfx_17/Projects/Slovo/schedule/backend/.venv/lib/python3.13/site-packages/starlette/routing.py", line 288, in handle
    await self.app(scope, receive, send)
  File "/home/dfx_17/Projects/Slovo/schedule/backend/.venv/lib/python3.13/site-packages/starlette/routing.py", line 76, in app
    await wrap_app_handling_exceptions(app, request)(scope, receive, send)
  File "/home/dfx_17/Projects/Slovo/schedule/backend/.venv/lib/python3.13/site-packages/starlette/_exception_handler.py", line 53, in wrapped_app
    raise exc
  File "/home/dfx_17/Projects/Slovo/schedule/backend/.venv/lib/python3.13/site-packages/starlette/_exception_handler.py", line 42, in wrapped_app
    await app(scope, receive, sender)
  File "/home/dfx_17/Projects/Slovo/schedule/backend/.venv/lib/python3.13/site-packages/starlette/routing.py", line 73, in app
    response = await f(request)
               ^^^^^^^^^^^^^^^^
  File "/home/dfx_17/Projects/Slovo/schedule/backend/.venv/lib/python3.13/site-packages/fastapi/routing.py", line 301, in app
    raw_response = await run_endpoint_function(
                   ^^^^^^^^^^^^^^^^^^^^^^^^^^^^
    ...<3 lines>...
    )
    ^
  File "/home/dfx_17/Projects/Slovo/schedule/backend/.venv/lib/python3.13/site-packages/fastapi/routing.py", line 212, in run_endpoint_function
    return await dependant.call(**values)
           ^^^^^^^^^^^^^^^^^^^^^^^^^^^^^^
  File "/home/dfx_17/Projects/Slovo/schedule/backend/src/api/appointment.py", line 27, in get_appointment
    data = await BitrixClient.get_crm_item(aety, id)
           ^^^^^^^^^^^^^^^^^^^^^^^^^^^^^^^^^^^^^^^^^
  File "/home/dfx_17/Projects/Slovo/schedule/backend/src/core/bitrix.py", line 32, in get_crm_item
    return await BITRIX.call("crm.item.get", items)
           ^^^^^^^^^^^^^^^^^^^^^^^^^^^^^^^^^^^^^^^^
  File "/home/dfx_17/Projects/Slovo/schedule/backend/.venv/lib/python3.13/site-packages/fast_bitrix24/logger.py", line 19, in wrapper
    return await func(*args, **kwargs)
           ^^^^^^^^^^^^^^^^^^^^^^^^^^^
  File "/home/dfx_17/Projects/Slovo/schedule/backend/.venv/lib/python3.13/site-packages/fast_bitrix24/bitrix.py", line 201, in call
    return await self.srh.run_async(request_cls(self, method, items).run())
           ^^^^^^^^^^^^^^^^^^^^^^^^^^^^^^^^^^^^^^^^^^^^^^^^^^^^^^^^^^^^^^^^
  File "/home/dfx_17/Projects/Slovo/schedule/backend/.venv/lib/python3.13/site-packages/fast_bitrix24/srh.py", line 129, in run_async
    return await coroutine
           ^^^^^^^^^^^^^^^
  File "/home/dfx_17/Projects/Slovo/schedule/backend/.venv/lib/python3.13/site-packages/fast_bitrix24/user_request.py", line 330, in run
    raw_results = await MultipleServerRequestHandlerPreserveIDs(
                  ^^^^^^^^^^^^^^^^^^^^^^^^^^^^^^^^^^^^^^^^^^^^^^
    ...<5 lines>...
    ).run()
    ^^^^^^^
  File "/home/dfx_17/Projects/Slovo/schedule/backend/.venv/lib/python3.13/site-packages/fast_bitrix24/mult_request.py", line 67, in run
    extracted_len = self.process_done_tasks(done)
  File "/home/dfx_17/Projects/Slovo/schedule/backend/.venv/lib/python3.13/site-packages/fast_bitrix24/mult_request.py", line 97, in process_done_tasks
    ).extract_results()
      ~~~~~~~~~~~~~~~^^
  File "/home/dfx_17/Projects/Slovo/schedule/backend/.venv/lib/python3.13/site-packages/fast_bitrix24/server_response.py", line 45, in extract_results
    self.raise_for_errors()
    ~~~~~~~~~~~~~~~~~~~~~^^
  File "/home/dfx_17/Projects/Slovo/schedule/backend/.venv/lib/python3.13/site-packages/fast_bitrix24/server_response.py", line 64, in raise_for_errors
    raise ErrorInServerResponseException(errors)
fast_bitrix24.server_response.ErrorInServerResponseException: {'order0000000000': {'error': 'NOT_FOUND', 'error_description': 'Элемент не найден'}}

2025-06-06 23:37:23.745 | CRITICAL | /home/dfx_17/Projects/Slovo/schedule/backend/.venv/lib/python3.13/site-packages/starlette/applications.py:112 (__call__)
Traceback (most recent call last):
  File "/home/dfx_17/Projects/Slovo/schedule/backend/.venv/lib/python3.13/site-packages/starlette/middleware/base.py", line 148, in call_next
    message = await recv_stream.receive()
              ^^^^^^^^^^^^^^^^^^^^^^^^^^^
  File "/home/dfx_17/Projects/Slovo/schedule/backend/.venv/lib/python3.13/site-packages/anyio/streams/memory.py", line 126, in receive
    raise EndOfStream from None
anyio.EndOfStream

During handling of the above exception, another exception occurred:

Traceback (most recent call last):
  File "/home/dfx_17/Projects/Slovo/schedule/backend/src/middleware.py", line 32, in dispatch
    return await call_next(request)
           ^^^^^^^^^^^^^^^^^^^^^^^^
  File "/home/dfx_17/Projects/Slovo/schedule/backend/.venv/lib/python3.13/site-packages/starlette/middleware/base.py", line 156, in call_next
    raise app_exc
  File "/home/dfx_17/Projects/Slovo/schedule/backend/.venv/lib/python3.13/site-packages/starlette/middleware/base.py", line 141, in coro
    await self.app(scope, receive_or_disconnect, send_no_error)
  File "/home/dfx_17/Projects/Slovo/schedule/backend/.venv/lib/python3.13/site-packages/starlette/middleware/cors.py", line 85, in __call__
    await self.app(scope, receive, send)
  File "/home/dfx_17/Projects/Slovo/schedule/backend/.venv/lib/python3.13/site-packages/starlette/middleware/exceptions.py", line 62, in __call__
    await wrap_app_handling_exceptions(self.app, conn)(scope, receive, send)
  File "/home/dfx_17/Projects/Slovo/schedule/backend/.venv/lib/python3.13/site-packages/starlette/_exception_handler.py", line 53, in wrapped_app
    raise exc
  File "/home/dfx_17/Projects/Slovo/schedule/backend/.venv/lib/python3.13/site-packages/starlette/_exception_handler.py", line 42, in wrapped_app
    await app(scope, receive, sender)
  File "/home/dfx_17/Projects/Slovo/schedule/backend/.venv/lib/python3.13/site-packages/starlette/routing.py", line 714, in __call__
    await self.middleware_stack(scope, receive, send)
  File "/home/dfx_17/Projects/Slovo/schedule/backend/.venv/lib/python3.13/site-packages/starlette/routing.py", line 734, in app
    await route.handle(scope, receive, send)
  File "/home/dfx_17/Projects/Slovo/schedule/backend/.venv/lib/python3.13/site-packages/starlette/routing.py", line 288, in handle
    await self.app(scope, receive, send)
  File "/home/dfx_17/Projects/Slovo/schedule/backend/.venv/lib/python3.13/site-packages/starlette/routing.py", line 76, in app
    await wrap_app_handling_exceptions(app, request)(scope, receive, send)
  File "/home/dfx_17/Projects/Slovo/schedule/backend/.venv/lib/python3.13/site-packages/starlette/_exception_handler.py", line 53, in wrapped_app
    raise exc
  File "/home/dfx_17/Projects/Slovo/schedule/backend/.venv/lib/python3.13/site-packages/starlette/_exception_handler.py", line 42, in wrapped_app
    await app(scope, receive, sender)
  File "/home/dfx_17/Projects/Slovo/schedule/backend/.venv/lib/python3.13/site-packages/starlette/routing.py", line 73, in app
    response = await f(request)
               ^^^^^^^^^^^^^^^^
  File "/home/dfx_17/Projects/Slovo/schedule/backend/.venv/lib/python3.13/site-packages/fastapi/routing.py", line 301, in app
    raw_response = await run_endpoint_function(
                   ^^^^^^^^^^^^^^^^^^^^^^^^^^^^
    ...<3 lines>...
    )
    ^
  File "/home/dfx_17/Projects/Slovo/schedule/backend/.venv/lib/python3.13/site-packages/fastapi/routing.py", line 212, in run_endpoint_function
    return await dependant.call(**values)
           ^^^^^^^^^^^^^^^^^^^^^^^^^^^^^^
  File "/home/dfx_17/Projects/Slovo/schedule/backend/src/api/appointment.py", line 27, in get_appointment
    data = await BitrixClient.get_crm_item(aety, id)
           ^^^^^^^^^^^^^^^^^^^^^^^^^^^^^^^^^^^^^^^^^
  File "/home/dfx_17/Projects/Slovo/schedule/backend/src/core/bitrix.py", line 32, in get_crm_item
    return await BITRIX.call("crm.item.get", items)
           ^^^^^^^^^^^^^^^^^^^^^^^^^^^^^^^^^^^^^^^^
  File "/home/dfx_17/Projects/Slovo/schedule/backend/.venv/lib/python3.13/site-packages/fast_bitrix24/logger.py", line 19, in wrapper
    return await func(*args, **kwargs)
           ^^^^^^^^^^^^^^^^^^^^^^^^^^^
  File "/home/dfx_17/Projects/Slovo/schedule/backend/.venv/lib/python3.13/site-packages/fast_bitrix24/bitrix.py", line 201, in call
    return await self.srh.run_async(request_cls(self, method, items).run())
           ^^^^^^^^^^^^^^^^^^^^^^^^^^^^^^^^^^^^^^^^^^^^^^^^^^^^^^^^^^^^^^^^
  File "/home/dfx_17/Projects/Slovo/schedule/backend/.venv/lib/python3.13/site-packages/fast_bitrix24/srh.py", line 129, in run_async
    return await coroutine
           ^^^^^^^^^^^^^^^
  File "/home/dfx_17/Projects/Slovo/schedule/backend/.venv/lib/python3.13/site-packages/fast_bitrix24/user_request.py", line 330, in run
    raw_results = await MultipleServerRequestHandlerPreserveIDs(
                  ^^^^^^^^^^^^^^^^^^^^^^^^^^^^^^^^^^^^^^^^^^^^^^
    ...<5 lines>...
    ).run()
    ^^^^^^^
  File "/home/dfx_17/Projects/Slovo/schedule/backend/.venv/lib/python3.13/site-packages/fast_bitrix24/mult_request.py", line 67, in run
    extracted_len = self.process_done_tasks(done)
  File "/home/dfx_17/Projects/Slovo/schedule/backend/.venv/lib/python3.13/site-packages/fast_bitrix24/mult_request.py", line 97, in process_done_tasks
    ).extract_results()
      ~~~~~~~~~~~~~~~^^
  File "/home/dfx_17/Projects/Slovo/schedule/backend/.venv/lib/python3.13/site-packages/fast_bitrix24/server_response.py", line 45, in extract_results
    self.raise_for_errors()
    ~~~~~~~~~~~~~~~~~~~~~^^
  File "/home/dfx_17/Projects/Slovo/schedule/backend/.venv/lib/python3.13/site-packages/fast_bitrix24/server_response.py", line 64, in raise_for_errors
    raise ErrorInServerResponseException(errors)
fast_bitrix24.server_response.ErrorInServerResponseException: {'order0000000000': {'error': 'NOT_FOUND', 'error_description': 'Элемент не найден'}}

2025-06-06 23:38:45.870 | CRITICAL | /home/dfx_17/Projects/Slovo/schedule/backend/.venv/lib/python3.13/site-packages/starlette/applications.py:112 (__call__)
Traceback (most recent call last):
  File "/home/dfx_17/Projects/Slovo/schedule/backend/.venv/lib/python3.13/site-packages/starlette/middleware/base.py", line 148, in call_next
    message = await recv_stream.receive()
              ^^^^^^^^^^^^^^^^^^^^^^^^^^^
  File "/home/dfx_17/Projects/Slovo/schedule/backend/.venv/lib/python3.13/site-packages/anyio/streams/memory.py", line 126, in receive
    raise EndOfStream from None
anyio.EndOfStream

During handling of the above exception, another exception occurred:

Traceback (most recent call last):
  File "/home/dfx_17/Projects/Slovo/schedule/backend/src/middleware.py", line 32, in dispatch
    return await call_next(request)
           ^^^^^^^^^^^^^^^^^^^^^^^^
  File "/home/dfx_17/Projects/Slovo/schedule/backend/.venv/lib/python3.13/site-packages/starlette/middleware/base.py", line 156, in call_next
    raise app_exc
  File "/home/dfx_17/Projects/Slovo/schedule/backend/.venv/lib/python3.13/site-packages/starlette/middleware/base.py", line 141, in coro
    await self.app(scope, receive_or_disconnect, send_no_error)
  File "/home/dfx_17/Projects/Slovo/schedule/backend/.venv/lib/python3.13/site-packages/starlette/middleware/cors.py", line 85, in __call__
    await self.app(scope, receive, send)
  File "/home/dfx_17/Projects/Slovo/schedule/backend/.venv/lib/python3.13/site-packages/starlette/middleware/exceptions.py", line 62, in __call__
    await wrap_app_handling_exceptions(self.app, conn)(scope, receive, send)
  File "/home/dfx_17/Projects/Slovo/schedule/backend/.venv/lib/python3.13/site-packages/starlette/_exception_handler.py", line 53, in wrapped_app
    raise exc
  File "/home/dfx_17/Projects/Slovo/schedule/backend/.venv/lib/python3.13/site-packages/starlette/_exception_handler.py", line 42, in wrapped_app
    await app(scope, receive, sender)
  File "/home/dfx_17/Projects/Slovo/schedule/backend/.venv/lib/python3.13/site-packages/starlette/routing.py", line 714, in __call__
    await self.middleware_stack(scope, receive, send)
  File "/home/dfx_17/Projects/Slovo/schedule/backend/.venv/lib/python3.13/site-packages/starlette/routing.py", line 734, in app
    await route.handle(scope, receive, send)
  File "/home/dfx_17/Projects/Slovo/schedule/backend/.venv/lib/python3.13/site-packages/starlette/routing.py", line 288, in handle
    await self.app(scope, receive, send)
  File "/home/dfx_17/Projects/Slovo/schedule/backend/.venv/lib/python3.13/site-packages/starlette/routing.py", line 76, in app
    await wrap_app_handling_exceptions(app, request)(scope, receive, send)
  File "/home/dfx_17/Projects/Slovo/schedule/backend/.venv/lib/python3.13/site-packages/starlette/_exception_handler.py", line 53, in wrapped_app
    raise exc
  File "/home/dfx_17/Projects/Slovo/schedule/backend/.venv/lib/python3.13/site-packages/starlette/_exception_handler.py", line 42, in wrapped_app
    await app(scope, receive, sender)
  File "/home/dfx_17/Projects/Slovo/schedule/backend/.venv/lib/python3.13/site-packages/starlette/routing.py", line 73, in app
    response = await f(request)
               ^^^^^^^^^^^^^^^^
  File "/home/dfx_17/Projects/Slovo/schedule/backend/.venv/lib/python3.13/site-packages/fastapi/routing.py", line 301, in app
    raw_response = await run_endpoint_function(
                   ^^^^^^^^^^^^^^^^^^^^^^^^^^^^
    ...<3 lines>...
    )
    ^
  File "/home/dfx_17/Projects/Slovo/schedule/backend/.venv/lib/python3.13/site-packages/fastapi/routing.py", line 212, in run_endpoint_function
    return await dependant.call(**values)
           ^^^^^^^^^^^^^^^^^^^^^^^^^^^^^^
  File "/home/dfx_17/Projects/Slovo/schedule/backend/src/api/appointment.py", line 27, in get_appointment
    data = await BitrixClient.get_crm_item(aety, id)
           ^^^^^^^^^^^^^^^^^^^^^^^^^^^^^^^^^^^^^^^^^
  File "/home/dfx_17/Projects/Slovo/schedule/backend/src/core/bitrix.py", line 32, in get_crm_item
    return await BITRIX.call("crm.item.get", items)
           ^^^^^^^^^^^^^^^^^^^^^^^^^^^^^^^^^^^^^^^^
  File "/home/dfx_17/Projects/Slovo/schedule/backend/.venv/lib/python3.13/site-packages/fast_bitrix24/logger.py", line 19, in wrapper
    return await func(*args, **kwargs)
           ^^^^^^^^^^^^^^^^^^^^^^^^^^^
  File "/home/dfx_17/Projects/Slovo/schedule/backend/.venv/lib/python3.13/site-packages/fast_bitrix24/bitrix.py", line 201, in call
    return await self.srh.run_async(request_cls(self, method, items).run())
           ^^^^^^^^^^^^^^^^^^^^^^^^^^^^^^^^^^^^^^^^^^^^^^^^^^^^^^^^^^^^^^^^
  File "/home/dfx_17/Projects/Slovo/schedule/backend/.venv/lib/python3.13/site-packages/fast_bitrix24/srh.py", line 129, in run_async
    return await coroutine
           ^^^^^^^^^^^^^^^
  File "/home/dfx_17/Projects/Slovo/schedule/backend/.venv/lib/python3.13/site-packages/fast_bitrix24/user_request.py", line 330, in run
    raw_results = await MultipleServerRequestHandlerPreserveIDs(
                  ^^^^^^^^^^^^^^^^^^^^^^^^^^^^^^^^^^^^^^^^^^^^^^
    ...<5 lines>...
    ).run()
    ^^^^^^^
  File "/home/dfx_17/Projects/Slovo/schedule/backend/.venv/lib/python3.13/site-packages/fast_bitrix24/mult_request.py", line 67, in run
    extracted_len = self.process_done_tasks(done)
  File "/home/dfx_17/Projects/Slovo/schedule/backend/.venv/lib/python3.13/site-packages/fast_bitrix24/mult_request.py", line 97, in process_done_tasks
    ).extract_results()
      ~~~~~~~~~~~~~~~^^
  File "/home/dfx_17/Projects/Slovo/schedule/backend/.venv/lib/python3.13/site-packages/fast_bitrix24/server_response.py", line 45, in extract_results
    self.raise_for_errors()
    ~~~~~~~~~~~~~~~~~~~~~^^
  File "/home/dfx_17/Projects/Slovo/schedule/backend/.venv/lib/python3.13/site-packages/fast_bitrix24/server_response.py", line 64, in raise_for_errors
    raise ErrorInServerResponseException(errors)
fast_bitrix24.server_response.ErrorInServerResponseException: {'order0000000000': {'error': 'NOT_FOUND', 'error_description': 'Элемент не найден'}}

2025-06-06 23:39:40.103 | CRITICAL | /home/dfx_17/Projects/Slovo/schedule/backend/.venv/lib/python3.13/site-packages/starlette/applications.py:112 (__call__)
Traceback (most recent call last):
  File "/home/dfx_17/Projects/Slovo/schedule/backend/.venv/lib/python3.13/site-packages/starlette/middleware/base.py", line 148, in call_next
    message = await recv_stream.receive()
              ^^^^^^^^^^^^^^^^^^^^^^^^^^^
  File "/home/dfx_17/Projects/Slovo/schedule/backend/.venv/lib/python3.13/site-packages/anyio/streams/memory.py", line 126, in receive
    raise EndOfStream from None
anyio.EndOfStream

During handling of the above exception, another exception occurred:

Traceback (most recent call last):
  File "/home/dfx_17/Projects/Slovo/schedule/backend/src/middleware.py", line 32, in dispatch
    return await call_next(request)
           ^^^^^^^^^^^^^^^^^^^^^^^^
  File "/home/dfx_17/Projects/Slovo/schedule/backend/.venv/lib/python3.13/site-packages/starlette/middleware/base.py", line 156, in call_next
    raise app_exc
  File "/home/dfx_17/Projects/Slovo/schedule/backend/.venv/lib/python3.13/site-packages/starlette/middleware/base.py", line 141, in coro
    await self.app(scope, receive_or_disconnect, send_no_error)
  File "/home/dfx_17/Projects/Slovo/schedule/backend/.venv/lib/python3.13/site-packages/starlette/middleware/cors.py", line 85, in __call__
    await self.app(scope, receive, send)
  File "/home/dfx_17/Projects/Slovo/schedule/backend/.venv/lib/python3.13/site-packages/starlette/middleware/exceptions.py", line 62, in __call__
    await wrap_app_handling_exceptions(self.app, conn)(scope, receive, send)
  File "/home/dfx_17/Projects/Slovo/schedule/backend/.venv/lib/python3.13/site-packages/starlette/_exception_handler.py", line 53, in wrapped_app
    raise exc
  File "/home/dfx_17/Projects/Slovo/schedule/backend/.venv/lib/python3.13/site-packages/starlette/_exception_handler.py", line 42, in wrapped_app
    await app(scope, receive, sender)
  File "/home/dfx_17/Projects/Slovo/schedule/backend/.venv/lib/python3.13/site-packages/starlette/routing.py", line 714, in __call__
    await self.middleware_stack(scope, receive, send)
  File "/home/dfx_17/Projects/Slovo/schedule/backend/.venv/lib/python3.13/site-packages/starlette/routing.py", line 734, in app
    await route.handle(scope, receive, send)
  File "/home/dfx_17/Projects/Slovo/schedule/backend/.venv/lib/python3.13/site-packages/starlette/routing.py", line 288, in handle
    await self.app(scope, receive, send)
  File "/home/dfx_17/Projects/Slovo/schedule/backend/.venv/lib/python3.13/site-packages/starlette/routing.py", line 76, in app
    await wrap_app_handling_exceptions(app, request)(scope, receive, send)
  File "/home/dfx_17/Projects/Slovo/schedule/backend/.venv/lib/python3.13/site-packages/starlette/_exception_handler.py", line 53, in wrapped_app
    raise exc
  File "/home/dfx_17/Projects/Slovo/schedule/backend/.venv/lib/python3.13/site-packages/starlette/_exception_handler.py", line 42, in wrapped_app
    await app(scope, receive, sender)
  File "/home/dfx_17/Projects/Slovo/schedule/backend/.venv/lib/python3.13/site-packages/starlette/routing.py", line 73, in app
    response = await f(request)
               ^^^^^^^^^^^^^^^^
  File "/home/dfx_17/Projects/Slovo/schedule/backend/.venv/lib/python3.13/site-packages/fastapi/routing.py", line 301, in app
    raw_response = await run_endpoint_function(
                   ^^^^^^^^^^^^^^^^^^^^^^^^^^^^
    ...<3 lines>...
    )
    ^
  File "/home/dfx_17/Projects/Slovo/schedule/backend/.venv/lib/python3.13/site-packages/fastapi/routing.py", line 212, in run_endpoint_function
    return await dependant.call(**values)
           ^^^^^^^^^^^^^^^^^^^^^^^^^^^^^^
  File "/home/dfx_17/Projects/Slovo/schedule/backend/src/api/appointment.py", line 27, in get_appointment
    data = await BitrixClient.get_crm_item(aety, id)
           ^^^^^^^^^^^^^^^^^^^^^^^^^^^^^^^^^^^^^^^^^
  File "/home/dfx_17/Projects/Slovo/schedule/backend/src/core/bitrix.py", line 32, in get_crm_item
    return await BITRIX.call("crm.item.get", items)
           ^^^^^^^^^^^^^^^^^^^^^^^^^^^^^^^^^^^^^^^^
  File "/home/dfx_17/Projects/Slovo/schedule/backend/.venv/lib/python3.13/site-packages/fast_bitrix24/logger.py", line 19, in wrapper
    return await func(*args, **kwargs)
           ^^^^^^^^^^^^^^^^^^^^^^^^^^^
  File "/home/dfx_17/Projects/Slovo/schedule/backend/.venv/lib/python3.13/site-packages/fast_bitrix24/bitrix.py", line 201, in call
    return await self.srh.run_async(request_cls(self, method, items).run())
           ^^^^^^^^^^^^^^^^^^^^^^^^^^^^^^^^^^^^^^^^^^^^^^^^^^^^^^^^^^^^^^^^
  File "/home/dfx_17/Projects/Slovo/schedule/backend/.venv/lib/python3.13/site-packages/fast_bitrix24/srh.py", line 129, in run_async
    return await coroutine
           ^^^^^^^^^^^^^^^
  File "/home/dfx_17/Projects/Slovo/schedule/backend/.venv/lib/python3.13/site-packages/fast_bitrix24/user_request.py", line 330, in run
    raw_results = await MultipleServerRequestHandlerPreserveIDs(
                  ^^^^^^^^^^^^^^^^^^^^^^^^^^^^^^^^^^^^^^^^^^^^^^
    ...<5 lines>...
    ).run()
    ^^^^^^^
  File "/home/dfx_17/Projects/Slovo/schedule/backend/.venv/lib/python3.13/site-packages/fast_bitrix24/mult_request.py", line 67, in run
    extracted_len = self.process_done_tasks(done)
  File "/home/dfx_17/Projects/Slovo/schedule/backend/.venv/lib/python3.13/site-packages/fast_bitrix24/mult_request.py", line 97, in process_done_tasks
    ).extract_results()
      ~~~~~~~~~~~~~~~^^
  File "/home/dfx_17/Projects/Slovo/schedule/backend/.venv/lib/python3.13/site-packages/fast_bitrix24/server_response.py", line 45, in extract_results
    self.raise_for_errors()
    ~~~~~~~~~~~~~~~~~~~~~^^
  File "/home/dfx_17/Projects/Slovo/schedule/backend/.venv/lib/python3.13/site-packages/fast_bitrix24/server_response.py", line 64, in raise_for_errors
    raise ErrorInServerResponseException(errors)
fast_bitrix24.server_response.ErrorInServerResponseException: {'order0000000000': {'error': 'NOT_FOUND', 'error_description': 'Элемент не найден'}}

2025-06-06 23:39:41.774 | CRITICAL | /home/dfx_17/Projects/Slovo/schedule/backend/.venv/lib/python3.13/site-packages/starlette/applications.py:112 (__call__)
Traceback (most recent call last):
  File "/home/dfx_17/Projects/Slovo/schedule/backend/.venv/lib/python3.13/site-packages/starlette/middleware/base.py", line 148, in call_next
    message = await recv_stream.receive()
              ^^^^^^^^^^^^^^^^^^^^^^^^^^^
  File "/home/dfx_17/Projects/Slovo/schedule/backend/.venv/lib/python3.13/site-packages/anyio/streams/memory.py", line 126, in receive
    raise EndOfStream from None
anyio.EndOfStream

During handling of the above exception, another exception occurred:

Traceback (most recent call last):
  File "/home/dfx_17/Projects/Slovo/schedule/backend/src/middleware.py", line 32, in dispatch
    return await call_next(request)
           ^^^^^^^^^^^^^^^^^^^^^^^^
  File "/home/dfx_17/Projects/Slovo/schedule/backend/.venv/lib/python3.13/site-packages/starlette/middleware/base.py", line 156, in call_next
    raise app_exc
  File "/home/dfx_17/Projects/Slovo/schedule/backend/.venv/lib/python3.13/site-packages/starlette/middleware/base.py", line 141, in coro
    await self.app(scope, receive_or_disconnect, send_no_error)
  File "/home/dfx_17/Projects/Slovo/schedule/backend/.venv/lib/python3.13/site-packages/starlette/middleware/cors.py", line 85, in __call__
    await self.app(scope, receive, send)
  File "/home/dfx_17/Projects/Slovo/schedule/backend/.venv/lib/python3.13/site-packages/starlette/middleware/exceptions.py", line 62, in __call__
    await wrap_app_handling_exceptions(self.app, conn)(scope, receive, send)
  File "/home/dfx_17/Projects/Slovo/schedule/backend/.venv/lib/python3.13/site-packages/starlette/_exception_handler.py", line 53, in wrapped_app
    raise exc
  File "/home/dfx_17/Projects/Slovo/schedule/backend/.venv/lib/python3.13/site-packages/starlette/_exception_handler.py", line 42, in wrapped_app
    await app(scope, receive, sender)
  File "/home/dfx_17/Projects/Slovo/schedule/backend/.venv/lib/python3.13/site-packages/starlette/routing.py", line 714, in __call__
    await self.middleware_stack(scope, receive, send)
  File "/home/dfx_17/Projects/Slovo/schedule/backend/.venv/lib/python3.13/site-packages/starlette/routing.py", line 734, in app
    await route.handle(scope, receive, send)
  File "/home/dfx_17/Projects/Slovo/schedule/backend/.venv/lib/python3.13/site-packages/starlette/routing.py", line 288, in handle
    await self.app(scope, receive, send)
  File "/home/dfx_17/Projects/Slovo/schedule/backend/.venv/lib/python3.13/site-packages/starlette/routing.py", line 76, in app
    await wrap_app_handling_exceptions(app, request)(scope, receive, send)
  File "/home/dfx_17/Projects/Slovo/schedule/backend/.venv/lib/python3.13/site-packages/starlette/_exception_handler.py", line 53, in wrapped_app
    raise exc
  File "/home/dfx_17/Projects/Slovo/schedule/backend/.venv/lib/python3.13/site-packages/starlette/_exception_handler.py", line 42, in wrapped_app
    await app(scope, receive, sender)
  File "/home/dfx_17/Projects/Slovo/schedule/backend/.venv/lib/python3.13/site-packages/starlette/routing.py", line 73, in app
    response = await f(request)
               ^^^^^^^^^^^^^^^^
  File "/home/dfx_17/Projects/Slovo/schedule/backend/.venv/lib/python3.13/site-packages/fastapi/routing.py", line 301, in app
    raw_response = await run_endpoint_function(
                   ^^^^^^^^^^^^^^^^^^^^^^^^^^^^
    ...<3 lines>...
    )
    ^
  File "/home/dfx_17/Projects/Slovo/schedule/backend/.venv/lib/python3.13/site-packages/fastapi/routing.py", line 212, in run_endpoint_function
    return await dependant.call(**values)
           ^^^^^^^^^^^^^^^^^^^^^^^^^^^^^^
  File "/home/dfx_17/Projects/Slovo/schedule/backend/src/api/appointment.py", line 40, in update_appointment
    updated_data = await BitrixClient.update_crm_item(aety, id, fields)
                   ^^^^^^^^^^^^^^^^^^^^^^^^^^^^^^^^^^^^^^^^^^^^^^^^^^^^
  File "/home/dfx_17/Projects/Slovo/schedule/backend/src/core/bitrix.py", line 37, in update_crm_item
    return await BITRIX.call('crm.item.update', items)
           ^^^^^^^^^^^^^^^^^^^^^^^^^^^^^^^^^^^^^^^^^^^
  File "/home/dfx_17/Projects/Slovo/schedule/backend/.venv/lib/python3.13/site-packages/fast_bitrix24/logger.py", line 19, in wrapper
    return await func(*args, **kwargs)
           ^^^^^^^^^^^^^^^^^^^^^^^^^^^
  File "/home/dfx_17/Projects/Slovo/schedule/backend/.venv/lib/python3.13/site-packages/fast_bitrix24/bitrix.py", line 201, in call
    return await self.srh.run_async(request_cls(self, method, items).run())
           ^^^^^^^^^^^^^^^^^^^^^^^^^^^^^^^^^^^^^^^^^^^^^^^^^^^^^^^^^^^^^^^^
  File "/home/dfx_17/Projects/Slovo/schedule/backend/.venv/lib/python3.13/site-packages/fast_bitrix24/srh.py", line 129, in run_async
    return await coroutine
           ^^^^^^^^^^^^^^^
  File "/home/dfx_17/Projects/Slovo/schedule/backend/.venv/lib/python3.13/site-packages/fast_bitrix24/user_request.py", line 330, in run
    raw_results = await MultipleServerRequestHandlerPreserveIDs(
                  ^^^^^^^^^^^^^^^^^^^^^^^^^^^^^^^^^^^^^^^^^^^^^^
    ...<5 lines>...
    ).run()
    ^^^^^^^
  File "/home/dfx_17/Projects/Slovo/schedule/backend/.venv/lib/python3.13/site-packages/fast_bitrix24/mult_request.py", line 67, in run
    extracted_len = self.process_done_tasks(done)
  File "/home/dfx_17/Projects/Slovo/schedule/backend/.venv/lib/python3.13/site-packages/fast_bitrix24/mult_request.py", line 97, in process_done_tasks
    ).extract_results()
      ~~~~~~~~~~~~~~~^^
  File "/home/dfx_17/Projects/Slovo/schedule/backend/.venv/lib/python3.13/site-packages/fast_bitrix24/server_response.py", line 45, in extract_results
    self.raise_for_errors()
    ~~~~~~~~~~~~~~~~~~~~~^^
  File "/home/dfx_17/Projects/Slovo/schedule/backend/.venv/lib/python3.13/site-packages/fast_bitrix24/server_response.py", line 64, in raise_for_errors
    raise ErrorInServerResponseException(errors)
fast_bitrix24.server_response.ErrorInServerResponseException: {'order0000000000': {'error': 'NOT_FOUND', 'error_description': 'Элемент не найден'}}

2025-06-06 23:40:40.454 | CRITICAL | /home/dfx_17/Projects/Slovo/schedule/backend/.venv/lib/python3.13/site-packages/starlette/applications.py:112 (__call__)
Traceback (most recent call last):
  File "/home/dfx_17/Projects/Slovo/schedule/backend/.venv/lib/python3.13/site-packages/starlette/middleware/base.py", line 148, in call_next
    message = await recv_stream.receive()
              ^^^^^^^^^^^^^^^^^^^^^^^^^^^
  File "/home/dfx_17/Projects/Slovo/schedule/backend/.venv/lib/python3.13/site-packages/anyio/streams/memory.py", line 126, in receive
    raise EndOfStream from None
anyio.EndOfStream

During handling of the above exception, another exception occurred:

Traceback (most recent call last):
  File "/home/dfx_17/Projects/Slovo/schedule/backend/src/middleware.py", line 32, in dispatch
    return await call_next(request)
           ^^^^^^^^^^^^^^^^^^^^^^^^
  File "/home/dfx_17/Projects/Slovo/schedule/backend/.venv/lib/python3.13/site-packages/starlette/middleware/base.py", line 156, in call_next
    raise app_exc
  File "/home/dfx_17/Projects/Slovo/schedule/backend/.venv/lib/python3.13/site-packages/starlette/middleware/base.py", line 141, in coro
    await self.app(scope, receive_or_disconnect, send_no_error)
  File "/home/dfx_17/Projects/Slovo/schedule/backend/.venv/lib/python3.13/site-packages/starlette/middleware/cors.py", line 85, in __call__
    await self.app(scope, receive, send)
  File "/home/dfx_17/Projects/Slovo/schedule/backend/.venv/lib/python3.13/site-packages/starlette/middleware/exceptions.py", line 62, in __call__
    await wrap_app_handling_exceptions(self.app, conn)(scope, receive, send)
  File "/home/dfx_17/Projects/Slovo/schedule/backend/.venv/lib/python3.13/site-packages/starlette/_exception_handler.py", line 53, in wrapped_app
    raise exc
  File "/home/dfx_17/Projects/Slovo/schedule/backend/.venv/lib/python3.13/site-packages/starlette/_exception_handler.py", line 42, in wrapped_app
    await app(scope, receive, sender)
  File "/home/dfx_17/Projects/Slovo/schedule/backend/.venv/lib/python3.13/site-packages/starlette/routing.py", line 714, in __call__
    await self.middleware_stack(scope, receive, send)
  File "/home/dfx_17/Projects/Slovo/schedule/backend/.venv/lib/python3.13/site-packages/starlette/routing.py", line 734, in app
    await route.handle(scope, receive, send)
  File "/home/dfx_17/Projects/Slovo/schedule/backend/.venv/lib/python3.13/site-packages/starlette/routing.py", line 288, in handle
    await self.app(scope, receive, send)
  File "/home/dfx_17/Projects/Slovo/schedule/backend/.venv/lib/python3.13/site-packages/starlette/routing.py", line 76, in app
    await wrap_app_handling_exceptions(app, request)(scope, receive, send)
  File "/home/dfx_17/Projects/Slovo/schedule/backend/.venv/lib/python3.13/site-packages/starlette/_exception_handler.py", line 53, in wrapped_app
    raise exc
  File "/home/dfx_17/Projects/Slovo/schedule/backend/.venv/lib/python3.13/site-packages/starlette/_exception_handler.py", line 42, in wrapped_app
    await app(scope, receive, sender)
  File "/home/dfx_17/Projects/Slovo/schedule/backend/.venv/lib/python3.13/site-packages/starlette/routing.py", line 73, in app
    response = await f(request)
               ^^^^^^^^^^^^^^^^
  File "/home/dfx_17/Projects/Slovo/schedule/backend/.venv/lib/python3.13/site-packages/fastapi/routing.py", line 301, in app
    raw_response = await run_endpoint_function(
                   ^^^^^^^^^^^^^^^^^^^^^^^^^^^^
    ...<3 lines>...
    )
    ^
  File "/home/dfx_17/Projects/Slovo/schedule/backend/.venv/lib/python3.13/site-packages/fastapi/routing.py", line 212, in run_endpoint_function
    return await dependant.call(**values)
           ^^^^^^^^^^^^^^^^^^^^^^^^^^^^^^
  File "/home/dfx_17/Projects/Slovo/schedule/backend/src/api/appointment.py", line 27, in get_appointment
    data = await BitrixClient.get_crm_item(aety, id)
           ^^^^^^^^^^^^^^^^^^^^^^^^^^^^^^^^^^^^^^^^^
  File "/home/dfx_17/Projects/Slovo/schedule/backend/src/core/bitrix.py", line 32, in get_crm_item
    return await BITRIX.call("crm.item.get", items)
           ^^^^^^^^^^^^^^^^^^^^^^^^^^^^^^^^^^^^^^^^
  File "/home/dfx_17/Projects/Slovo/schedule/backend/.venv/lib/python3.13/site-packages/fast_bitrix24/logger.py", line 19, in wrapper
    return await func(*args, **kwargs)
           ^^^^^^^^^^^^^^^^^^^^^^^^^^^
  File "/home/dfx_17/Projects/Slovo/schedule/backend/.venv/lib/python3.13/site-packages/fast_bitrix24/bitrix.py", line 201, in call
    return await self.srh.run_async(request_cls(self, method, items).run())
           ^^^^^^^^^^^^^^^^^^^^^^^^^^^^^^^^^^^^^^^^^^^^^^^^^^^^^^^^^^^^^^^^
  File "/home/dfx_17/Projects/Slovo/schedule/backend/.venv/lib/python3.13/site-packages/fast_bitrix24/srh.py", line 129, in run_async
    return await coroutine
           ^^^^^^^^^^^^^^^
  File "/home/dfx_17/Projects/Slovo/schedule/backend/.venv/lib/python3.13/site-packages/fast_bitrix24/user_request.py", line 330, in run
    raw_results = await MultipleServerRequestHandlerPreserveIDs(
                  ^^^^^^^^^^^^^^^^^^^^^^^^^^^^^^^^^^^^^^^^^^^^^^
    ...<5 lines>...
    ).run()
    ^^^^^^^
  File "/home/dfx_17/Projects/Slovo/schedule/backend/.venv/lib/python3.13/site-packages/fast_bitrix24/mult_request.py", line 67, in run
    extracted_len = self.process_done_tasks(done)
  File "/home/dfx_17/Projects/Slovo/schedule/backend/.venv/lib/python3.13/site-packages/fast_bitrix24/mult_request.py", line 97, in process_done_tasks
    ).extract_results()
      ~~~~~~~~~~~~~~~^^
  File "/home/dfx_17/Projects/Slovo/schedule/backend/.venv/lib/python3.13/site-packages/fast_bitrix24/server_response.py", line 45, in extract_results
    self.raise_for_errors()
    ~~~~~~~~~~~~~~~~~~~~~^^
  File "/home/dfx_17/Projects/Slovo/schedule/backend/.venv/lib/python3.13/site-packages/fast_bitrix24/server_response.py", line 64, in raise_for_errors
    raise ErrorInServerResponseException(errors)
fast_bitrix24.server_response.ErrorInServerResponseException: {'order0000000000': {'error': 'NOT_FOUND', 'error_description': 'Элемент не найден'}}

2025-06-06 23:40:41.781 | CRITICAL | /home/dfx_17/Projects/Slovo/schedule/backend/.venv/lib/python3.13/site-packages/starlette/applications.py:112 (__call__)
Traceback (most recent call last):
  File "/home/dfx_17/Projects/Slovo/schedule/backend/.venv/lib/python3.13/site-packages/starlette/middleware/base.py", line 148, in call_next
    message = await recv_stream.receive()
              ^^^^^^^^^^^^^^^^^^^^^^^^^^^
  File "/home/dfx_17/Projects/Slovo/schedule/backend/.venv/lib/python3.13/site-packages/anyio/streams/memory.py", line 126, in receive
    raise EndOfStream from None
anyio.EndOfStream

During handling of the above exception, another exception occurred:

Traceback (most recent call last):
  File "/home/dfx_17/Projects/Slovo/schedule/backend/src/middleware.py", line 32, in dispatch
    return await call_next(request)
           ^^^^^^^^^^^^^^^^^^^^^^^^
  File "/home/dfx_17/Projects/Slovo/schedule/backend/.venv/lib/python3.13/site-packages/starlette/middleware/base.py", line 156, in call_next
    raise app_exc
  File "/home/dfx_17/Projects/Slovo/schedule/backend/.venv/lib/python3.13/site-packages/starlette/middleware/base.py", line 141, in coro
    await self.app(scope, receive_or_disconnect, send_no_error)
  File "/home/dfx_17/Projects/Slovo/schedule/backend/.venv/lib/python3.13/site-packages/starlette/middleware/cors.py", line 85, in __call__
    await self.app(scope, receive, send)
  File "/home/dfx_17/Projects/Slovo/schedule/backend/.venv/lib/python3.13/site-packages/starlette/middleware/exceptions.py", line 62, in __call__
    await wrap_app_handling_exceptions(self.app, conn)(scope, receive, send)
  File "/home/dfx_17/Projects/Slovo/schedule/backend/.venv/lib/python3.13/site-packages/starlette/_exception_handler.py", line 53, in wrapped_app
    raise exc
  File "/home/dfx_17/Projects/Slovo/schedule/backend/.venv/lib/python3.13/site-packages/starlette/_exception_handler.py", line 42, in wrapped_app
    await app(scope, receive, sender)
  File "/home/dfx_17/Projects/Slovo/schedule/backend/.venv/lib/python3.13/site-packages/starlette/routing.py", line 714, in __call__
    await self.middleware_stack(scope, receive, send)
  File "/home/dfx_17/Projects/Slovo/schedule/backend/.venv/lib/python3.13/site-packages/starlette/routing.py", line 734, in app
    await route.handle(scope, receive, send)
  File "/home/dfx_17/Projects/Slovo/schedule/backend/.venv/lib/python3.13/site-packages/starlette/routing.py", line 288, in handle
    await self.app(scope, receive, send)
  File "/home/dfx_17/Projects/Slovo/schedule/backend/.venv/lib/python3.13/site-packages/starlette/routing.py", line 76, in app
    await wrap_app_handling_exceptions(app, request)(scope, receive, send)
  File "/home/dfx_17/Projects/Slovo/schedule/backend/.venv/lib/python3.13/site-packages/starlette/_exception_handler.py", line 53, in wrapped_app
    raise exc
  File "/home/dfx_17/Projects/Slovo/schedule/backend/.venv/lib/python3.13/site-packages/starlette/_exception_handler.py", line 42, in wrapped_app
    await app(scope, receive, sender)
  File "/home/dfx_17/Projects/Slovo/schedule/backend/.venv/lib/python3.13/site-packages/starlette/routing.py", line 73, in app
    response = await f(request)
               ^^^^^^^^^^^^^^^^
  File "/home/dfx_17/Projects/Slovo/schedule/backend/.venv/lib/python3.13/site-packages/fastapi/routing.py", line 301, in app
    raw_response = await run_endpoint_function(
                   ^^^^^^^^^^^^^^^^^^^^^^^^^^^^
    ...<3 lines>...
    )
    ^
  File "/home/dfx_17/Projects/Slovo/schedule/backend/.venv/lib/python3.13/site-packages/fastapi/routing.py", line 212, in run_endpoint_function
    return await dependant.call(**values)
           ^^^^^^^^^^^^^^^^^^^^^^^^^^^^^^
  File "/home/dfx_17/Projects/Slovo/schedule/backend/src/api/appointment.py", line 40, in update_appointment
    updated_data = await BitrixClient.update_crm_item(aety, id, fields)
                   ^^^^^^^^^^^^^^^^^^^^^^^^^^^^^^^^^^^^^^^^^^^^^^^^^^^^
  File "/home/dfx_17/Projects/Slovo/schedule/backend/src/core/bitrix.py", line 37, in update_crm_item
    return await BITRIX.call('crm.item.update', items)
           ^^^^^^^^^^^^^^^^^^^^^^^^^^^^^^^^^^^^^^^^^^^
  File "/home/dfx_17/Projects/Slovo/schedule/backend/.venv/lib/python3.13/site-packages/fast_bitrix24/logger.py", line 19, in wrapper
    return await func(*args, **kwargs)
           ^^^^^^^^^^^^^^^^^^^^^^^^^^^
  File "/home/dfx_17/Projects/Slovo/schedule/backend/.venv/lib/python3.13/site-packages/fast_bitrix24/bitrix.py", line 201, in call
    return await self.srh.run_async(request_cls(self, method, items).run())
           ^^^^^^^^^^^^^^^^^^^^^^^^^^^^^^^^^^^^^^^^^^^^^^^^^^^^^^^^^^^^^^^^
  File "/home/dfx_17/Projects/Slovo/schedule/backend/.venv/lib/python3.13/site-packages/fast_bitrix24/srh.py", line 129, in run_async
    return await coroutine
           ^^^^^^^^^^^^^^^
  File "/home/dfx_17/Projects/Slovo/schedule/backend/.venv/lib/python3.13/site-packages/fast_bitrix24/user_request.py", line 330, in run
    raw_results = await MultipleServerRequestHandlerPreserveIDs(
                  ^^^^^^^^^^^^^^^^^^^^^^^^^^^^^^^^^^^^^^^^^^^^^^
    ...<5 lines>...
    ).run()
    ^^^^^^^
  File "/home/dfx_17/Projects/Slovo/schedule/backend/.venv/lib/python3.13/site-packages/fast_bitrix24/mult_request.py", line 67, in run
    extracted_len = self.process_done_tasks(done)
  File "/home/dfx_17/Projects/Slovo/schedule/backend/.venv/lib/python3.13/site-packages/fast_bitrix24/mult_request.py", line 97, in process_done_tasks
    ).extract_results()
      ~~~~~~~~~~~~~~~^^
  File "/home/dfx_17/Projects/Slovo/schedule/backend/.venv/lib/python3.13/site-packages/fast_bitrix24/server_response.py", line 45, in extract_results
    self.raise_for_errors()
    ~~~~~~~~~~~~~~~~~~~~~^^
  File "/home/dfx_17/Projects/Slovo/schedule/backend/.venv/lib/python3.13/site-packages/fast_bitrix24/server_response.py", line 64, in raise_for_errors
    raise ErrorInServerResponseException(errors)
fast_bitrix24.server_response.ErrorInServerResponseException: {'order0000000000': {'error': 'NOT_FOUND', 'error_description': 'Элемент не найден'}}

2025-06-07 08:21:27.372 | CRITICAL | /home/dfx_17/Projects/Slovo/schedule/backend/.venv/lib/python3.13/site-packages/starlette/applications.py:112 (__call__)
Traceback (most recent call last):
  File "/home/dfx_17/Projects/Slovo/schedule/backend/.venv/lib/python3.13/site-packages/starlette/middleware/base.py", line 148, in call_next
    message = await recv_stream.receive()
              ^^^^^^^^^^^^^^^^^^^^^^^^^^^
  File "/home/dfx_17/Projects/Slovo/schedule/backend/.venv/lib/python3.13/site-packages/anyio/streams/memory.py", line 126, in receive
    raise EndOfStream from None
anyio.EndOfStream

During handling of the above exception, another exception occurred:

Traceback (most recent call last):
  File "/home/dfx_17/Projects/Slovo/schedule/backend/src/middleware.py", line 32, in dispatch
    return await call_next(request)
           ^^^^^^^^^^^^^^^^^^^^^^^^
  File "/home/dfx_17/Projects/Slovo/schedule/backend/.venv/lib/python3.13/site-packages/starlette/middleware/base.py", line 156, in call_next
    raise app_exc
  File "/home/dfx_17/Projects/Slovo/schedule/backend/.venv/lib/python3.13/site-packages/starlette/middleware/base.py", line 141, in coro
    await self.app(scope, receive_or_disconnect, send_no_error)
  File "/home/dfx_17/Projects/Slovo/schedule/backend/.venv/lib/python3.13/site-packages/starlette/middleware/cors.py", line 85, in __call__
    await self.app(scope, receive, send)
  File "/home/dfx_17/Projects/Slovo/schedule/backend/.venv/lib/python3.13/site-packages/starlette/middleware/exceptions.py", line 62, in __call__
    await wrap_app_handling_exceptions(self.app, conn)(scope, receive, send)
  File "/home/dfx_17/Projects/Slovo/schedule/backend/.venv/lib/python3.13/site-packages/starlette/_exception_handler.py", line 53, in wrapped_app
    raise exc
  File "/home/dfx_17/Projects/Slovo/schedule/backend/.venv/lib/python3.13/site-packages/starlette/_exception_handler.py", line 42, in wrapped_app
    await app(scope, receive, sender)
  File "/home/dfx_17/Projects/Slovo/schedule/backend/.venv/lib/python3.13/site-packages/starlette/routing.py", line 714, in __call__
    await self.middleware_stack(scope, receive, send)
  File "/home/dfx_17/Projects/Slovo/schedule/backend/.venv/lib/python3.13/site-packages/starlette/routing.py", line 734, in app
    await route.handle(scope, receive, send)
  File "/home/dfx_17/Projects/Slovo/schedule/backend/.venv/lib/python3.13/site-packages/starlette/routing.py", line 288, in handle
    await self.app(scope, receive, send)
  File "/home/dfx_17/Projects/Slovo/schedule/backend/.venv/lib/python3.13/site-packages/starlette/routing.py", line 76, in app
    await wrap_app_handling_exceptions(app, request)(scope, receive, send)
  File "/home/dfx_17/Projects/Slovo/schedule/backend/.venv/lib/python3.13/site-packages/starlette/_exception_handler.py", line 53, in wrapped_app
    raise exc
  File "/home/dfx_17/Projects/Slovo/schedule/backend/.venv/lib/python3.13/site-packages/starlette/_exception_handler.py", line 42, in wrapped_app
    await app(scope, receive, sender)
  File "/home/dfx_17/Projects/Slovo/schedule/backend/.venv/lib/python3.13/site-packages/starlette/routing.py", line 73, in app
    response = await f(request)
               ^^^^^^^^^^^^^^^^
  File "/home/dfx_17/Projects/Slovo/schedule/backend/.venv/lib/python3.13/site-packages/fastapi/routing.py", line 301, in app
    raw_response = await run_endpoint_function(
                   ^^^^^^^^^^^^^^^^^^^^^^^^^^^^
    ...<3 lines>...
    )
    ^
  File "/home/dfx_17/Projects/Slovo/schedule/backend/.venv/lib/python3.13/site-packages/fastapi/routing.py", line 212, in run_endpoint_function
    return await dependant.call(**values)
           ^^^^^^^^^^^^^^^^^^^^^^^^^^^^^^
  File "/home/dfx_17/Projects/Slovo/schedule/backend/src/api/appointment.py", line 27, in get_appointment
    data = await BitrixClient.get_crm_item(aety, id)
           ^^^^^^^^^^^^^^^^^^^^^^^^^^^^^^^^^^^^^^^^^
  File "/home/dfx_17/Projects/Slovo/schedule/backend/src/core/bitrix.py", line 32, in get_crm_item
    return await BITRIX.call("crm.item.get", items)
           ^^^^^^^^^^^^^^^^^^^^^^^^^^^^^^^^^^^^^^^^
  File "/home/dfx_17/Projects/Slovo/schedule/backend/.venv/lib/python3.13/site-packages/fast_bitrix24/logger.py", line 19, in wrapper
    return await func(*args, **kwargs)
           ^^^^^^^^^^^^^^^^^^^^^^^^^^^
  File "/home/dfx_17/Projects/Slovo/schedule/backend/.venv/lib/python3.13/site-packages/fast_bitrix24/bitrix.py", line 201, in call
    return await self.srh.run_async(request_cls(self, method, items).run())
           ^^^^^^^^^^^^^^^^^^^^^^^^^^^^^^^^^^^^^^^^^^^^^^^^^^^^^^^^^^^^^^^^
  File "/home/dfx_17/Projects/Slovo/schedule/backend/.venv/lib/python3.13/site-packages/fast_bitrix24/srh.py", line 129, in run_async
    return await coroutine
           ^^^^^^^^^^^^^^^
  File "/home/dfx_17/Projects/Slovo/schedule/backend/.venv/lib/python3.13/site-packages/fast_bitrix24/user_request.py", line 330, in run
    raw_results = await MultipleServerRequestHandlerPreserveIDs(
                  ^^^^^^^^^^^^^^^^^^^^^^^^^^^^^^^^^^^^^^^^^^^^^^
    ...<5 lines>...
    ).run()
    ^^^^^^^
  File "/home/dfx_17/Projects/Slovo/schedule/backend/.venv/lib/python3.13/site-packages/fast_bitrix24/mult_request.py", line 67, in run
    extracted_len = self.process_done_tasks(done)
  File "/home/dfx_17/Projects/Slovo/schedule/backend/.venv/lib/python3.13/site-packages/fast_bitrix24/mult_request.py", line 97, in process_done_tasks
    ).extract_results()
      ~~~~~~~~~~~~~~~^^
  File "/home/dfx_17/Projects/Slovo/schedule/backend/.venv/lib/python3.13/site-packages/fast_bitrix24/server_response.py", line 45, in extract_results
    self.raise_for_errors()
    ~~~~~~~~~~~~~~~~~~~~~^^
  File "/home/dfx_17/Projects/Slovo/schedule/backend/.venv/lib/python3.13/site-packages/fast_bitrix24/server_response.py", line 64, in raise_for_errors
    raise ErrorInServerResponseException(errors)
fast_bitrix24.server_response.ErrorInServerResponseException: {'order0000000000': {'error': 'NOT_FOUND', 'error_description': 'Элемент не найден'}}

2025-06-07 08:21:28.899 | CRITICAL | /home/dfx_17/Projects/Slovo/schedule/backend/.venv/lib/python3.13/site-packages/starlette/applications.py:112 (__call__)
Traceback (most recent call last):
  File "/home/dfx_17/Projects/Slovo/schedule/backend/.venv/lib/python3.13/site-packages/starlette/middleware/base.py", line 148, in call_next
    message = await recv_stream.receive()
              ^^^^^^^^^^^^^^^^^^^^^^^^^^^
  File "/home/dfx_17/Projects/Slovo/schedule/backend/.venv/lib/python3.13/site-packages/anyio/streams/memory.py", line 126, in receive
    raise EndOfStream from None
anyio.EndOfStream

During handling of the above exception, another exception occurred:

Traceback (most recent call last):
  File "/home/dfx_17/Projects/Slovo/schedule/backend/src/middleware.py", line 32, in dispatch
    return await call_next(request)
           ^^^^^^^^^^^^^^^^^^^^^^^^
  File "/home/dfx_17/Projects/Slovo/schedule/backend/.venv/lib/python3.13/site-packages/starlette/middleware/base.py", line 156, in call_next
    raise app_exc
  File "/home/dfx_17/Projects/Slovo/schedule/backend/.venv/lib/python3.13/site-packages/starlette/middleware/base.py", line 141, in coro
    await self.app(scope, receive_or_disconnect, send_no_error)
  File "/home/dfx_17/Projects/Slovo/schedule/backend/.venv/lib/python3.13/site-packages/starlette/middleware/cors.py", line 85, in __call__
    await self.app(scope, receive, send)
  File "/home/dfx_17/Projects/Slovo/schedule/backend/.venv/lib/python3.13/site-packages/starlette/middleware/exceptions.py", line 62, in __call__
    await wrap_app_handling_exceptions(self.app, conn)(scope, receive, send)
  File "/home/dfx_17/Projects/Slovo/schedule/backend/.venv/lib/python3.13/site-packages/starlette/_exception_handler.py", line 53, in wrapped_app
    raise exc
  File "/home/dfx_17/Projects/Slovo/schedule/backend/.venv/lib/python3.13/site-packages/starlette/_exception_handler.py", line 42, in wrapped_app
    await app(scope, receive, sender)
  File "/home/dfx_17/Projects/Slovo/schedule/backend/.venv/lib/python3.13/site-packages/starlette/routing.py", line 714, in __call__
    await self.middleware_stack(scope, receive, send)
  File "/home/dfx_17/Projects/Slovo/schedule/backend/.venv/lib/python3.13/site-packages/starlette/routing.py", line 734, in app
    await route.handle(scope, receive, send)
  File "/home/dfx_17/Projects/Slovo/schedule/backend/.venv/lib/python3.13/site-packages/starlette/routing.py", line 288, in handle
    await self.app(scope, receive, send)
  File "/home/dfx_17/Projects/Slovo/schedule/backend/.venv/lib/python3.13/site-packages/starlette/routing.py", line 76, in app
    await wrap_app_handling_exceptions(app, request)(scope, receive, send)
  File "/home/dfx_17/Projects/Slovo/schedule/backend/.venv/lib/python3.13/site-packages/starlette/_exception_handler.py", line 53, in wrapped_app
    raise exc
  File "/home/dfx_17/Projects/Slovo/schedule/backend/.venv/lib/python3.13/site-packages/starlette/_exception_handler.py", line 42, in wrapped_app
    await app(scope, receive, sender)
  File "/home/dfx_17/Projects/Slovo/schedule/backend/.venv/lib/python3.13/site-packages/starlette/routing.py", line 73, in app
    response = await f(request)
               ^^^^^^^^^^^^^^^^
  File "/home/dfx_17/Projects/Slovo/schedule/backend/.venv/lib/python3.13/site-packages/fastapi/routing.py", line 301, in app
    raw_response = await run_endpoint_function(
                   ^^^^^^^^^^^^^^^^^^^^^^^^^^^^
    ...<3 lines>...
    )
    ^
  File "/home/dfx_17/Projects/Slovo/schedule/backend/.venv/lib/python3.13/site-packages/fastapi/routing.py", line 212, in run_endpoint_function
    return await dependant.call(**values)
           ^^^^^^^^^^^^^^^^^^^^^^^^^^^^^^
  File "/home/dfx_17/Projects/Slovo/schedule/backend/src/api/appointment.py", line 40, in update_appointment
    updated_data = await BitrixClient.update_crm_item(aety, id, fields)
                   ^^^^^^^^^^^^^^^^^^^^^^^^^^^^^^^^^^^^^^^^^^^^^^^^^^^^
  File "/home/dfx_17/Projects/Slovo/schedule/backend/src/core/bitrix.py", line 37, in update_crm_item
    return await BITRIX.call('crm.item.update', items)
           ^^^^^^^^^^^^^^^^^^^^^^^^^^^^^^^^^^^^^^^^^^^
  File "/home/dfx_17/Projects/Slovo/schedule/backend/.venv/lib/python3.13/site-packages/fast_bitrix24/logger.py", line 19, in wrapper
    return await func(*args, **kwargs)
           ^^^^^^^^^^^^^^^^^^^^^^^^^^^
  File "/home/dfx_17/Projects/Slovo/schedule/backend/.venv/lib/python3.13/site-packages/fast_bitrix24/bitrix.py", line 201, in call
    return await self.srh.run_async(request_cls(self, method, items).run())
           ^^^^^^^^^^^^^^^^^^^^^^^^^^^^^^^^^^^^^^^^^^^^^^^^^^^^^^^^^^^^^^^^
  File "/home/dfx_17/Projects/Slovo/schedule/backend/.venv/lib/python3.13/site-packages/fast_bitrix24/srh.py", line 129, in run_async
    return await coroutine
           ^^^^^^^^^^^^^^^
  File "/home/dfx_17/Projects/Slovo/schedule/backend/.venv/lib/python3.13/site-packages/fast_bitrix24/user_request.py", line 330, in run
    raw_results = await MultipleServerRequestHandlerPreserveIDs(
                  ^^^^^^^^^^^^^^^^^^^^^^^^^^^^^^^^^^^^^^^^^^^^^^
    ...<5 lines>...
    ).run()
    ^^^^^^^
  File "/home/dfx_17/Projects/Slovo/schedule/backend/.venv/lib/python3.13/site-packages/fast_bitrix24/mult_request.py", line 67, in run
    extracted_len = self.process_done_tasks(done)
  File "/home/dfx_17/Projects/Slovo/schedule/backend/.venv/lib/python3.13/site-packages/fast_bitrix24/mult_request.py", line 97, in process_done_tasks
    ).extract_results()
      ~~~~~~~~~~~~~~~^^
  File "/home/dfx_17/Projects/Slovo/schedule/backend/.venv/lib/python3.13/site-packages/fast_bitrix24/server_response.py", line 45, in extract_results
    self.raise_for_errors()
    ~~~~~~~~~~~~~~~~~~~~~^^
  File "/home/dfx_17/Projects/Slovo/schedule/backend/.venv/lib/python3.13/site-packages/fast_bitrix24/server_response.py", line 64, in raise_for_errors
    raise ErrorInServerResponseException(errors)
fast_bitrix24.server_response.ErrorInServerResponseException: {'order0000000000': {'error': 'NOT_FOUND', 'error_description': 'Элемент не найден'}}

2025-06-07 08:21:41.700 | CRITICAL | /home/dfx_17/Projects/Slovo/schedule/backend/.venv/lib/python3.13/site-packages/starlette/applications.py:112 (__call__)
Traceback (most recent call last):
  File "/home/dfx_17/Projects/Slovo/schedule/backend/.venv/lib/python3.13/site-packages/starlette/middleware/base.py", line 148, in call_next
    message = await recv_stream.receive()
              ^^^^^^^^^^^^^^^^^^^^^^^^^^^
  File "/home/dfx_17/Projects/Slovo/schedule/backend/.venv/lib/python3.13/site-packages/anyio/streams/memory.py", line 126, in receive
    raise EndOfStream from None
anyio.EndOfStream

During handling of the above exception, another exception occurred:

Traceback (most recent call last):
  File "/home/dfx_17/Projects/Slovo/schedule/backend/src/middleware.py", line 32, in dispatch
    return await call_next(request)
           ^^^^^^^^^^^^^^^^^^^^^^^^
  File "/home/dfx_17/Projects/Slovo/schedule/backend/.venv/lib/python3.13/site-packages/starlette/middleware/base.py", line 156, in call_next
    raise app_exc
  File "/home/dfx_17/Projects/Slovo/schedule/backend/.venv/lib/python3.13/site-packages/starlette/middleware/base.py", line 141, in coro
    await self.app(scope, receive_or_disconnect, send_no_error)
  File "/home/dfx_17/Projects/Slovo/schedule/backend/.venv/lib/python3.13/site-packages/starlette/middleware/cors.py", line 85, in __call__
    await self.app(scope, receive, send)
  File "/home/dfx_17/Projects/Slovo/schedule/backend/.venv/lib/python3.13/site-packages/starlette/middleware/exceptions.py", line 62, in __call__
    await wrap_app_handling_exceptions(self.app, conn)(scope, receive, send)
  File "/home/dfx_17/Projects/Slovo/schedule/backend/.venv/lib/python3.13/site-packages/starlette/_exception_handler.py", line 53, in wrapped_app
    raise exc
  File "/home/dfx_17/Projects/Slovo/schedule/backend/.venv/lib/python3.13/site-packages/starlette/_exception_handler.py", line 42, in wrapped_app
    await app(scope, receive, sender)
  File "/home/dfx_17/Projects/Slovo/schedule/backend/.venv/lib/python3.13/site-packages/starlette/routing.py", line 714, in __call__
    await self.middleware_stack(scope, receive, send)
  File "/home/dfx_17/Projects/Slovo/schedule/backend/.venv/lib/python3.13/site-packages/starlette/routing.py", line 734, in app
    await route.handle(scope, receive, send)
  File "/home/dfx_17/Projects/Slovo/schedule/backend/.venv/lib/python3.13/site-packages/starlette/routing.py", line 288, in handle
    await self.app(scope, receive, send)
  File "/home/dfx_17/Projects/Slovo/schedule/backend/.venv/lib/python3.13/site-packages/starlette/routing.py", line 76, in app
    await wrap_app_handling_exceptions(app, request)(scope, receive, send)
  File "/home/dfx_17/Projects/Slovo/schedule/backend/.venv/lib/python3.13/site-packages/starlette/_exception_handler.py", line 53, in wrapped_app
    raise exc
  File "/home/dfx_17/Projects/Slovo/schedule/backend/.venv/lib/python3.13/site-packages/starlette/_exception_handler.py", line 42, in wrapped_app
    await app(scope, receive, sender)
  File "/home/dfx_17/Projects/Slovo/schedule/backend/.venv/lib/python3.13/site-packages/starlette/routing.py", line 73, in app
    response = await f(request)
               ^^^^^^^^^^^^^^^^
  File "/home/dfx_17/Projects/Slovo/schedule/backend/.venv/lib/python3.13/site-packages/fastapi/routing.py", line 301, in app
    raw_response = await run_endpoint_function(
                   ^^^^^^^^^^^^^^^^^^^^^^^^^^^^
    ...<3 lines>...
    )
    ^
  File "/home/dfx_17/Projects/Slovo/schedule/backend/.venv/lib/python3.13/site-packages/fastapi/routing.py", line 212, in run_endpoint_function
    return await dependant.call(**values)
           ^^^^^^^^^^^^^^^^^^^^^^^^^^^^^^
  File "/home/dfx_17/Projects/Slovo/schedule/backend/src/api/appointment.py", line 27, in get_appointment
    data = await BitrixClient.get_crm_item(aety, id)
           ^^^^^^^^^^^^^^^^^^^^^^^^^^^^^^^^^^^^^^^^^
  File "/home/dfx_17/Projects/Slovo/schedule/backend/src/core/bitrix.py", line 32, in get_crm_item
    return await BITRIX.call("crm.item.get", items)
           ^^^^^^^^^^^^^^^^^^^^^^^^^^^^^^^^^^^^^^^^
  File "/home/dfx_17/Projects/Slovo/schedule/backend/.venv/lib/python3.13/site-packages/fast_bitrix24/logger.py", line 19, in wrapper
    return await func(*args, **kwargs)
           ^^^^^^^^^^^^^^^^^^^^^^^^^^^
  File "/home/dfx_17/Projects/Slovo/schedule/backend/.venv/lib/python3.13/site-packages/fast_bitrix24/bitrix.py", line 201, in call
    return await self.srh.run_async(request_cls(self, method, items).run())
           ^^^^^^^^^^^^^^^^^^^^^^^^^^^^^^^^^^^^^^^^^^^^^^^^^^^^^^^^^^^^^^^^
  File "/home/dfx_17/Projects/Slovo/schedule/backend/.venv/lib/python3.13/site-packages/fast_bitrix24/srh.py", line 129, in run_async
    return await coroutine
           ^^^^^^^^^^^^^^^
  File "/home/dfx_17/Projects/Slovo/schedule/backend/.venv/lib/python3.13/site-packages/fast_bitrix24/user_request.py", line 330, in run
    raw_results = await MultipleServerRequestHandlerPreserveIDs(
                  ^^^^^^^^^^^^^^^^^^^^^^^^^^^^^^^^^^^^^^^^^^^^^^
    ...<5 lines>...
    ).run()
    ^^^^^^^
  File "/home/dfx_17/Projects/Slovo/schedule/backend/.venv/lib/python3.13/site-packages/fast_bitrix24/mult_request.py", line 67, in run
    extracted_len = self.process_done_tasks(done)
  File "/home/dfx_17/Projects/Slovo/schedule/backend/.venv/lib/python3.13/site-packages/fast_bitrix24/mult_request.py", line 97, in process_done_tasks
    ).extract_results()
      ~~~~~~~~~~~~~~~^^
  File "/home/dfx_17/Projects/Slovo/schedule/backend/.venv/lib/python3.13/site-packages/fast_bitrix24/server_response.py", line 45, in extract_results
    self.raise_for_errors()
    ~~~~~~~~~~~~~~~~~~~~~^^
  File "/home/dfx_17/Projects/Slovo/schedule/backend/.venv/lib/python3.13/site-packages/fast_bitrix24/server_response.py", line 64, in raise_for_errors
    raise ErrorInServerResponseException(errors)
fast_bitrix24.server_response.ErrorInServerResponseException: {'order0000000000': {'error': 'NOT_FOUND', 'error_description': 'Элемент не найден'}}

2025-06-07 08:21:42.414 | CRITICAL | /home/dfx_17/Projects/Slovo/schedule/backend/.venv/lib/python3.13/site-packages/starlette/applications.py:112 (__call__)
Traceback (most recent call last):
  File "/home/dfx_17/Projects/Slovo/schedule/backend/.venv/lib/python3.13/site-packages/starlette/middleware/base.py", line 148, in call_next
    message = await recv_stream.receive()
              ^^^^^^^^^^^^^^^^^^^^^^^^^^^
  File "/home/dfx_17/Projects/Slovo/schedule/backend/.venv/lib/python3.13/site-packages/anyio/streams/memory.py", line 126, in receive
    raise EndOfStream from None
anyio.EndOfStream

During handling of the above exception, another exception occurred:

Traceback (most recent call last):
  File "/home/dfx_17/Projects/Slovo/schedule/backend/src/middleware.py", line 32, in dispatch
    return await call_next(request)
           ^^^^^^^^^^^^^^^^^^^^^^^^
  File "/home/dfx_17/Projects/Slovo/schedule/backend/.venv/lib/python3.13/site-packages/starlette/middleware/base.py", line 156, in call_next
    raise app_exc
  File "/home/dfx_17/Projects/Slovo/schedule/backend/.venv/lib/python3.13/site-packages/starlette/middleware/base.py", line 141, in coro
    await self.app(scope, receive_or_disconnect, send_no_error)
  File "/home/dfx_17/Projects/Slovo/schedule/backend/.venv/lib/python3.13/site-packages/starlette/middleware/cors.py", line 85, in __call__
    await self.app(scope, receive, send)
  File "/home/dfx_17/Projects/Slovo/schedule/backend/.venv/lib/python3.13/site-packages/starlette/middleware/exceptions.py", line 62, in __call__
    await wrap_app_handling_exceptions(self.app, conn)(scope, receive, send)
  File "/home/dfx_17/Projects/Slovo/schedule/backend/.venv/lib/python3.13/site-packages/starlette/_exception_handler.py", line 53, in wrapped_app
    raise exc
  File "/home/dfx_17/Projects/Slovo/schedule/backend/.venv/lib/python3.13/site-packages/starlette/_exception_handler.py", line 42, in wrapped_app
    await app(scope, receive, sender)
  File "/home/dfx_17/Projects/Slovo/schedule/backend/.venv/lib/python3.13/site-packages/starlette/routing.py", line 714, in __call__
    await self.middleware_stack(scope, receive, send)
  File "/home/dfx_17/Projects/Slovo/schedule/backend/.venv/lib/python3.13/site-packages/starlette/routing.py", line 734, in app
    await route.handle(scope, receive, send)
  File "/home/dfx_17/Projects/Slovo/schedule/backend/.venv/lib/python3.13/site-packages/starlette/routing.py", line 288, in handle
    await self.app(scope, receive, send)
  File "/home/dfx_17/Projects/Slovo/schedule/backend/.venv/lib/python3.13/site-packages/starlette/routing.py", line 76, in app
    await wrap_app_handling_exceptions(app, request)(scope, receive, send)
  File "/home/dfx_17/Projects/Slovo/schedule/backend/.venv/lib/python3.13/site-packages/starlette/_exception_handler.py", line 53, in wrapped_app
    raise exc
  File "/home/dfx_17/Projects/Slovo/schedule/backend/.venv/lib/python3.13/site-packages/starlette/_exception_handler.py", line 42, in wrapped_app
    await app(scope, receive, sender)
  File "/home/dfx_17/Projects/Slovo/schedule/backend/.venv/lib/python3.13/site-packages/starlette/routing.py", line 73, in app
    response = await f(request)
               ^^^^^^^^^^^^^^^^
  File "/home/dfx_17/Projects/Slovo/schedule/backend/.venv/lib/python3.13/site-packages/fastapi/routing.py", line 301, in app
    raw_response = await run_endpoint_function(
                   ^^^^^^^^^^^^^^^^^^^^^^^^^^^^
    ...<3 lines>...
    )
    ^
  File "/home/dfx_17/Projects/Slovo/schedule/backend/.venv/lib/python3.13/site-packages/fastapi/routing.py", line 212, in run_endpoint_function
    return await dependant.call(**values)
           ^^^^^^^^^^^^^^^^^^^^^^^^^^^^^^
  File "/home/dfx_17/Projects/Slovo/schedule/backend/src/api/appointment.py", line 40, in update_appointment
    updated_data = await BitrixClient.update_crm_item(aety, id, fields)
                   ^^^^^^^^^^^^^^^^^^^^^^^^^^^^^^^^^^^^^^^^^^^^^^^^^^^^
  File "/home/dfx_17/Projects/Slovo/schedule/backend/src/core/bitrix.py", line 37, in update_crm_item
    return await BITRIX.call('crm.item.update', items)
           ^^^^^^^^^^^^^^^^^^^^^^^^^^^^^^^^^^^^^^^^^^^
  File "/home/dfx_17/Projects/Slovo/schedule/backend/.venv/lib/python3.13/site-packages/fast_bitrix24/logger.py", line 19, in wrapper
    return await func(*args, **kwargs)
           ^^^^^^^^^^^^^^^^^^^^^^^^^^^
  File "/home/dfx_17/Projects/Slovo/schedule/backend/.venv/lib/python3.13/site-packages/fast_bitrix24/bitrix.py", line 201, in call
    return await self.srh.run_async(request_cls(self, method, items).run())
           ^^^^^^^^^^^^^^^^^^^^^^^^^^^^^^^^^^^^^^^^^^^^^^^^^^^^^^^^^^^^^^^^
  File "/home/dfx_17/Projects/Slovo/schedule/backend/.venv/lib/python3.13/site-packages/fast_bitrix24/srh.py", line 129, in run_async
    return await coroutine
           ^^^^^^^^^^^^^^^
  File "/home/dfx_17/Projects/Slovo/schedule/backend/.venv/lib/python3.13/site-packages/fast_bitrix24/user_request.py", line 330, in run
    raw_results = await MultipleServerRequestHandlerPreserveIDs(
                  ^^^^^^^^^^^^^^^^^^^^^^^^^^^^^^^^^^^^^^^^^^^^^^
    ...<5 lines>...
    ).run()
    ^^^^^^^
  File "/home/dfx_17/Projects/Slovo/schedule/backend/.venv/lib/python3.13/site-packages/fast_bitrix24/mult_request.py", line 67, in run
    extracted_len = self.process_done_tasks(done)
  File "/home/dfx_17/Projects/Slovo/schedule/backend/.venv/lib/python3.13/site-packages/fast_bitrix24/mult_request.py", line 97, in process_done_tasks
    ).extract_results()
      ~~~~~~~~~~~~~~~^^
  File "/home/dfx_17/Projects/Slovo/schedule/backend/.venv/lib/python3.13/site-packages/fast_bitrix24/server_response.py", line 45, in extract_results
    self.raise_for_errors()
    ~~~~~~~~~~~~~~~~~~~~~^^
  File "/home/dfx_17/Projects/Slovo/schedule/backend/.venv/lib/python3.13/site-packages/fast_bitrix24/server_response.py", line 64, in raise_for_errors
    raise ErrorInServerResponseException(errors)
fast_bitrix24.server_response.ErrorInServerResponseException: {'order0000000000': {'error': 'NOT_FOUND', 'error_description': 'Элемент не найден'}}

2025-06-07 08:32:12.734 | CRITICAL | /home/dfx_17/Projects/Slovo/schedule/backend/.venv/lib/python3.13/site-packages/starlette/applications.py:112 (__call__)
Traceback (most recent call last):
  File "/home/dfx_17/Projects/Slovo/schedule/backend/.venv/lib/python3.13/site-packages/starlette/middleware/base.py", line 148, in call_next
    message = await recv_stream.receive()
              ^^^^^^^^^^^^^^^^^^^^^^^^^^^
  File "/home/dfx_17/Projects/Slovo/schedule/backend/.venv/lib/python3.13/site-packages/anyio/streams/memory.py", line 126, in receive
    raise EndOfStream from None
anyio.EndOfStream

During handling of the above exception, another exception occurred:

Traceback (most recent call last):
  File "/home/dfx_17/Projects/Slovo/schedule/backend/src/middleware.py", line 32, in dispatch
    return await call_next(request)
           ^^^^^^^^^^^^^^^^^^^^^^^^
  File "/home/dfx_17/Projects/Slovo/schedule/backend/.venv/lib/python3.13/site-packages/starlette/middleware/base.py", line 156, in call_next
    raise app_exc
  File "/home/dfx_17/Projects/Slovo/schedule/backend/.venv/lib/python3.13/site-packages/starlette/middleware/base.py", line 141, in coro
    await self.app(scope, receive_or_disconnect, send_no_error)
  File "/home/dfx_17/Projects/Slovo/schedule/backend/.venv/lib/python3.13/site-packages/starlette/middleware/cors.py", line 85, in __call__
    await self.app(scope, receive, send)
  File "/home/dfx_17/Projects/Slovo/schedule/backend/.venv/lib/python3.13/site-packages/starlette/middleware/exceptions.py", line 62, in __call__
    await wrap_app_handling_exceptions(self.app, conn)(scope, receive, send)
  File "/home/dfx_17/Projects/Slovo/schedule/backend/.venv/lib/python3.13/site-packages/starlette/_exception_handler.py", line 53, in wrapped_app
    raise exc
  File "/home/dfx_17/Projects/Slovo/schedule/backend/.venv/lib/python3.13/site-packages/starlette/_exception_handler.py", line 42, in wrapped_app
    await app(scope, receive, sender)
  File "/home/dfx_17/Projects/Slovo/schedule/backend/.venv/lib/python3.13/site-packages/starlette/routing.py", line 714, in __call__
    await self.middleware_stack(scope, receive, send)
  File "/home/dfx_17/Projects/Slovo/schedule/backend/.venv/lib/python3.13/site-packages/starlette/routing.py", line 734, in app
    await route.handle(scope, receive, send)
  File "/home/dfx_17/Projects/Slovo/schedule/backend/.venv/lib/python3.13/site-packages/starlette/routing.py", line 288, in handle
    await self.app(scope, receive, send)
  File "/home/dfx_17/Projects/Slovo/schedule/backend/.venv/lib/python3.13/site-packages/starlette/routing.py", line 76, in app
    await wrap_app_handling_exceptions(app, request)(scope, receive, send)
  File "/home/dfx_17/Projects/Slovo/schedule/backend/.venv/lib/python3.13/site-packages/starlette/_exception_handler.py", line 53, in wrapped_app
    raise exc
  File "/home/dfx_17/Projects/Slovo/schedule/backend/.venv/lib/python3.13/site-packages/starlette/_exception_handler.py", line 42, in wrapped_app
    await app(scope, receive, sender)
  File "/home/dfx_17/Projects/Slovo/schedule/backend/.venv/lib/python3.13/site-packages/starlette/routing.py", line 73, in app
    response = await f(request)
               ^^^^^^^^^^^^^^^^
  File "/home/dfx_17/Projects/Slovo/schedule/backend/.venv/lib/python3.13/site-packages/fastapi/routing.py", line 301, in app
    raw_response = await run_endpoint_function(
                   ^^^^^^^^^^^^^^^^^^^^^^^^^^^^
    ...<3 lines>...
    )
    ^
  File "/home/dfx_17/Projects/Slovo/schedule/backend/.venv/lib/python3.13/site-packages/fastapi/routing.py", line 212, in run_endpoint_function
    return await dependant.call(**values)
           ^^^^^^^^^^^^^^^^^^^^^^^^^^^^^^
  File "/home/dfx_17/Projects/Slovo/schedule/backend/src/api/appointment.py", line 27, in get_appointment
    data = await BitrixClient.get_crm_item(aety, id)
           ^^^^^^^^^^^^^^^^^^^^^^^^^^^^^^^^^^^^^^^^^
  File "/home/dfx_17/Projects/Slovo/schedule/backend/src/core/bitrix.py", line 32, in get_crm_item
    return await BITRIX.call("crm.item.get", items)
           ^^^^^^^^^^^^^^^^^^^^^^^^^^^^^^^^^^^^^^^^
  File "/home/dfx_17/Projects/Slovo/schedule/backend/.venv/lib/python3.13/site-packages/fast_bitrix24/logger.py", line 19, in wrapper
    return await func(*args, **kwargs)
           ^^^^^^^^^^^^^^^^^^^^^^^^^^^
  File "/home/dfx_17/Projects/Slovo/schedule/backend/.venv/lib/python3.13/site-packages/fast_bitrix24/bitrix.py", line 201, in call
    return await self.srh.run_async(request_cls(self, method, items).run())
           ^^^^^^^^^^^^^^^^^^^^^^^^^^^^^^^^^^^^^^^^^^^^^^^^^^^^^^^^^^^^^^^^
  File "/home/dfx_17/Projects/Slovo/schedule/backend/.venv/lib/python3.13/site-packages/fast_bitrix24/srh.py", line 129, in run_async
    return await coroutine
           ^^^^^^^^^^^^^^^
  File "/home/dfx_17/Projects/Slovo/schedule/backend/.venv/lib/python3.13/site-packages/fast_bitrix24/user_request.py", line 330, in run
    raw_results = await MultipleServerRequestHandlerPreserveIDs(
                  ^^^^^^^^^^^^^^^^^^^^^^^^^^^^^^^^^^^^^^^^^^^^^^
    ...<5 lines>...
    ).run()
    ^^^^^^^
  File "/home/dfx_17/Projects/Slovo/schedule/backend/.venv/lib/python3.13/site-packages/fast_bitrix24/mult_request.py", line 67, in run
    extracted_len = self.process_done_tasks(done)
  File "/home/dfx_17/Projects/Slovo/schedule/backend/.venv/lib/python3.13/site-packages/fast_bitrix24/mult_request.py", line 97, in process_done_tasks
    ).extract_results()
      ~~~~~~~~~~~~~~~^^
  File "/home/dfx_17/Projects/Slovo/schedule/backend/.venv/lib/python3.13/site-packages/fast_bitrix24/server_response.py", line 45, in extract_results
    self.raise_for_errors()
    ~~~~~~~~~~~~~~~~~~~~~^^
  File "/home/dfx_17/Projects/Slovo/schedule/backend/.venv/lib/python3.13/site-packages/fast_bitrix24/server_response.py", line 64, in raise_for_errors
    raise ErrorInServerResponseException(errors)
fast_bitrix24.server_response.ErrorInServerResponseException: {'order0000000000': {'error': 'NOT_FOUND', 'error_description': 'Элемент не найден'}}

2025-06-07 08:32:13.516 | CRITICAL | /home/dfx_17/Projects/Slovo/schedule/backend/.venv/lib/python3.13/site-packages/starlette/applications.py:112 (__call__)
Traceback (most recent call last):
  File "/home/dfx_17/Projects/Slovo/schedule/backend/.venv/lib/python3.13/site-packages/starlette/middleware/base.py", line 148, in call_next
    message = await recv_stream.receive()
              ^^^^^^^^^^^^^^^^^^^^^^^^^^^
  File "/home/dfx_17/Projects/Slovo/schedule/backend/.venv/lib/python3.13/site-packages/anyio/streams/memory.py", line 126, in receive
    raise EndOfStream from None
anyio.EndOfStream

During handling of the above exception, another exception occurred:

Traceback (most recent call last):
  File "/home/dfx_17/Projects/Slovo/schedule/backend/src/middleware.py", line 32, in dispatch
    return await call_next(request)
           ^^^^^^^^^^^^^^^^^^^^^^^^
  File "/home/dfx_17/Projects/Slovo/schedule/backend/.venv/lib/python3.13/site-packages/starlette/middleware/base.py", line 156, in call_next
    raise app_exc
  File "/home/dfx_17/Projects/Slovo/schedule/backend/.venv/lib/python3.13/site-packages/starlette/middleware/base.py", line 141, in coro
    await self.app(scope, receive_or_disconnect, send_no_error)
  File "/home/dfx_17/Projects/Slovo/schedule/backend/.venv/lib/python3.13/site-packages/starlette/middleware/cors.py", line 85, in __call__
    await self.app(scope, receive, send)
  File "/home/dfx_17/Projects/Slovo/schedule/backend/.venv/lib/python3.13/site-packages/starlette/middleware/exceptions.py", line 62, in __call__
    await wrap_app_handling_exceptions(self.app, conn)(scope, receive, send)
  File "/home/dfx_17/Projects/Slovo/schedule/backend/.venv/lib/python3.13/site-packages/starlette/_exception_handler.py", line 53, in wrapped_app
    raise exc
  File "/home/dfx_17/Projects/Slovo/schedule/backend/.venv/lib/python3.13/site-packages/starlette/_exception_handler.py", line 42, in wrapped_app
    await app(scope, receive, sender)
  File "/home/dfx_17/Projects/Slovo/schedule/backend/.venv/lib/python3.13/site-packages/starlette/routing.py", line 714, in __call__
    await self.middleware_stack(scope, receive, send)
  File "/home/dfx_17/Projects/Slovo/schedule/backend/.venv/lib/python3.13/site-packages/starlette/routing.py", line 734, in app
    await route.handle(scope, receive, send)
  File "/home/dfx_17/Projects/Slovo/schedule/backend/.venv/lib/python3.13/site-packages/starlette/routing.py", line 288, in handle
    await self.app(scope, receive, send)
  File "/home/dfx_17/Projects/Slovo/schedule/backend/.venv/lib/python3.13/site-packages/starlette/routing.py", line 76, in app
    await wrap_app_handling_exceptions(app, request)(scope, receive, send)
  File "/home/dfx_17/Projects/Slovo/schedule/backend/.venv/lib/python3.13/site-packages/starlette/_exception_handler.py", line 53, in wrapped_app
    raise exc
  File "/home/dfx_17/Projects/Slovo/schedule/backend/.venv/lib/python3.13/site-packages/starlette/_exception_handler.py", line 42, in wrapped_app
    await app(scope, receive, sender)
  File "/home/dfx_17/Projects/Slovo/schedule/backend/.venv/lib/python3.13/site-packages/starlette/routing.py", line 73, in app
    response = await f(request)
               ^^^^^^^^^^^^^^^^
  File "/home/dfx_17/Projects/Slovo/schedule/backend/.venv/lib/python3.13/site-packages/fastapi/routing.py", line 301, in app
    raw_response = await run_endpoint_function(
                   ^^^^^^^^^^^^^^^^^^^^^^^^^^^^
    ...<3 lines>...
    )
    ^
  File "/home/dfx_17/Projects/Slovo/schedule/backend/.venv/lib/python3.13/site-packages/fastapi/routing.py", line 212, in run_endpoint_function
    return await dependant.call(**values)
           ^^^^^^^^^^^^^^^^^^^^^^^^^^^^^^
  File "/home/dfx_17/Projects/Slovo/schedule/backend/src/api/appointment.py", line 40, in update_appointment
    updated_data = await BitrixClient.update_crm_item(aety, id, fields)
                   ^^^^^^^^^^^^^^^^^^^^^^^^^^^^^^^^^^^^^^^^^^^^^^^^^^^^
  File "/home/dfx_17/Projects/Slovo/schedule/backend/src/core/bitrix.py", line 37, in update_crm_item
    return await BITRIX.call('crm.item.update', items)
           ^^^^^^^^^^^^^^^^^^^^^^^^^^^^^^^^^^^^^^^^^^^
  File "/home/dfx_17/Projects/Slovo/schedule/backend/.venv/lib/python3.13/site-packages/fast_bitrix24/logger.py", line 19, in wrapper
    return await func(*args, **kwargs)
           ^^^^^^^^^^^^^^^^^^^^^^^^^^^
  File "/home/dfx_17/Projects/Slovo/schedule/backend/.venv/lib/python3.13/site-packages/fast_bitrix24/bitrix.py", line 201, in call
    return await self.srh.run_async(request_cls(self, method, items).run())
           ^^^^^^^^^^^^^^^^^^^^^^^^^^^^^^^^^^^^^^^^^^^^^^^^^^^^^^^^^^^^^^^^
  File "/home/dfx_17/Projects/Slovo/schedule/backend/.venv/lib/python3.13/site-packages/fast_bitrix24/srh.py", line 129, in run_async
    return await coroutine
           ^^^^^^^^^^^^^^^
  File "/home/dfx_17/Projects/Slovo/schedule/backend/.venv/lib/python3.13/site-packages/fast_bitrix24/user_request.py", line 330, in run
    raw_results = await MultipleServerRequestHandlerPreserveIDs(
                  ^^^^^^^^^^^^^^^^^^^^^^^^^^^^^^^^^^^^^^^^^^^^^^
    ...<5 lines>...
    ).run()
    ^^^^^^^
  File "/home/dfx_17/Projects/Slovo/schedule/backend/.venv/lib/python3.13/site-packages/fast_bitrix24/mult_request.py", line 67, in run
    extracted_len = self.process_done_tasks(done)
  File "/home/dfx_17/Projects/Slovo/schedule/backend/.venv/lib/python3.13/site-packages/fast_bitrix24/mult_request.py", line 97, in process_done_tasks
    ).extract_results()
      ~~~~~~~~~~~~~~~^^
  File "/home/dfx_17/Projects/Slovo/schedule/backend/.venv/lib/python3.13/site-packages/fast_bitrix24/server_response.py", line 45, in extract_results
    self.raise_for_errors()
    ~~~~~~~~~~~~~~~~~~~~~^^
  File "/home/dfx_17/Projects/Slovo/schedule/backend/.venv/lib/python3.13/site-packages/fast_bitrix24/server_response.py", line 64, in raise_for_errors
    raise ErrorInServerResponseException(errors)
fast_bitrix24.server_response.ErrorInServerResponseException: {'order0000000000': {'error': 'NOT_FOUND', 'error_description': 'Элемент не найден'}}

2025-06-07 08:33:01.338 | CRITICAL | /home/dfx_17/Projects/Slovo/schedule/backend/.venv/lib/python3.13/site-packages/starlette/applications.py:112 (__call__)
Traceback (most recent call last):
  File "/home/dfx_17/Projects/Slovo/schedule/backend/.venv/lib/python3.13/site-packages/starlette/middleware/base.py", line 148, in call_next
    message = await recv_stream.receive()
              ^^^^^^^^^^^^^^^^^^^^^^^^^^^
  File "/home/dfx_17/Projects/Slovo/schedule/backend/.venv/lib/python3.13/site-packages/anyio/streams/memory.py", line 126, in receive
    raise EndOfStream from None
anyio.EndOfStream

During handling of the above exception, another exception occurred:

Traceback (most recent call last):
  File "/home/dfx_17/Projects/Slovo/schedule/backend/src/middleware.py", line 32, in dispatch
    return await call_next(request)
           ^^^^^^^^^^^^^^^^^^^^^^^^
  File "/home/dfx_17/Projects/Slovo/schedule/backend/.venv/lib/python3.13/site-packages/starlette/middleware/base.py", line 156, in call_next
    raise app_exc
  File "/home/dfx_17/Projects/Slovo/schedule/backend/.venv/lib/python3.13/site-packages/starlette/middleware/base.py", line 141, in coro
    await self.app(scope, receive_or_disconnect, send_no_error)
  File "/home/dfx_17/Projects/Slovo/schedule/backend/.venv/lib/python3.13/site-packages/starlette/middleware/cors.py", line 85, in __call__
    await self.app(scope, receive, send)
  File "/home/dfx_17/Projects/Slovo/schedule/backend/.venv/lib/python3.13/site-packages/starlette/middleware/exceptions.py", line 62, in __call__
    await wrap_app_handling_exceptions(self.app, conn)(scope, receive, send)
  File "/home/dfx_17/Projects/Slovo/schedule/backend/.venv/lib/python3.13/site-packages/starlette/_exception_handler.py", line 53, in wrapped_app
    raise exc
  File "/home/dfx_17/Projects/Slovo/schedule/backend/.venv/lib/python3.13/site-packages/starlette/_exception_handler.py", line 42, in wrapped_app
    await app(scope, receive, sender)
  File "/home/dfx_17/Projects/Slovo/schedule/backend/.venv/lib/python3.13/site-packages/starlette/routing.py", line 714, in __call__
    await self.middleware_stack(scope, receive, send)
  File "/home/dfx_17/Projects/Slovo/schedule/backend/.venv/lib/python3.13/site-packages/starlette/routing.py", line 734, in app
    await route.handle(scope, receive, send)
  File "/home/dfx_17/Projects/Slovo/schedule/backend/.venv/lib/python3.13/site-packages/starlette/routing.py", line 288, in handle
    await self.app(scope, receive, send)
  File "/home/dfx_17/Projects/Slovo/schedule/backend/.venv/lib/python3.13/site-packages/starlette/routing.py", line 76, in app
    await wrap_app_handling_exceptions(app, request)(scope, receive, send)
  File "/home/dfx_17/Projects/Slovo/schedule/backend/.venv/lib/python3.13/site-packages/starlette/_exception_handler.py", line 53, in wrapped_app
    raise exc
  File "/home/dfx_17/Projects/Slovo/schedule/backend/.venv/lib/python3.13/site-packages/starlette/_exception_handler.py", line 42, in wrapped_app
    await app(scope, receive, sender)
  File "/home/dfx_17/Projects/Slovo/schedule/backend/.venv/lib/python3.13/site-packages/starlette/routing.py", line 73, in app
    response = await f(request)
               ^^^^^^^^^^^^^^^^
  File "/home/dfx_17/Projects/Slovo/schedule/backend/.venv/lib/python3.13/site-packages/fastapi/routing.py", line 301, in app
    raw_response = await run_endpoint_function(
                   ^^^^^^^^^^^^^^^^^^^^^^^^^^^^
    ...<3 lines>...
    )
    ^
  File "/home/dfx_17/Projects/Slovo/schedule/backend/.venv/lib/python3.13/site-packages/fastapi/routing.py", line 212, in run_endpoint_function
    return await dependant.call(**values)
           ^^^^^^^^^^^^^^^^^^^^^^^^^^^^^^
  File "/home/dfx_17/Projects/Slovo/schedule/backend/src/api/appointment.py", line 27, in get_appointment
    data = await BitrixClient.get_crm_item(aety, id)
           ^^^^^^^^^^^^^^^^^^^^^^^^^^^^^^^^^^^^^^^^^
  File "/home/dfx_17/Projects/Slovo/schedule/backend/src/core/bitrix.py", line 32, in get_crm_item
    return await BITRIX.call("crm.item.get", items)
           ^^^^^^^^^^^^^^^^^^^^^^^^^^^^^^^^^^^^^^^^
  File "/home/dfx_17/Projects/Slovo/schedule/backend/.venv/lib/python3.13/site-packages/fast_bitrix24/logger.py", line 19, in wrapper
    return await func(*args, **kwargs)
           ^^^^^^^^^^^^^^^^^^^^^^^^^^^
  File "/home/dfx_17/Projects/Slovo/schedule/backend/.venv/lib/python3.13/site-packages/fast_bitrix24/bitrix.py", line 201, in call
    return await self.srh.run_async(request_cls(self, method, items).run())
           ^^^^^^^^^^^^^^^^^^^^^^^^^^^^^^^^^^^^^^^^^^^^^^^^^^^^^^^^^^^^^^^^
  File "/home/dfx_17/Projects/Slovo/schedule/backend/.venv/lib/python3.13/site-packages/fast_bitrix24/srh.py", line 129, in run_async
    return await coroutine
           ^^^^^^^^^^^^^^^
  File "/home/dfx_17/Projects/Slovo/schedule/backend/.venv/lib/python3.13/site-packages/fast_bitrix24/user_request.py", line 330, in run
    raw_results = await MultipleServerRequestHandlerPreserveIDs(
                  ^^^^^^^^^^^^^^^^^^^^^^^^^^^^^^^^^^^^^^^^^^^^^^
    ...<5 lines>...
    ).run()
    ^^^^^^^
  File "/home/dfx_17/Projects/Slovo/schedule/backend/.venv/lib/python3.13/site-packages/fast_bitrix24/mult_request.py", line 67, in run
    extracted_len = self.process_done_tasks(done)
  File "/home/dfx_17/Projects/Slovo/schedule/backend/.venv/lib/python3.13/site-packages/fast_bitrix24/mult_request.py", line 97, in process_done_tasks
    ).extract_results()
      ~~~~~~~~~~~~~~~^^
  File "/home/dfx_17/Projects/Slovo/schedule/backend/.venv/lib/python3.13/site-packages/fast_bitrix24/server_response.py", line 45, in extract_results
    self.raise_for_errors()
    ~~~~~~~~~~~~~~~~~~~~~^^
  File "/home/dfx_17/Projects/Slovo/schedule/backend/.venv/lib/python3.13/site-packages/fast_bitrix24/server_response.py", line 64, in raise_for_errors
    raise ErrorInServerResponseException(errors)
fast_bitrix24.server_response.ErrorInServerResponseException: {'order0000000000': {'error': 'NOT_FOUND', 'error_description': 'Элемент не найден'}}

2025-06-07 08:33:02.052 | CRITICAL | /home/dfx_17/Projects/Slovo/schedule/backend/.venv/lib/python3.13/site-packages/starlette/applications.py:112 (__call__)
Traceback (most recent call last):
  File "/home/dfx_17/Projects/Slovo/schedule/backend/.venv/lib/python3.13/site-packages/starlette/middleware/base.py", line 148, in call_next
    message = await recv_stream.receive()
              ^^^^^^^^^^^^^^^^^^^^^^^^^^^
  File "/home/dfx_17/Projects/Slovo/schedule/backend/.venv/lib/python3.13/site-packages/anyio/streams/memory.py", line 126, in receive
    raise EndOfStream from None
anyio.EndOfStream

During handling of the above exception, another exception occurred:

Traceback (most recent call last):
  File "/home/dfx_17/Projects/Slovo/schedule/backend/src/middleware.py", line 32, in dispatch
    return await call_next(request)
           ^^^^^^^^^^^^^^^^^^^^^^^^
  File "/home/dfx_17/Projects/Slovo/schedule/backend/.venv/lib/python3.13/site-packages/starlette/middleware/base.py", line 156, in call_next
    raise app_exc
  File "/home/dfx_17/Projects/Slovo/schedule/backend/.venv/lib/python3.13/site-packages/starlette/middleware/base.py", line 141, in coro
    await self.app(scope, receive_or_disconnect, send_no_error)
  File "/home/dfx_17/Projects/Slovo/schedule/backend/.venv/lib/python3.13/site-packages/starlette/middleware/cors.py", line 85, in __call__
    await self.app(scope, receive, send)
  File "/home/dfx_17/Projects/Slovo/schedule/backend/.venv/lib/python3.13/site-packages/starlette/middleware/exceptions.py", line 62, in __call__
    await wrap_app_handling_exceptions(self.app, conn)(scope, receive, send)
  File "/home/dfx_17/Projects/Slovo/schedule/backend/.venv/lib/python3.13/site-packages/starlette/_exception_handler.py", line 53, in wrapped_app
    raise exc
  File "/home/dfx_17/Projects/Slovo/schedule/backend/.venv/lib/python3.13/site-packages/starlette/_exception_handler.py", line 42, in wrapped_app
    await app(scope, receive, sender)
  File "/home/dfx_17/Projects/Slovo/schedule/backend/.venv/lib/python3.13/site-packages/starlette/routing.py", line 714, in __call__
    await self.middleware_stack(scope, receive, send)
  File "/home/dfx_17/Projects/Slovo/schedule/backend/.venv/lib/python3.13/site-packages/starlette/routing.py", line 734, in app
    await route.handle(scope, receive, send)
  File "/home/dfx_17/Projects/Slovo/schedule/backend/.venv/lib/python3.13/site-packages/starlette/routing.py", line 288, in handle
    await self.app(scope, receive, send)
  File "/home/dfx_17/Projects/Slovo/schedule/backend/.venv/lib/python3.13/site-packages/starlette/routing.py", line 76, in app
    await wrap_app_handling_exceptions(app, request)(scope, receive, send)
  File "/home/dfx_17/Projects/Slovo/schedule/backend/.venv/lib/python3.13/site-packages/starlette/_exception_handler.py", line 53, in wrapped_app
    raise exc
  File "/home/dfx_17/Projects/Slovo/schedule/backend/.venv/lib/python3.13/site-packages/starlette/_exception_handler.py", line 42, in wrapped_app
    await app(scope, receive, sender)
  File "/home/dfx_17/Projects/Slovo/schedule/backend/.venv/lib/python3.13/site-packages/starlette/routing.py", line 73, in app
    response = await f(request)
               ^^^^^^^^^^^^^^^^
  File "/home/dfx_17/Projects/Slovo/schedule/backend/.venv/lib/python3.13/site-packages/fastapi/routing.py", line 301, in app
    raw_response = await run_endpoint_function(
                   ^^^^^^^^^^^^^^^^^^^^^^^^^^^^
    ...<3 lines>...
    )
    ^
  File "/home/dfx_17/Projects/Slovo/schedule/backend/.venv/lib/python3.13/site-packages/fastapi/routing.py", line 212, in run_endpoint_function
    return await dependant.call(**values)
           ^^^^^^^^^^^^^^^^^^^^^^^^^^^^^^
  File "/home/dfx_17/Projects/Slovo/schedule/backend/src/api/appointment.py", line 40, in update_appointment
    updated_data = await BitrixClient.update_crm_item(aety, id, fields)
                   ^^^^^^^^^^^^^^^^^^^^^^^^^^^^^^^^^^^^^^^^^^^^^^^^^^^^
  File "/home/dfx_17/Projects/Slovo/schedule/backend/src/core/bitrix.py", line 37, in update_crm_item
    return await BITRIX.call('crm.item.update', items)
           ^^^^^^^^^^^^^^^^^^^^^^^^^^^^^^^^^^^^^^^^^^^
  File "/home/dfx_17/Projects/Slovo/schedule/backend/.venv/lib/python3.13/site-packages/fast_bitrix24/logger.py", line 19, in wrapper
    return await func(*args, **kwargs)
           ^^^^^^^^^^^^^^^^^^^^^^^^^^^
  File "/home/dfx_17/Projects/Slovo/schedule/backend/.venv/lib/python3.13/site-packages/fast_bitrix24/bitrix.py", line 201, in call
    return await self.srh.run_async(request_cls(self, method, items).run())
           ^^^^^^^^^^^^^^^^^^^^^^^^^^^^^^^^^^^^^^^^^^^^^^^^^^^^^^^^^^^^^^^^
  File "/home/dfx_17/Projects/Slovo/schedule/backend/.venv/lib/python3.13/site-packages/fast_bitrix24/srh.py", line 129, in run_async
    return await coroutine
           ^^^^^^^^^^^^^^^
  File "/home/dfx_17/Projects/Slovo/schedule/backend/.venv/lib/python3.13/site-packages/fast_bitrix24/user_request.py", line 330, in run
    raw_results = await MultipleServerRequestHandlerPreserveIDs(
                  ^^^^^^^^^^^^^^^^^^^^^^^^^^^^^^^^^^^^^^^^^^^^^^
    ...<5 lines>...
    ).run()
    ^^^^^^^
  File "/home/dfx_17/Projects/Slovo/schedule/backend/.venv/lib/python3.13/site-packages/fast_bitrix24/mult_request.py", line 67, in run
    extracted_len = self.process_done_tasks(done)
  File "/home/dfx_17/Projects/Slovo/schedule/backend/.venv/lib/python3.13/site-packages/fast_bitrix24/mult_request.py", line 97, in process_done_tasks
    ).extract_results()
      ~~~~~~~~~~~~~~~^^
  File "/home/dfx_17/Projects/Slovo/schedule/backend/.venv/lib/python3.13/site-packages/fast_bitrix24/server_response.py", line 45, in extract_results
    self.raise_for_errors()
    ~~~~~~~~~~~~~~~~~~~~~^^
  File "/home/dfx_17/Projects/Slovo/schedule/backend/.venv/lib/python3.13/site-packages/fast_bitrix24/server_response.py", line 64, in raise_for_errors
    raise ErrorInServerResponseException(errors)
fast_bitrix24.server_response.ErrorInServerResponseException: {'order0000000000': {'error': 'NOT_FOUND', 'error_description': 'Элемент не найден'}}

2025-06-07 09:47:08.052 | CRITICAL | /home/dfx_17/Projects/Slovo/schedule/backend/.venv/lib/python3.13/site-packages/starlette/applications.py:112 (__call__)
Traceback (most recent call last):
  File "/home/dfx_17/Projects/Slovo/schedule/backend/.venv/lib/python3.13/site-packages/starlette/middleware/base.py", line 148, in call_next
    message = await recv_stream.receive()
              ^^^^^^^^^^^^^^^^^^^^^^^^^^^
  File "/home/dfx_17/Projects/Slovo/schedule/backend/.venv/lib/python3.13/site-packages/anyio/streams/memory.py", line 126, in receive
    raise EndOfStream from None
anyio.EndOfStream

During handling of the above exception, another exception occurred:

Traceback (most recent call last):
  File "/home/dfx_17/Projects/Slovo/schedule/backend/src/middleware.py", line 32, in dispatch
    return await call_next(request)
           ^^^^^^^^^^^^^^^^^^^^^^^^
  File "/home/dfx_17/Projects/Slovo/schedule/backend/.venv/lib/python3.13/site-packages/starlette/middleware/base.py", line 156, in call_next
    raise app_exc
  File "/home/dfx_17/Projects/Slovo/schedule/backend/.venv/lib/python3.13/site-packages/starlette/middleware/base.py", line 141, in coro
    await self.app(scope, receive_or_disconnect, send_no_error)
  File "/home/dfx_17/Projects/Slovo/schedule/backend/.venv/lib/python3.13/site-packages/starlette/middleware/cors.py", line 85, in __call__
    await self.app(scope, receive, send)
  File "/home/dfx_17/Projects/Slovo/schedule/backend/.venv/lib/python3.13/site-packages/starlette/middleware/exceptions.py", line 62, in __call__
    await wrap_app_handling_exceptions(self.app, conn)(scope, receive, send)
  File "/home/dfx_17/Projects/Slovo/schedule/backend/.venv/lib/python3.13/site-packages/starlette/_exception_handler.py", line 53, in wrapped_app
    raise exc
  File "/home/dfx_17/Projects/Slovo/schedule/backend/.venv/lib/python3.13/site-packages/starlette/_exception_handler.py", line 42, in wrapped_app
    await app(scope, receive, sender)
  File "/home/dfx_17/Projects/Slovo/schedule/backend/.venv/lib/python3.13/site-packages/starlette/routing.py", line 714, in __call__
    await self.middleware_stack(scope, receive, send)
  File "/home/dfx_17/Projects/Slovo/schedule/backend/.venv/lib/python3.13/site-packages/starlette/routing.py", line 734, in app
    await route.handle(scope, receive, send)
  File "/home/dfx_17/Projects/Slovo/schedule/backend/.venv/lib/python3.13/site-packages/starlette/routing.py", line 288, in handle
    await self.app(scope, receive, send)
  File "/home/dfx_17/Projects/Slovo/schedule/backend/.venv/lib/python3.13/site-packages/starlette/routing.py", line 76, in app
    await wrap_app_handling_exceptions(app, request)(scope, receive, send)
  File "/home/dfx_17/Projects/Slovo/schedule/backend/.venv/lib/python3.13/site-packages/starlette/_exception_handler.py", line 53, in wrapped_app
    raise exc
  File "/home/dfx_17/Projects/Slovo/schedule/backend/.venv/lib/python3.13/site-packages/starlette/_exception_handler.py", line 42, in wrapped_app
    await app(scope, receive, sender)
  File "/home/dfx_17/Projects/Slovo/schedule/backend/.venv/lib/python3.13/site-packages/starlette/routing.py", line 73, in app
    response = await f(request)
               ^^^^^^^^^^^^^^^^
  File "/home/dfx_17/Projects/Slovo/schedule/backend/.venv/lib/python3.13/site-packages/fastapi/routing.py", line 301, in app
    raw_response = await run_endpoint_function(
                   ^^^^^^^^^^^^^^^^^^^^^^^^^^^^
    ...<3 lines>...
    )
    ^
  File "/home/dfx_17/Projects/Slovo/schedule/backend/.venv/lib/python3.13/site-packages/fastapi/routing.py", line 212, in run_endpoint_function
    return await dependant.call(**values)
           ^^^^^^^^^^^^^^^^^^^^^^^^^^^^^^
  File "/home/dfx_17/Projects/Slovo/schedule/backend/src/api/appointment.py", line 27, in get_appointment
    data = await BitrixClient.get_crm_item(aety, id)
           ^^^^^^^^^^^^^^^^^^^^^^^^^^^^^^^^^^^^^^^^^
  File "/home/dfx_17/Projects/Slovo/schedule/backend/src/core/bitrix.py", line 32, in get_crm_item
    return await BITRIX.call("crm.item.get", items)
           ^^^^^^^^^^^^^^^^^^^^^^^^^^^^^^^^^^^^^^^^
  File "/home/dfx_17/Projects/Slovo/schedule/backend/.venv/lib/python3.13/site-packages/fast_bitrix24/logger.py", line 19, in wrapper
    return await func(*args, **kwargs)
           ^^^^^^^^^^^^^^^^^^^^^^^^^^^
  File "/home/dfx_17/Projects/Slovo/schedule/backend/.venv/lib/python3.13/site-packages/fast_bitrix24/bitrix.py", line 201, in call
    return await self.srh.run_async(request_cls(self, method, items).run())
           ^^^^^^^^^^^^^^^^^^^^^^^^^^^^^^^^^^^^^^^^^^^^^^^^^^^^^^^^^^^^^^^^
  File "/home/dfx_17/Projects/Slovo/schedule/backend/.venv/lib/python3.13/site-packages/fast_bitrix24/srh.py", line 129, in run_async
    return await coroutine
           ^^^^^^^^^^^^^^^
  File "/home/dfx_17/Projects/Slovo/schedule/backend/.venv/lib/python3.13/site-packages/fast_bitrix24/user_request.py", line 330, in run
    raw_results = await MultipleServerRequestHandlerPreserveIDs(
                  ^^^^^^^^^^^^^^^^^^^^^^^^^^^^^^^^^^^^^^^^^^^^^^
    ...<5 lines>...
    ).run()
    ^^^^^^^
  File "/home/dfx_17/Projects/Slovo/schedule/backend/.venv/lib/python3.13/site-packages/fast_bitrix24/mult_request.py", line 67, in run
    extracted_len = self.process_done_tasks(done)
  File "/home/dfx_17/Projects/Slovo/schedule/backend/.venv/lib/python3.13/site-packages/fast_bitrix24/mult_request.py", line 97, in process_done_tasks
    ).extract_results()
      ~~~~~~~~~~~~~~~^^
  File "/home/dfx_17/Projects/Slovo/schedule/backend/.venv/lib/python3.13/site-packages/fast_bitrix24/server_response.py", line 45, in extract_results
    self.raise_for_errors()
    ~~~~~~~~~~~~~~~~~~~~~^^
  File "/home/dfx_17/Projects/Slovo/schedule/backend/.venv/lib/python3.13/site-packages/fast_bitrix24/server_response.py", line 64, in raise_for_errors
    raise ErrorInServerResponseException(errors)
fast_bitrix24.server_response.ErrorInServerResponseException: {'order0000000000': {'error': 'NOT_FOUND', 'error_description': 'Элемент не найден'}}

2025-06-07 09:48:12.150 | CRITICAL | /home/dfx_17/Projects/Slovo/schedule/backend/.venv/lib/python3.13/site-packages/starlette/applications.py:112 (__call__)
Traceback (most recent call last):
  File "/home/dfx_17/Projects/Slovo/schedule/backend/.venv/lib/python3.13/site-packages/starlette/middleware/base.py", line 148, in call_next
    message = await recv_stream.receive()
              ^^^^^^^^^^^^^^^^^^^^^^^^^^^
  File "/home/dfx_17/Projects/Slovo/schedule/backend/.venv/lib/python3.13/site-packages/anyio/streams/memory.py", line 126, in receive
    raise EndOfStream from None
anyio.EndOfStream

During handling of the above exception, another exception occurred:

Traceback (most recent call last):
  File "/home/dfx_17/Projects/Slovo/schedule/backend/src/middleware.py", line 32, in dispatch
    return await call_next(request)
           ^^^^^^^^^^^^^^^^^^^^^^^^
  File "/home/dfx_17/Projects/Slovo/schedule/backend/.venv/lib/python3.13/site-packages/starlette/middleware/base.py", line 156, in call_next
    raise app_exc
  File "/home/dfx_17/Projects/Slovo/schedule/backend/.venv/lib/python3.13/site-packages/starlette/middleware/base.py", line 141, in coro
    await self.app(scope, receive_or_disconnect, send_no_error)
  File "/home/dfx_17/Projects/Slovo/schedule/backend/.venv/lib/python3.13/site-packages/starlette/middleware/cors.py", line 85, in __call__
    await self.app(scope, receive, send)
  File "/home/dfx_17/Projects/Slovo/schedule/backend/.venv/lib/python3.13/site-packages/starlette/middleware/exceptions.py", line 62, in __call__
    await wrap_app_handling_exceptions(self.app, conn)(scope, receive, send)
  File "/home/dfx_17/Projects/Slovo/schedule/backend/.venv/lib/python3.13/site-packages/starlette/_exception_handler.py", line 53, in wrapped_app
    raise exc
  File "/home/dfx_17/Projects/Slovo/schedule/backend/.venv/lib/python3.13/site-packages/starlette/_exception_handler.py", line 42, in wrapped_app
    await app(scope, receive, sender)
  File "/home/dfx_17/Projects/Slovo/schedule/backend/.venv/lib/python3.13/site-packages/starlette/routing.py", line 714, in __call__
    await self.middleware_stack(scope, receive, send)
  File "/home/dfx_17/Projects/Slovo/schedule/backend/.venv/lib/python3.13/site-packages/starlette/routing.py", line 734, in app
    await route.handle(scope, receive, send)
  File "/home/dfx_17/Projects/Slovo/schedule/backend/.venv/lib/python3.13/site-packages/starlette/routing.py", line 288, in handle
    await self.app(scope, receive, send)
  File "/home/dfx_17/Projects/Slovo/schedule/backend/.venv/lib/python3.13/site-packages/starlette/routing.py", line 76, in app
    await wrap_app_handling_exceptions(app, request)(scope, receive, send)
  File "/home/dfx_17/Projects/Slovo/schedule/backend/.venv/lib/python3.13/site-packages/starlette/_exception_handler.py", line 53, in wrapped_app
    raise exc
  File "/home/dfx_17/Projects/Slovo/schedule/backend/.venv/lib/python3.13/site-packages/starlette/_exception_handler.py", line 42, in wrapped_app
    await app(scope, receive, sender)
  File "/home/dfx_17/Projects/Slovo/schedule/backend/.venv/lib/python3.13/site-packages/starlette/routing.py", line 73, in app
    response = await f(request)
               ^^^^^^^^^^^^^^^^
  File "/home/dfx_17/Projects/Slovo/schedule/backend/.venv/lib/python3.13/site-packages/fastapi/routing.py", line 301, in app
    raw_response = await run_endpoint_function(
                   ^^^^^^^^^^^^^^^^^^^^^^^^^^^^
    ...<3 lines>...
    )
    ^
  File "/home/dfx_17/Projects/Slovo/schedule/backend/.venv/lib/python3.13/site-packages/fastapi/routing.py", line 212, in run_endpoint_function
    return await dependant.call(**values)
           ^^^^^^^^^^^^^^^^^^^^^^^^^^^^^^
  File "/home/dfx_17/Projects/Slovo/schedule/backend/src/api/appointment.py", line 27, in get_appointment
    data = await BitrixClient.get_crm_item(aety, id)
           ^^^^^^^^^^^^^^^^^^^^^^^^^^^^^^^^^^^^^^^^^
  File "/home/dfx_17/Projects/Slovo/schedule/backend/src/core/bitrix.py", line 32, in get_crm_item
    return await BITRIX.call("crm.item.get", items)
           ^^^^^^^^^^^^^^^^^^^^^^^^^^^^^^^^^^^^^^^^
  File "/home/dfx_17/Projects/Slovo/schedule/backend/.venv/lib/python3.13/site-packages/fast_bitrix24/logger.py", line 19, in wrapper
    return await func(*args, **kwargs)
           ^^^^^^^^^^^^^^^^^^^^^^^^^^^
  File "/home/dfx_17/Projects/Slovo/schedule/backend/.venv/lib/python3.13/site-packages/fast_bitrix24/bitrix.py", line 201, in call
    return await self.srh.run_async(request_cls(self, method, items).run())
           ^^^^^^^^^^^^^^^^^^^^^^^^^^^^^^^^^^^^^^^^^^^^^^^^^^^^^^^^^^^^^^^^
  File "/home/dfx_17/Projects/Slovo/schedule/backend/.venv/lib/python3.13/site-packages/fast_bitrix24/srh.py", line 129, in run_async
    return await coroutine
           ^^^^^^^^^^^^^^^
  File "/home/dfx_17/Projects/Slovo/schedule/backend/.venv/lib/python3.13/site-packages/fast_bitrix24/user_request.py", line 330, in run
    raw_results = await MultipleServerRequestHandlerPreserveIDs(
                  ^^^^^^^^^^^^^^^^^^^^^^^^^^^^^^^^^^^^^^^^^^^^^^
    ...<5 lines>...
    ).run()
    ^^^^^^^
  File "/home/dfx_17/Projects/Slovo/schedule/backend/.venv/lib/python3.13/site-packages/fast_bitrix24/mult_request.py", line 67, in run
    extracted_len = self.process_done_tasks(done)
  File "/home/dfx_17/Projects/Slovo/schedule/backend/.venv/lib/python3.13/site-packages/fast_bitrix24/mult_request.py", line 97, in process_done_tasks
    ).extract_results()
      ~~~~~~~~~~~~~~~^^
  File "/home/dfx_17/Projects/Slovo/schedule/backend/.venv/lib/python3.13/site-packages/fast_bitrix24/server_response.py", line 45, in extract_results
    self.raise_for_errors()
    ~~~~~~~~~~~~~~~~~~~~~^^
  File "/home/dfx_17/Projects/Slovo/schedule/backend/.venv/lib/python3.13/site-packages/fast_bitrix24/server_response.py", line 64, in raise_for_errors
    raise ErrorInServerResponseException(errors)
fast_bitrix24.server_response.ErrorInServerResponseException: {'order0000000000': {'error': 'NOT_FOUND', 'error_description': 'Элемент не найден'}}

